
package RubyCraft.Estructuras;

import java.util.Random;

import RubyCraft.xJuanathan.Principal;
import net.minecraft.block.Block;
import net.minecraft.init.Blocks;
import net.minecraft.world.World;
import net.minecraft.world.gen.feature.WorldGenerator;


public class Arbol extends WorldGenerator
{

private static Block MaderaFosil = Principal.Madera_Fosil;
private static Block Maderaadn = Principal.Madera_Fosil_Adn;
private static Block Maderaambar = Principal.Madera_Fosil_Ambar;
private static Block MaderaHueso = Principal.Madera_Fosil_Hueso;

private static Block bloque;

	public boolean generate(World world, Random rand, int x, int y, int z)
	{
	
		
		
		    generate_r0(world,  x, y, z);
		

       return true;

	}
	

	public boolean generate_r0(World world,  int x, int y, int z)
	{
		
		VerqueBloqueGenerar();
		world.setBlock(x + 11, y + 0, z + 15, bloque, 0, 3);	
		world.setBlock(x + 12, y + 0, z + 15, bloque, 0, 3);
		VerqueBloqueGenerar();
		world.setBlock(x + 13, y + 0, z + 15, bloque, 0, 3);
		VerqueBloqueGenerar();
		world.setBlock(x + 14, y + 0, z + 15, bloque, 0, 3);
		VerqueBloqueGenerar();
		world.setBlock(x + 15, y + 0, z + 15, bloque, 0, 3);
		VerqueBloqueGenerar();
		world.setBlock(x + 16, y + 0, z + 15, bloque, 0, 3);
		VerqueBloqueGenerar();
		world.setBlock(x + 11, y + 0, z + 16, bloque, 0, 3);
		VerqueBloqueGenerar();
		world.setBlock(x + 12, y + 0, z + 16, bloque, 0, 3);
		world.setBlock(x + 13, y + 0, z + 16, bloque, 0, 3);
		VerqueBloqueGenerar();
		world.setBlock(x + 14, y + 0, z + 16, bloque, 0, 3);
		VerqueBloqueGenerar();
		world.setBlock(x + 15, y + 0, z + 16, bloque, 0, 3);
		VerqueBloqueGenerar();
		world.setBlock(x + 16, y + 0, z + 16, bloque, 0, 3);
		VerqueBloqueGenerar();
		world.setBlock(x + 11, y + 0, z + 17, bloque, 0, 3);
		world.setBlock(x + 12, y + 0, z + 17, bloque, 0, 3);
		VerqueBloqueGenerar();
		world.setBlock(x + 13, y + 0, z + 17, bloque, 0, 3);
		VerqueBloqueGenerar();
		world.setBlock(x + 14, y + 0, z + 17, bloque, 0, 3);
		VerqueBloqueGenerar();
		world.setBlock(x + 15, y + 0, z + 17, bloque, 0, 3);
		VerqueBloqueGenerar();
		world.setBlock(x + 16, y + 0, z + 17, bloque, 0, 3);
		VerqueBloqueGenerar();
		world.setBlock(x + 11, y + 0, z + 18, bloque, 0, 3);
		world.setBlock(x + 12, y + 0, z + 18, bloque, 0, 3);
		world.setBlock(x + 13, y + 0, z + 18, bloque, 0, 3);
		world.setBlock(x + 14, y + 0, z + 18, bloque, 0, 3);
		world.setBlock(x + 15, y + 0, z + 18, bloque, 0, 3);
		VerqueBloqueGenerar();
		world.setBlock(x + 16, y + 0, z + 18, bloque, 0, 3);
		world.setBlock(x + 11, y + 0, z + 19, bloque, 0, 3);
		world.setBlock(x + 12, y + 0, z + 19, bloque, 0, 3);
		world.setBlock(x + 13, y + 0, z + 19, bloque, 0, 3);
		world.setBlock(x + 14, y + 0, z + 19, bloque, 0, 3);
		VerqueBloqueGenerar();
		world.setBlock(x + 15, y + 0, z + 19, bloque, 0, 3);
		world.setBlock(x + 16, y + 0, z + 19, bloque, 0, 3);
		world.setBlock(x + 11, y + 0, z + 20, bloque, 0, 3);
		world.setBlock(x + 12, y + 0, z + 20, bloque, 0, 3);
		world.setBlock(x + 13, y + 0, z + 20, bloque, 0, 3);
		VerqueBloqueGenerar();
		world.setBlock(x + 14, y + 0, z + 20, bloque, 0, 3);
		world.setBlock(x + 15, y + 0, z + 20, bloque, 0, 3);
		world.setBlock(x + 16, y + 0, z + 20, bloque, 0, 3);
		world.setBlock(x + 11, y + 1, z + 15, bloque, 0, 3);
		VerqueBloqueGenerar();
		world.setBlock(x + 12, y + 1, z + 15, bloque, 0, 3);
		world.setBlock(x + 13, y + 1, z + 15, bloque, 0, 3);
		world.setBlock(x + 14, y + 1, z + 15, bloque, 0, 3);
		world.setBlock(x + 15, y + 1, z + 15, bloque, 0, 3);
		VerqueBloqueGenerar();
		world.setBlock(x + 16, y + 1, z + 15, bloque, 0, 3);
		world.setBlock(x + 11, y + 1, z + 16, bloque, 0, 3);
		world.setBlock(x + 12, y + 1, z + 16, bloque, 0, 3);
		world.setBlock(x + 13, y + 1, z + 16, bloque, 0, 3);
		world.setBlock(x + 14, y + 1, z + 16, bloque, 0, 3);
		world.setBlock(x + 15, y + 1, z + 16, bloque, 0, 3);
		VerqueBloqueGenerar();
		world.setBlock(x + 16, y + 1, z + 16, bloque, 0, 3);
		world.setBlock(x + 11, y + 1, z + 17, bloque, 0, 3);
		world.setBlock(x + 12, y + 1, z + 17, bloque, 0, 3);
		world.setBlock(x + 13, y + 1, z + 17, bloque, 0, 3);
		world.setBlock(x + 14, y + 1, z + 17, bloque, 0, 3);
		VerqueBloqueGenerar();
		world.setBlock(x + 15, y + 1, z + 17, bloque, 0, 3);
		world.setBlock(x + 16, y + 1, z + 17, bloque, 0, 3);
		world.setBlock(x + 11, y + 1, z + 18, bloque, 0, 3);
		VerqueBloqueGenerar();
		world.setBlock(x + 12, y + 1, z + 18, bloque, 0, 3);
		world.setBlock(x + 13, y + 1, z + 18, bloque, 0, 3);
		world.setBlock(x + 14, y + 1, z + 18, bloque, 0, 3);
		world.setBlock(x + 15, y + 1, z + 18, bloque, 0, 3);
		VerqueBloqueGenerar();
		world.setBlock(x + 16, y + 1, z + 18, bloque, 0, 3);
		world.setBlock(x + 11, y + 1, z + 19, bloque, 0, 3);
		world.setBlock(x + 12, y + 1, z + 19, bloque, 0, 3);
		VerqueBloqueGenerar();
		world.setBlock(x + 13, y + 1, z + 19, bloque, 0, 3);
		world.setBlock(x + 14, y + 1, z + 19, bloque, 0, 3);
		VerqueBloqueGenerar();
		world.setBlock(x + 15, y + 1, z + 19, bloque, 0, 3);
		world.setBlock(x + 16, y + 1, z + 19, bloque, 0, 3);
		world.setBlock(x + 11, y + 1, z + 20, bloque, 0, 3);
		world.setBlock(x + 12, y + 1, z + 20, bloque, 0, 3);
		VerqueBloqueGenerar();
		world.setBlock(x + 13, y + 1, z + 20, bloque, 0, 3);
		world.setBlock(x + 14, y + 1, z + 20, bloque, 0, 3);
		VerqueBloqueGenerar();
		world.setBlock(x + 15, y + 1, z + 20, bloque, 0, 3);
		world.setBlock(x + 16, y + 1, z + 20, bloque, 0, 3);
		world.setBlock(x + 11, y + 2, z + 15, bloque, 0, 3);
		VerqueBloqueGenerar();
		world.setBlock(x + 12, y + 2, z + 15, bloque, 0, 3);
		world.setBlock(x + 13, y + 2, z + 15, bloque, 0, 3);
		world.setBlock(x + 14, y + 2, z + 15, bloque, 0, 3);
		VerqueBloqueGenerar();
		world.setBlock(x + 15, y + 2, z + 15, bloque, 0, 3);
		world.setBlock(x + 16, y + 2, z + 15, bloque, 0, 3);
		world.setBlock(x + 11, y + 2, z + 16, bloque, 0, 3);
		VerqueBloqueGenerar();
		world.setBlock(x + 12, y + 2, z + 16, bloque, 0, 3);
		world.setBlock(x + 13, y + 2, z + 16, bloque, 0, 3);
		world.setBlock(x + 14, y + 2, z + 16, bloque, 0, 3);
		world.setBlock(x + 15, y + 2, z + 16, bloque, 0, 3);
		VerqueBloqueGenerar();
		world.setBlock(x + 16, y + 2, z + 16, bloque, 0, 3);
		world.setBlock(x + 11, y + 2, z + 17, bloque, 0, 3);
		world.setBlock(x + 12, y + 2, z + 17, bloque, 0, 3);
		VerqueBloqueGenerar();
		world.setBlock(x + 13, y + 2, z + 17, bloque, 0, 3);
		world.setBlock(x + 14, y + 2, z + 17, bloque, 0, 3);
		VerqueBloqueGenerar();
		world.setBlock(x + 15, y + 2, z + 17, bloque, 0, 3);
		world.setBlock(x + 16, y + 2, z + 17, bloque, 0, 3);
		VerqueBloqueGenerar();
		world.setBlock(x + 11, y + 2, z + 18, bloque, 0, 3);
		world.setBlock(x + 12, y + 2, z + 18, bloque, 0, 3);
		world.setBlock(x + 13, y + 2, z + 18, bloque, 0, 3);
		VerqueBloqueGenerar();
		world.setBlock(x + 14, y + 2, z + 18, bloque, 0, 3);
		world.setBlock(x + 15, y + 2, z + 18, bloque, 0, 3);
		world.setBlock(x + 16, y + 2, z + 18, bloque, 0, 3);
		world.setBlock(x + 11, y + 2, z + 19, bloque, 0, 3);
		world.setBlock(x + 12, y + 2, z + 19, bloque, 0, 3);
		world.setBlock(x + 13, y + 2, z + 19, bloque, 0, 3);
		VerqueBloqueGenerar();
		world.setBlock(x + 14, y + 2, z + 19, bloque, 0, 3);
		world.setBlock(x + 15, y + 2, z + 19, bloque, 0, 3);
		world.setBlock(x + 16, y + 2, z + 19, bloque, 0, 3);
		world.setBlock(x + 11, y + 2, z + 20, bloque, 0, 3);
		world.setBlock(x + 12, y + 2, z + 20, bloque, 0, 3);
		VerqueBloqueGenerar();
		world.setBlock(x + 13, y + 2, z + 20, bloque, 0, 3);
		world.setBlock(x + 14, y + 2, z + 20, bloque, 0, 3);
		world.setBlock(x + 15, y + 2, z + 20, bloque, 0, 3);
		world.setBlock(x + 16, y + 2, z + 20, bloque, 0, 3);
		world.setBlock(x + 11, y + 3, z + 15, bloque, 0, 3);
		VerqueBloqueGenerar();
		world.setBlock(x + 12, y + 3, z + 15, bloque, 0, 3);
		world.setBlock(x + 13, y + 3, z + 15, bloque, 0, 3);
		world.setBlock(x + 14, y + 3, z + 15, bloque, 0, 3);
		VerqueBloqueGenerar();
		world.setBlock(x + 15, y + 3, z + 15, bloque, 0, 3);
		world.setBlock(x + 16, y + 3, z + 15, bloque, 0, 3);
		world.setBlock(x + 11, y + 3, z + 16, bloque, 0, 3);
		VerqueBloqueGenerar();
		world.setBlock(x + 12, y + 3, z + 16, bloque, 0, 3);
		world.setBlock(x + 13, y + 3, z + 16, bloque, 0, 3);
		VerqueBloqueGenerar();
		world.setBlock(x + 14, y + 3, z + 16, bloque, 0, 3);
		world.setBlock(x + 15, y + 3, z + 16, bloque, 0, 3);
		VerqueBloqueGenerar();
		world.setBlock(x + 16, y + 3, z + 16, bloque, 0, 3);
		world.setBlock(x + 11, y + 3, z + 17, bloque, 0, 3);
		world.setBlock(x + 12, y + 3, z + 17, bloque, 0, 3);
		world.setBlock(x + 13, y + 3, z + 17, bloque, 0, 3);
		VerqueBloqueGenerar();
		world.setBlock(x + 14, y + 3, z + 17, bloque, 0, 3);
		world.setBlock(x + 15, y + 3, z + 17, bloque, 0, 3);
		world.setBlock(x + 16, y + 3, z + 17, bloque, 0, 3);
		world.setBlock(x + 11, y + 3, z + 18, bloque, 0, 3);
		world.setBlock(x + 12, y + 3, z + 18, bloque, 0, 3);
		VerqueBloqueGenerar();
		world.setBlock(x + 13, y + 3, z + 18, bloque, 0, 3);
		world.setBlock(x + 14, y + 3, z + 18, bloque, 0, 3);
		world.setBlock(x + 15, y + 3, z + 18, bloque, 0, 3);
		world.setBlock(x + 16, y + 3, z + 18, bloque, 0, 3);
		VerqueBloqueGenerar();
		world.setBlock(x + 11, y + 3, z + 19, bloque, 0, 3);
		world.setBlock(x + 12, y + 3, z + 19, bloque, 0, 3);
		world.setBlock(x + 13, y + 3, z + 19, bloque, 0, 3);
		world.setBlock(x + 14, y + 3, z + 19, bloque, 0, 3);
		VerqueBloqueGenerar();
		world.setBlock(x + 15, y + 3, z + 19, bloque, 0, 3);
		world.setBlock(x + 16, y + 3, z + 19, bloque, 0, 3);
		world.setBlock(x + 11, y + 3, z + 20, bloque, 0, 3);
		world.setBlock(x + 12, y + 3, z + 20, bloque, 0, 3);
		VerqueBloqueGenerar();
		world.setBlock(x + 13, y + 3, z + 20, bloque, 0, 3);
		world.setBlock(x + 14, y + 3, z + 20, bloque, 0, 3);
		world.setBlock(x + 15, y + 3, z + 20, bloque, 0, 3);
		VerqueBloqueGenerar();
		world.setBlock(x + 16, y + 3, z + 20, bloque, 0, 3);
		world.setBlock(x + 13, y + 4, z + 17, bloque, 0, 3);
		world.setBlock(x + 14, y + 4, z + 17, bloque, 0, 3);
		world.setBlock(x + 13, y + 4, z + 18, bloque, 0, 3);
		world.setBlock(x + 14, y + 4, z + 18, bloque, 0, 3);
		world.setBlock(x + 13, y + 5, z + 17, bloque, 0, 3);
		VerqueBloqueGenerar();
		world.setBlock(x + 14, y + 5, z + 17, bloque, 0, 3);
		world.setBlock(x + 13, y + 5, z + 18, bloque, 0, 3);
		world.setBlock(x + 14, y + 5, z + 18, bloque, 0, 3);
		VerqueBloqueGenerar();
		world.setBlock(x + 8, y + 6, z + 12, Blocks.log2, 1, 3);
		world.setBlock(x + 19, y + 6, z + 12, Blocks.log2, 1, 3);
		world.setBlock(x + 13, y + 6, z + 17, bloque, 0, 3);
		world.setBlock(x + 14, y + 6, z + 17, bloque, 0, 3);
		world.setBlock(x + 13, y + 6, z + 18, bloque, 0, 3);
		VerqueBloqueGenerar();
		world.setBlock(x + 14, y + 6, z + 18, bloque, 0, 3);
		world.setBlock(x + 8, y + 6, z + 23, Blocks.log2, 1, 3);
		world.setBlock(x + 19, y + 6, z + 23, Blocks.log2, 1, 3);
		world.setBlock(x + 8, y + 7, z + 11, Blocks.log2, 1, 3);
		world.setBlock(x + 19, y + 7, z + 11, Blocks.log2, 1, 3);
		world.setBlock(x + 7, y + 7, z + 12, Blocks.log2, 1, 3);
		world.setBlock(x + 8, y + 7, z + 12, Blocks.log2, 1, 3);
		world.setBlock(x + 9, y + 7, z + 12, Blocks.log2, 1, 3);
		world.setBlock(x + 19, y + 7, z + 12, Blocks.log2, 1, 3);
		world.setBlock(x + 20, y + 7, z + 12, Blocks.log2, 1, 3);
		world.setBlock(x + 8, y + 7, z + 13, Blocks.log2, 1, 3);
		world.setBlock(x + 13, y + 7, z + 17, Blocks.log2, 1, 3);
		world.setBlock(x + 14, y + 7, z + 17, Blocks.log2, 1, 3);
		world.setBlock(x + 13, y + 7, z + 18, Blocks.log2, 1, 3);
		world.setBlock(x + 14, y + 7, z + 18, Blocks.log2, 1, 3);
		world.setBlock(x + 8, y + 7, z + 22, Blocks.log2, 1, 3);
		world.setBlock(x + 19, y + 7, z + 22, Blocks.log2, 1, 3);
		world.setBlock(x + 7, y + 7, z + 23, Blocks.log2, 1, 3);
		world.setBlock(x + 8, y + 7, z + 23, Blocks.log2, 1, 3);
		world.setBlock(x + 9, y + 7, z + 23, Blocks.log2, 1, 3);
		world.setBlock(x + 18, y + 7, z + 23, Blocks.log2, 1, 3);
		world.setBlock(x + 19, y + 7, z + 23, Blocks.log2, 1, 3);
		world.setBlock(x + 20, y + 7, z + 23, Blocks.log2, 1, 3);
		world.setBlock(x + 8, y + 7, z + 24, Blocks.log2, 1, 3);
		world.setBlock(x + 19, y + 7, z + 24, Blocks.log2, 1, 3);
		world.setBlock(x + 8, y + 8, z + 10, Blocks.log2, 1, 3);
		world.setBlock(x + 19, y + 8, z + 10, Blocks.log2, 1, 3);
		world.setBlock(x + 7, y + 8, z + 11, Blocks.log2, 1, 3);
		world.setBlock(x + 8, y + 8, z + 11, Blocks.log2, 1, 3);
		world.setBlock(x + 9, y + 8, z + 11, Blocks.log2, 1, 3);
		world.setBlock(x + 18, y + 8, z + 11, Blocks.log2, 1, 3);
		world.setBlock(x + 19, y + 8, z + 11, Blocks.log2, 1, 3);
		world.setBlock(x + 20, y + 8, z + 11, Blocks.log2, 1, 3);
		world.setBlock(x + 6, y + 8, z + 12, Blocks.log2, 1, 3);
		world.setBlock(x + 7, y + 8, z + 12, Blocks.log2, 1, 3);
		world.setBlock(x + 8, y + 8, z + 12, Blocks.log2, 1, 3);
		world.setBlock(x + 9, y + 8, z + 12, Blocks.log2, 1, 3);
		world.setBlock(x + 19, y + 8, z + 12, Blocks.log2, 1, 3);
		world.setBlock(x + 20, y + 8, z + 12, Blocks.log2, 1, 3);
		world.setBlock(x + 21, y + 8, z + 12, Blocks.log2, 1, 3);
		world.setBlock(x + 7, y + 8, z + 13, Blocks.log2, 1, 3);
		world.setBlock(x + 8, y + 8, z + 13, Blocks.log2, 1, 3);
		world.setBlock(x + 9, y + 8, z + 13, Blocks.log2, 1, 3);
		world.setBlock(x + 20, y + 8, z + 13, Blocks.log2, 1, 3);
		world.setBlock(x + 8, y + 8, z + 14, Blocks.log2, 1, 3);
		world.setBlock(x + 12, y + 8, z + 16, Blocks.log2, 1, 3);
		world.setBlock(x + 15, y + 8, z + 16, Blocks.log2, 1, 3);
		world.setBlock(x + 13, y + 8, z + 17, Blocks.log2, 1, 3);
		world.setBlock(x + 14, y + 8, z + 17, Blocks.log2, 1, 3);
		world.setBlock(x + 13, y + 8, z + 18, Blocks.log2, 1, 3);
		world.setBlock(x + 14, y + 8, z + 18, Blocks.log2, 1, 3);
		world.setBlock(x + 12, y + 8, z + 19, Blocks.log2, 1, 3);
		world.setBlock(x + 15, y + 8, z + 19, Blocks.log2, 1, 3);
		world.setBlock(x + 8, y + 8, z + 21, Blocks.log2, 1, 3);
		world.setBlock(x + 19, y + 8, z + 21, Blocks.log2, 1, 3);
		world.setBlock(x + 7, y + 8, z + 22, Blocks.log2, 1, 3);
		world.setBlock(x + 8, y + 8, z + 22, Blocks.log2, 1, 3);
		world.setBlock(x + 9, y + 8, z + 22, Blocks.log2, 1, 3);
		world.setBlock(x + 18, y + 8, z + 22, Blocks.log2, 1, 3);
		world.setBlock(x + 19, y + 8, z + 22, Blocks.log2, 1, 3);
		world.setBlock(x + 20, y + 8, z + 22, Blocks.log2, 1, 3);
		world.setBlock(x + 6, y + 8, z + 23, Blocks.log2, 1, 3);
		world.setBlock(x + 7, y + 8, z + 23, Blocks.log2, 1, 3);
		world.setBlock(x + 8, y + 8, z + 23, Blocks.log2, 1, 3);
		world.setBlock(x + 9, y + 8, z + 23, Blocks.log2, 1, 3);
		world.setBlock(x + 10, y + 8, z + 23, Blocks.log2, 1, 3);
		world.setBlock(x + 18, y + 8, z + 23, Blocks.log2, 1, 3);
		world.setBlock(x + 19, y + 8, z + 23, Blocks.log2, 1, 3);
		world.setBlock(x + 20, y + 8, z + 23, Blocks.log2, 1, 3);
		world.setBlock(x + 21, y + 8, z + 23, Blocks.log2, 1, 3);
		world.setBlock(x + 7, y + 8, z + 24, Blocks.log2, 1, 3);
		world.setBlock(x + 8, y + 8, z + 24, Blocks.log2, 1, 3);
		world.setBlock(x + 9, y + 8, z + 24, Blocks.log2, 1, 3);
		world.setBlock(x + 18, y + 8, z + 24, Blocks.log2, 1, 3);
		world.setBlock(x + 19, y + 8, z + 24, Blocks.log2, 1, 3);
		world.setBlock(x + 20, y + 8, z + 24, Blocks.log2, 1, 3);
		world.setBlock(x + 8, y + 8, z + 25, Blocks.log2, 1, 3);
		world.setBlock(x + 19, y + 8, z + 25, Blocks.log2, 1, 3);
		world.setBlock(x + 8, y + 9, z + 10, Blocks.log2, 1, 3);
		world.setBlock(x + 19, y + 9, z + 10, Blocks.log2, 1, 3);
		world.setBlock(x + 7, y + 9, z + 11, Blocks.log2, 1, 3);
		world.setBlock(x + 8, y + 9, z + 11, Blocks.log2, 1, 3);
		world.setBlock(x + 9, y + 9, z + 11, Blocks.log2, 1, 3);
		world.setBlock(x + 18, y + 9, z + 11, Blocks.log2, 1, 3);
		world.setBlock(x + 19, y + 9, z + 11, Blocks.log2, 1, 3);
		world.setBlock(x + 20, y + 9, z + 11, Blocks.log2, 1, 3);
		world.setBlock(x + 6, y + 9, z + 12, Blocks.log2, 1, 3);
		world.setBlock(x + 7, y + 9, z + 12, Blocks.log2, 1, 3);
		world.setBlock(x + 8, y + 9, z + 12, Blocks.log2, 1, 3);
		world.setBlock(x + 9, y + 9, z + 12, Blocks.log2, 1, 3);
		world.setBlock(x + 18, y + 9, z + 12, Blocks.log2, 1, 3);
		world.setBlock(x + 19, y + 9, z + 12, Blocks.log2, 1, 3);
		world.setBlock(x + 20, y + 9, z + 12, Blocks.log2, 1, 3);
		world.setBlock(x + 21, y + 9, z + 12, Blocks.log2, 1, 3);
		world.setBlock(x + 7, y + 9, z + 13, Blocks.log2, 1, 3);
		world.setBlock(x + 8, y + 9, z + 13, Blocks.log2, 1, 3);
		world.setBlock(x + 9, y + 9, z + 13, Blocks.log2, 1, 3);
		world.setBlock(x + 18, y + 9, z + 13, Blocks.log2, 1, 3);
		world.setBlock(x + 20, y + 9, z + 13, Blocks.log2, 1, 3);
		world.setBlock(x + 8, y + 9, z + 14, Blocks.log2, 1, 3);
		world.setBlock(x + 9, y + 9, z + 14, Blocks.log2, 1, 3);
		world.setBlock(x + 10, y + 9, z + 14, Blocks.log2, 1, 3);
		world.setBlock(x + 17, y + 9, z + 14, Blocks.log2, 1, 3);
		world.setBlock(x + 11, y + 9, z + 15, Blocks.log2, 1, 3);
		world.setBlock(x + 16, y + 9, z + 15, Blocks.log2, 1, 3);
		world.setBlock(x + 12, y + 9, z + 16, Blocks.log2, 1, 3);
		world.setBlock(x + 13, y + 9, z + 16, Blocks.log2, 1, 3);
		world.setBlock(x + 14, y + 9, z + 16, Blocks.log2, 1, 3);
		world.setBlock(x + 15, y + 9, z + 16, Blocks.log2, 1, 3);
		world.setBlock(x + 12, y + 9, z + 17, Blocks.log2, 1, 3);
		world.setBlock(x + 13, y + 9, z + 17, Blocks.log2, 1, 3);
		world.setBlock(x + 14, y + 9, z + 17, Blocks.log2, 1, 3);
		world.setBlock(x + 15, y + 9, z + 17, Blocks.log2, 1, 3);
		world.setBlock(x + 12, y + 9, z + 18, Blocks.log2, 1, 3);
		world.setBlock(x + 13, y + 9, z + 18, Blocks.log2, 1, 3);
		world.setBlock(x + 14, y + 9, z + 18, Blocks.log2, 1, 3);
		world.setBlock(x + 15, y + 9, z + 18, Blocks.log2, 1, 3);
		world.setBlock(x + 12, y + 9, z + 19, Blocks.log2, 1, 3);
		world.setBlock(x + 13, y + 9, z + 19, Blocks.log2, 1, 3);
		world.setBlock(x + 14, y + 9, z + 19, Blocks.log2, 1, 3);
		world.setBlock(x + 15, y + 9, z + 19, Blocks.log2, 1, 3);
		world.setBlock(x + 11, y + 9, z + 20, Blocks.log2, 1, 3);
		world.setBlock(x + 16, y + 9, z + 20, Blocks.log2, 1, 3);
		world.setBlock(x + 8, y + 9, z + 21, Blocks.log2, 1, 3);
		world.setBlock(x + 10, y + 9, z + 21, Blocks.log2, 1, 3);
		world.setBlock(x + 17, y + 9, z + 21, Blocks.log2, 1, 3);
		world.setBlock(x + 18, y + 9, z + 21, Blocks.log2, 1, 3);
		world.setBlock(x + 19, y + 9, z + 21, Blocks.log2, 1, 3);
		world.setBlock(x + 7, y + 9, z + 22, Blocks.log2, 1, 3);
		world.setBlock(x + 8, y + 9, z + 22, Blocks.log2, 1, 3);
		world.setBlock(x + 9, y + 9, z + 22, Blocks.log2, 1, 3);
		world.setBlock(x + 10, y + 9, z + 22, Blocks.log2, 1, 3);
		world.setBlock(x + 18, y + 9, z + 22, Blocks.log2, 1, 3);
		world.setBlock(x + 19, y + 9, z + 22, Blocks.log2, 1, 3);
		world.setBlock(x + 20, y + 9, z + 22, Blocks.log2, 1, 3);
		world.setBlock(x + 6, y + 9, z + 23, Blocks.log2, 1, 3);
		world.setBlock(x + 7, y + 9, z + 23, Blocks.log2, 1, 3);
		world.setBlock(x + 8, y + 9, z + 23, Blocks.log2, 1, 3);
		world.setBlock(x + 9, y + 9, z + 23, Blocks.log2, 1, 3);
		world.setBlock(x + 10, y + 9, z + 23, Blocks.log2, 1, 3);
		world.setBlock(x + 17, y + 9, z + 23, Blocks.log2, 1, 3);
		world.setBlock(x + 18, y + 9, z + 23, Blocks.log2, 1, 3);
		world.setBlock(x + 19, y + 9, z + 23, Blocks.log2, 1, 3);
		world.setBlock(x + 20, y + 9, z + 23, Blocks.log2, 1, 3);
		world.setBlock(x + 21, y + 9, z + 23, Blocks.log2, 1, 3);
		world.setBlock(x + 7, y + 9, z + 24, Blocks.log2, 1, 3);
		world.setBlock(x + 8, y + 9, z + 24, Blocks.log2, 1, 3);
		world.setBlock(x + 9, y + 9, z + 24, Blocks.log2, 1, 3);
		world.setBlock(x + 18, y + 9, z + 24, Blocks.log2, 1, 3);
		world.setBlock(x + 19, y + 9, z + 24, Blocks.log2, 1, 3);
		world.setBlock(x + 20, y + 9, z + 24, Blocks.log2, 1, 3);
		world.setBlock(x + 8, y + 9, z + 25, Blocks.log2, 1, 3);
		world.setBlock(x + 19, y + 9, z + 25, Blocks.log2, 1, 3);
		world.setBlock(x + 8, y + 10, z + 11, Blocks.log2, 1, 3);
		world.setBlock(x + 19, y + 10, z + 11, Blocks.log2, 1, 3);
		world.setBlock(x + 7, y + 10, z + 12, Blocks.log2, 1, 3);
		world.setBlock(x + 8, y + 10, z + 12, Blocks.log2, 1, 3);
		world.setBlock(x + 9, y + 10, z + 12, Blocks.log2, 1, 3);
		world.setBlock(x + 17, y + 10, z + 12, Blocks.log2, 1, 3);
		world.setBlock(x + 18, y + 10, z + 12, Blocks.log2, 1, 3);
		world.setBlock(x + 19, y + 10, z + 12, Blocks.log2, 1, 3);
		world.setBlock(x + 20, y + 10, z + 12, Blocks.log2, 1, 3);
		world.setBlock(x + 8, y + 10, z + 13, Blocks.log2, 1, 3);
		world.setBlock(x + 9, y + 10, z + 13, Blocks.log2, 1, 3);
		world.setBlock(x + 10, y + 10, z + 13, Blocks.log2, 1, 3);
		world.setBlock(x + 17, y + 10, z + 13, Blocks.log2, 1, 3);
		world.setBlock(x + 18, y + 10, z + 13, Blocks.log2, 1, 3);
		world.setBlock(x + 19, y + 10, z + 13, Blocks.log2, 1, 3);
		world.setBlock(x + 9, y + 10, z + 14, Blocks.log2, 1, 3);
		world.setBlock(x + 10, y + 10, z + 14, Blocks.log2, 1, 3);
		world.setBlock(x + 11, y + 10, z + 14, Blocks.log2, 1, 3);
		world.setBlock(x + 16, y + 10, z + 14, Blocks.log2, 1, 3);
		world.setBlock(x + 17, y + 10, z + 14, Blocks.log2, 1, 3);
		world.setBlock(x + 18, y + 10, z + 14, Blocks.log2, 1, 3);
		world.setBlock(x + 10, y + 10, z + 15, Blocks.log2, 1, 3);
		world.setBlock(x + 11, y + 10, z + 15, Blocks.log2, 1, 3);
		world.setBlock(x + 14, y + 10, z + 15, Blocks.log2, 1, 3);
		world.setBlock(x + 15, y + 10, z + 15, Blocks.log2, 5, 3);
		world.setBlock(x + 16, y + 10, z + 15, Blocks.log2, 1, 3);
		world.setBlock(x + 17, y + 10, z + 15, Blocks.log2, 1, 3);
		world.setBlock(x + 12, y + 10, z + 16, Blocks.log2, 1, 3);
		world.setBlock(x + 13, y + 10, z + 16, Blocks.log2, 1, 3);
		world.setBlock(x + 14, y + 10, z + 16, Blocks.log2, 1, 3);
		world.setBlock(x + 15, y + 10, z + 16, Blocks.log2, 1, 3);
		world.setBlock(x + 11, y + 10, z + 17, Blocks.log2, 1, 3);
		world.setBlock(x + 12, y + 10, z + 17, Blocks.log2, 1, 3);
		world.setBlock(x + 13, y + 10, z + 17, Blocks.log2, 1, 3);
		world.setBlock(x + 14, y + 10, z + 17, Blocks.log2, 1, 3);
		world.setBlock(x + 15, y + 10, z + 17, Blocks.log2, 1, 3);
		world.setBlock(x + 16, y + 10, z + 17, Blocks.log2, 1, 3);
		world.setBlock(x + 11, y + 10, z + 18, Blocks.log2, 1, 3);
		world.setBlock(x + 12, y + 10, z + 18, Blocks.log2, 1, 3);
		world.setBlock(x + 13, y + 10, z + 18, Blocks.log2, 1, 3);
		world.setBlock(x + 14, y + 10, z + 18, Blocks.log2, 1, 3);
		world.setBlock(x + 15, y + 10, z + 18, Blocks.log2, 1, 3);
		world.setBlock(x + 16, y + 10, z + 18, Blocks.log2, 1, 3);
		world.setBlock(x + 12, y + 10, z + 19, Blocks.log2, 1, 3);
		world.setBlock(x + 13, y + 10, z + 19, Blocks.log2, 1, 3);
		world.setBlock(x + 14, y + 10, z + 19, Blocks.log2, 1, 3);
		world.setBlock(x + 15, y + 10, z + 19, Blocks.log2, 1, 3);
		world.setBlock(x + 10, y + 10, z + 20, Blocks.log2, 1, 3);
		world.setBlock(x + 11, y + 10, z + 20, Blocks.log2, 1, 3);
		world.setBlock(x + 12, y + 10, z + 20, Blocks.log2, 5, 3);
		world.setBlock(x + 13, y + 10, z + 20, Blocks.log2, 1, 3);
		world.setBlock(x + 14, y + 10, z + 20, Blocks.log2, 1, 3);
		world.setBlock(x + 16, y + 10, z + 20, Blocks.log2, 1, 3);
		world.setBlock(x + 17, y + 10, z + 20, Blocks.log2, 5, 3);
		world.setBlock(x + 9, y + 10, z + 21, Blocks.log2, 1, 3);
		world.setBlock(x + 10, y + 10, z + 21, Blocks.log2, 1, 3);
		world.setBlock(x + 11, y + 10, z + 21, Blocks.log2, 1, 3);
		world.setBlock(x + 16, y + 10, z + 21, Blocks.log2, 1, 3);
		world.setBlock(x + 17, y + 10, z + 21, Blocks.log2, 1, 3);
		world.setBlock(x + 18, y + 10, z + 21, Blocks.log2, 1, 3);
		world.setBlock(x + 8, y + 10, z + 22, Blocks.log2, 1, 3);
		world.setBlock(x + 9, y + 10, z + 22, Blocks.log2, 1, 3);
		world.setBlock(x + 10, y + 10, z + 22, Blocks.log2, 1, 3);
		world.setBlock(x + 17, y + 10, z + 22, Blocks.log2, 1, 3);
		world.setBlock(x + 18, y + 10, z + 22, Blocks.log2, 1, 3);
		world.setBlock(x + 19, y + 10, z + 22, Blocks.log2, 1, 3);
		world.setBlock(x + 7, y + 10, z + 23, Blocks.log2, 1, 3);
		world.setBlock(x + 8, y + 10, z + 23, Blocks.log2, 1, 3);
		world.setBlock(x + 9, y + 10, z + 23, Blocks.log2, 1, 3);
		world.setBlock(x + 17, y + 10, z + 23, Blocks.log2, 1, 3);
		world.setBlock(x + 18, y + 10, z + 23, Blocks.log2, 1, 3);
		world.setBlock(x + 19, y + 10, z + 23, Blocks.log2, 1, 3);
		world.setBlock(x + 20, y + 10, z + 23, Blocks.log2, 1, 3);
		world.setBlock(x + 8, y + 10, z + 24, Blocks.log2, 1, 3);
		world.setBlock(x + 19, y + 10, z + 24, Blocks.log2, 1, 3);
		world.setBlock(x + 8, y + 11, z + 12, Blocks.log2, 5, 3);
		world.setBlock(x + 19, y + 11, z + 12, Blocks.log2, 5, 3);
		world.setBlock(x + 9, y + 11, z + 13, Blocks.log2, 1, 3);
		world.setBlock(x + 18, y + 11, z + 13, Blocks.log2, 1, 3);
		world.setBlock(x + 10, y + 11, z + 14, Blocks.log2, 1, 3);
		world.setBlock(x + 16, y + 11, z + 14, Blocks.log2, 1, 3);
		world.setBlock(x + 17, y + 11, z + 14, Blocks.log2, 1, 3);
		world.setBlock(x + 10, y + 11, z + 15, Blocks.log2, 1, 3);
		world.setBlock(x + 11, y + 11, z + 15, Blocks.log2, 1, 3);
		world.setBlock(x + 16, y + 11, z + 15, Blocks.log2, 1, 3);
		world.setBlock(x + 17, y + 11, z + 15, Blocks.log2, 1, 3);
		world.setBlock(x + 12, y + 11, z + 16, Blocks.log2, 9, 3);
		world.setBlock(x + 13, y + 11, z + 16, Blocks.log2, 1, 3);
		world.setBlock(x + 14, y + 11, z + 16, Blocks.log2, 9, 3);
		world.setBlock(x + 15, y + 11, z + 16, Blocks.log2, 1, 3);
		world.setBlock(x + 11, y + 11, z + 17, Blocks.log2, 5, 3);
		world.setBlock(x + 12, y + 11, z + 17, Blocks.log2, 9, 3);
		world.setBlock(x + 13, y + 11, z + 17, Blocks.log2, 1, 3);
		world.setBlock(x + 14, y + 11, z + 17, Blocks.log2, 1, 3);
		world.setBlock(x + 15, y + 11, z + 17, Blocks.log2, 1, 3);
		world.setBlock(x + 16, y + 11, z + 17, Blocks.log2, 1, 3);
		world.setBlock(x + 11, y + 11, z + 18, Blocks.log2, 5, 3);
		world.setBlock(x + 12, y + 11, z + 18, Blocks.log2, 1, 3);
		world.setBlock(x + 13, y + 11, z + 18, Blocks.log2, 1, 3);
		world.setBlock(x + 14, y + 11, z + 18, Blocks.log2, 1, 3);
		world.setBlock(x + 15, y + 11, z + 18, Blocks.log2, 1, 3);
		world.setBlock(x + 16, y + 11, z + 18, Blocks.log2, 1, 3);
		world.setBlock(x + 12, y + 11, z + 19, Blocks.log2, 1, 3);
		world.setBlock(x + 13, y + 11, z + 19, Blocks.log2, 9, 3);
		world.setBlock(x + 14, y + 11, z + 19, Blocks.log2, 1, 3);
		world.setBlock(x + 15, y + 11, z + 19, Blocks.log2, 1, 3);
		world.setBlock(x + 10, y + 11, z + 20, Blocks.log2, 1, 3);
		world.setBlock(x + 11, y + 11, z + 20, Blocks.log2, 1, 3);
		world.setBlock(x + 12, y + 11, z + 20, Blocks.log2, 1, 3);
		world.setBlock(x + 13, y + 11, z + 20, Blocks.log2, 1, 3);
		world.setBlock(x + 14, y + 11, z + 20, Blocks.log2, 1, 3);
		world.setBlock(x + 16, y + 11, z + 20, Blocks.log2, 1, 3);
		world.setBlock(x + 9, y + 11, z + 21, Blocks.log2, 5, 3);
		world.setBlock(x + 10, y + 11, z + 21, Blocks.log2, 1, 3);
		world.setBlock(x + 11, y + 11, z + 21, Blocks.log2, 1, 3);
		world.setBlock(x + 17, y + 11, z + 21, Blocks.log2, 1, 3);
		world.setBlock(x + 8, y + 11, z + 22, Blocks.log2, 1, 3);
		world.setBlock(x + 9, y + 11, z + 22, Blocks.log2, 1, 3);
		world.setBlock(x + 10, y + 11, z + 22, Blocks.log2, 1, 3);
		world.setBlock(x + 18, y + 11, z + 22, Blocks.log2, 1, 3);
		world.setBlock(x + 8, y + 11, z + 23, Blocks.log2, 9, 3);
		world.setBlock(x + 19, y + 11, z + 23, Blocks.log2, 5, 3);
		world.setBlock(x + 9, y + 12, z + 13, Blocks.log2, 1, 3);
		world.setBlock(x + 13, y + 12, z + 13, Blocks.log2, 1, 3);
		world.setBlock(x + 14, y + 12, z + 13, Blocks.log2, 1, 3);
		world.setBlock(x + 18, y + 12, z + 13, Blocks.log2, 1, 3);
		world.setBlock(x + 10, y + 12, z + 14, Blocks.log2, 1, 3);
		world.setBlock(x + 12, y + 12, z + 14, Blocks.log2, 1, 3);
		world.setBlock(x + 13, y + 12, z + 14, Blocks.log2, 1, 3);
		world.setBlock(x + 14, y + 12, z + 14, Blocks.log2, 1, 3);
		world.setBlock(x + 15, y + 12, z + 14, Blocks.log2, 1, 3);
		world.setBlock(x + 17, y + 12, z + 14, Blocks.log2, 1, 3);
		world.setBlock(x + 11, y + 12, z + 15, Blocks.log2, 1, 3);
		world.setBlock(x + 12, y + 12, z + 15, Blocks.log2, 1, 3);
		world.setBlock(x + 13, y + 12, z + 15, Blocks.log2, 1, 3);
		world.setBlock(x + 14, y + 12, z + 15, Blocks.log2, 1, 3);
		world.setBlock(x + 15, y + 12, z + 15, Blocks.log2, 1, 3);
		world.setBlock(x + 16, y + 12, z + 15, Blocks.log2, 1, 3);
		world.setBlock(x + 10, y + 12, z + 16, Blocks.log2, 1, 3);
		world.setBlock(x + 11, y + 12, z + 16, Blocks.log2, 1, 3);
		world.setBlock(x + 12, y + 12, z + 16, Blocks.log2, 1, 3);
		world.setBlock(x + 13, y + 12, z + 16, Blocks.log2, 1, 3);
		world.setBlock(x + 14, y + 12, z + 16, Blocks.log2, 1, 3);
		world.setBlock(x + 15, y + 12, z + 16, Blocks.log2, 1, 3);
		world.setBlock(x + 16, y + 12, z + 16, Blocks.log2, 1, 3);
		world.setBlock(x + 17, y + 12, z + 16, Blocks.log2, 1, 3);
		world.setBlock(x + 9, y + 12, z + 17, Blocks.log2, 1, 3);
		world.setBlock(x + 10, y + 12, z + 17, Blocks.log2, 1, 3);
		world.setBlock(x + 11, y + 12, z + 17, Blocks.log2, 1, 3);
		world.setBlock(x + 12, y + 12, z + 17, Blocks.log2, 1, 3);
		world.setBlock(x + 13, y + 12, z + 17, Blocks.log2, 1, 3);
		world.setBlock(x + 14, y + 12, z + 17, Blocks.log2, 1, 3);
		world.setBlock(x + 15, y + 12, z + 17, Blocks.log2, 1, 3);
		world.setBlock(x + 16, y + 12, z + 17, Blocks.log2, 1, 3);
		world.setBlock(x + 17, y + 12, z + 17, Blocks.log2, 1, 3);
		world.setBlock(x + 18, y + 12, z + 17, Blocks.log2, 1, 3);
		world.setBlock(x + 9, y + 12, z + 18, Blocks.log2, 1, 3);
		world.setBlock(x + 10, y + 12, z + 18, Blocks.log2, 1, 3);
		world.setBlock(x + 11, y + 12, z + 18, Blocks.log2, 1, 3);
		world.setBlock(x + 12, y + 12, z + 18, Blocks.log2, 1, 3);
		world.setBlock(x + 13, y + 12, z + 18, Blocks.log2, 1, 3);
		world.setBlock(x + 14, y + 12, z + 18, Blocks.log2, 1, 3);
		world.setBlock(x + 15, y + 12, z + 18, Blocks.log2, 1, 3);
		world.setBlock(x + 16, y + 12, z + 18, Blocks.log2, 1, 3);
		world.setBlock(x + 17, y + 12, z + 18, Blocks.log2, 1, 3);
		world.setBlock(x + 18, y + 12, z + 18, Blocks.log2, 1, 3);
		world.setBlock(x + 10, y + 12, z + 19, Blocks.log2, 1, 3);
		world.setBlock(x + 11, y + 12, z + 19, Blocks.log2, 1, 3);
		world.setBlock(x + 12, y + 12, z + 19, Blocks.log2, 1, 3);
		world.setBlock(x + 13, y + 12, z + 19, Blocks.log2, 1, 3);
		world.setBlock(x + 14, y + 12, z + 19, Blocks.log2, 1, 3);
		world.setBlock(x + 15, y + 12, z + 19, Blocks.log2, 1, 3);
		world.setBlock(x + 16, y + 12, z + 19, Blocks.log2, 1, 3);
		world.setBlock(x + 17, y + 12, z + 19, Blocks.log2, 1, 3);
		world.setBlock(x + 11, y + 12, z + 20, Blocks.log2, 1, 3);
		world.setBlock(x + 12, y + 12, z + 20, Blocks.log2, 1, 3);
		world.setBlock(x + 13, y + 12, z + 20, Blocks.log2, 1, 3);
		world.setBlock(x + 14, y + 12, z + 20, Blocks.log2, 1, 3);
		world.setBlock(x + 15, y + 12, z + 20, Blocks.log2, 1, 3);
		world.setBlock(x + 16, y + 12, z + 20, Blocks.log2, 1, 3);
		world.setBlock(x + 10, y + 12, z + 21, Blocks.log2, 1, 3);
		world.setBlock(x + 12, y + 12, z + 21, Blocks.log2, 1, 3);
		world.setBlock(x + 13, y + 12, z + 21, Blocks.log2, 1, 3);
		world.setBlock(x + 14, y + 12, z + 21, Blocks.log2, 1, 3);
		world.setBlock(x + 15, y + 12, z + 21, Blocks.log2, 1, 3);
		world.setBlock(x + 17, y + 12, z + 21, Blocks.log2, 1, 3);
		world.setBlock(x + 9, y + 12, z + 22, Blocks.log2, 1, 3);
		world.setBlock(x + 13, y + 12, z + 22, Blocks.log2, 1, 3);
		world.setBlock(x + 14, y + 12, z + 22, Blocks.log2, 1, 3);
		world.setBlock(x + 18, y + 12, z + 22, Blocks.log2, 1, 3);
		world.setBlock(x + 13, y + 13, z + 14, Blocks.log2, 1, 3);
		world.setBlock(x + 14, y + 13, z + 14, Blocks.log2, 1, 3);
		world.setBlock(x + 11, y + 13, z + 15, Blocks.log2, 1, 3);
		world.setBlock(x + 12, y + 13, z + 15, Blocks.log2, 1, 3);
		world.setBlock(x + 13, y + 13, z + 15, Blocks.log2, 1, 3);
		world.setBlock(x + 14, y + 13, z + 15, Blocks.log2, 1, 3);
		world.setBlock(x + 15, y + 13, z + 15, Blocks.log2, 1, 3);
		world.setBlock(x + 16, y + 13, z + 15, Blocks.log2, 1, 3);
		world.setBlock(x + 11, y + 13, z + 16, Blocks.log2, 1, 3);
		world.setBlock(x + 12, y + 13, z + 16, Blocks.log2, 1, 3);
		world.setBlock(x + 13, y + 13, z + 16, Blocks.log2, 1, 3);
		world.setBlock(x + 14, y + 13, z + 16, Blocks.log2, 1, 3);
		world.setBlock(x + 15, y + 13, z + 16, Blocks.log2, 1, 3);
		world.setBlock(x + 16, y + 13, z + 16, Blocks.log2, 1, 3);
		world.setBlock(x + 10, y + 13, z + 17, Blocks.log2, 1, 3);
		world.setBlock(x + 11, y + 13, z + 17, Blocks.log2, 1, 3);
		world.setBlock(x + 12, y + 13, z + 17, Blocks.log2, 1, 3);
		world.setBlock(x + 13, y + 13, z + 17, Blocks.log2, 1, 3);
		world.setBlock(x + 14, y + 13, z + 17, Blocks.log2, 1, 3);
		world.setBlock(x + 15, y + 13, z + 17, Blocks.log2, 1, 3);
		world.setBlock(x + 16, y + 13, z + 17, Blocks.log2, 1, 3);
		world.setBlock(x + 17, y + 13, z + 17, Blocks.log2, 1, 3);
		world.setBlock(x + 10, y + 13, z + 18, Blocks.log2, 1, 3);
		world.setBlock(x + 11, y + 13, z + 18, Blocks.log2, 1, 3);
		world.setBlock(x + 12, y + 13, z + 18, Blocks.log2, 1, 3);
		world.setBlock(x + 13, y + 13, z + 18, Blocks.log2, 1, 3);
		world.setBlock(x + 14, y + 13, z + 18, Blocks.log2, 1, 3);
		world.setBlock(x + 15, y + 13, z + 18, Blocks.log2, 1, 3);
		world.setBlock(x + 16, y + 13, z + 18, Blocks.log2, 1, 3);
		world.setBlock(x + 17, y + 13, z + 18, Blocks.log2, 1, 3);
		world.setBlock(x + 11, y + 13, z + 19, Blocks.log2, 1, 3);
		world.setBlock(x + 12, y + 13, z + 19, Blocks.log2, 1, 3);
		world.setBlock(x + 13, y + 13, z + 19, Blocks.log2, 1, 3);
		world.setBlock(x + 14, y + 13, z + 19, Blocks.log2, 1, 3);
		world.setBlock(x + 15, y + 13, z + 19, Blocks.log2, 1, 3);
		world.setBlock(x + 16, y + 13, z + 19, Blocks.log2, 1, 3);
		world.setBlock(x + 11, y + 13, z + 20, Blocks.log2, 1, 3);
		world.setBlock(x + 12, y + 13, z + 20, Blocks.log2, 1, 3);
		world.setBlock(x + 13, y + 13, z + 20, Blocks.log2, 1, 3);
		world.setBlock(x + 14, y + 13, z + 20, Blocks.log2, 1, 3);
		world.setBlock(x + 15, y + 13, z + 20, Blocks.log2, 1, 3);
		world.setBlock(x + 16, y + 13, z + 20, Blocks.log2, 1, 3);
		world.setBlock(x + 13, y + 13, z + 21, Blocks.log2, 1, 3);
		world.setBlock(x + 14, y + 13, z + 21, Blocks.log2, 1, 3);
		world.setBlock(x + 12, y + 14, z + 15, Blocks.log2, 1, 3);
		world.setBlock(x + 13, y + 14, z + 15, Blocks.log2, 1, 3);
		world.setBlock(x + 14, y + 14, z + 15, Blocks.log2, 1, 3);
		world.setBlock(x + 15, y + 14, z + 15, Blocks.log2, 1, 3);
		world.setBlock(x + 11, y + 14, z + 16, Blocks.log2, 1, 3);
		world.setBlock(x + 12, y + 14, z + 16, Blocks.log2, 1, 3);
		world.setBlock(x + 13, y + 14, z + 16, Blocks.log2, 1, 3);
		world.setBlock(x + 14, y + 14, z + 16, Blocks.log2, 1, 3);
		world.setBlock(x + 15, y + 14, z + 16, Blocks.log2, 1, 3);
		world.setBlock(x + 16, y + 14, z + 16, Blocks.log2, 1, 3);
		world.setBlock(x + 11, y + 14, z + 17, Blocks.log2, 1, 3);
		world.setBlock(x + 12, y + 14, z + 17, Blocks.log2, 1, 3);
		world.setBlock(x + 13, y + 14, z + 17, Blocks.log2, 1, 3);
		world.setBlock(x + 14, y + 14, z + 17, Blocks.log2, 1, 3);
		world.setBlock(x + 15, y + 14, z + 17, Blocks.log2, 1, 3);
		world.setBlock(x + 16, y + 14, z + 17, Blocks.log2, 1, 3);
		world.setBlock(x + 11, y + 14, z + 18, Blocks.log2, 1, 3);
		world.setBlock(x + 12, y + 14, z + 18, Blocks.log2, 1, 3);
		world.setBlock(x + 13, y + 14, z + 18, Blocks.log2, 1, 3);
		world.setBlock(x + 14, y + 14, z + 18, Blocks.log2, 1, 3);
		world.setBlock(x + 15, y + 14, z + 18, Blocks.log2, 1, 3);
		world.setBlock(x + 16, y + 14, z + 18, Blocks.log2, 1, 3);
		world.setBlock(x + 11, y + 14, z + 19, Blocks.log2, 1, 3);
		world.setBlock(x + 12, y + 14, z + 19, Blocks.log2, 1, 3);
		world.setBlock(x + 13, y + 14, z + 19, Blocks.log2, 1, 3);
		world.setBlock(x + 14, y + 14, z + 19, Blocks.log2, 1, 3);
		world.setBlock(x + 15, y + 14, z + 19, Blocks.log2, 1, 3);
		world.setBlock(x + 16, y + 14, z + 19, Blocks.log2, 1, 3);
		world.setBlock(x + 12, y + 14, z + 20, Blocks.log2, 1, 3);
		world.setBlock(x + 13, y + 14, z + 20, Blocks.log2, 1, 3);
		world.setBlock(x + 14, y + 14, z + 20, Blocks.log2, 1, 3);
		world.setBlock(x + 15, y + 14, z + 20, Blocks.log2, 1, 3);
		world.setBlock(x + 13, y + 15, z + 15, Blocks.log2, 1, 3);
		world.setBlock(x + 14, y + 15, z + 15, Blocks.log2, 1, 3);
		world.setBlock(x + 12, y + 15, z + 16, Blocks.log2, 1, 3);
		world.setBlock(x + 13, y + 15, z + 16, Blocks.log2, 1, 3);
		world.setBlock(x + 14, y + 15, z + 16, Blocks.log2, 1, 3);
		world.setBlock(x + 15, y + 15, z + 16, Blocks.log2, 1, 3);
		world.setBlock(x + 11, y + 15, z + 17, Blocks.log2, 1, 3);
		world.setBlock(x + 12, y + 15, z + 17, Blocks.log2, 1, 3);
		world.setBlock(x + 13, y + 15, z + 17, Blocks.log2, 1, 3);
		world.setBlock(x + 14, y + 15, z + 17, Blocks.log2, 1, 3);
		world.setBlock(x + 15, y + 15, z + 17, Blocks.log2, 1, 3);
		world.setBlock(x + 16, y + 15, z + 17, Blocks.log2, 1, 3);
		world.setBlock(x + 11, y + 15, z + 18, Blocks.log2, 1, 3);
		world.setBlock(x + 12, y + 15, z + 18, Blocks.log2, 1, 3);
		world.setBlock(x + 13, y + 15, z + 18, Blocks.log2, 1, 3);
		world.setBlock(x + 14, y + 15, z + 18, Blocks.log2, 1, 3);
		world.setBlock(x + 15, y + 15, z + 18, Blocks.log2, 1, 3);
		world.setBlock(x + 16, y + 15, z + 18, Blocks.log2, 1, 3);
		world.setBlock(x + 12, y + 15, z + 19, Blocks.log2, 1, 3);
		world.setBlock(x + 13, y + 15, z + 19, Blocks.log2, 1, 3);
		world.setBlock(x + 14, y + 15, z + 19, Blocks.log2, 1, 3);
		world.setBlock(x + 15, y + 15, z + 19, Blocks.log2, 1, 3);
		world.setBlock(x + 13, y + 15, z + 20, Blocks.log2, 1, 3);
		world.setBlock(x + 14, y + 15, z + 20, Blocks.log2, 1, 3);
		world.setBlock(x + 12, y + 16, z + 16, Blocks.log2, 1, 3);
		world.setBlock(x + 13, y + 16, z + 16, Blocks.log2, 1, 3);
		world.setBlock(x + 14, y + 16, z + 16, Blocks.log2, 1, 3);
		world.setBlock(x + 15, y + 16, z + 16, Blocks.log2, 1, 3);
		world.setBlock(x + 12, y + 16, z + 17, Blocks.log2, 1, 3);
		world.setBlock(x + 13, y + 16, z + 17, Blocks.log2, 1, 3);
		world.setBlock(x + 14, y + 16, z + 17, Blocks.log2, 1, 3);
		world.setBlock(x + 15, y + 16, z + 17, Blocks.log2, 1, 3);
		world.setBlock(x + 16, y + 16, z + 17, Blocks.log2, 1, 3);
		world.setBlock(x + 12, y + 16, z + 18, Blocks.log2, 1, 3);
		world.setBlock(x + 13, y + 16, z + 18, Blocks.log2, 1, 3);
		world.setBlock(x + 14, y + 16, z + 18, Blocks.log2, 1, 3);
		world.setBlock(x + 15, y + 16, z + 18, Blocks.log2, 1, 3);
		world.setBlock(x + 16, y + 16, z + 18, Blocks.log2, 1, 3);
		world.setBlock(x + 12, y + 16, z + 19, Blocks.log2, 1, 3);
		world.setBlock(x + 13, y + 16, z + 19, Blocks.log2, 1, 3);
		world.setBlock(x + 14, y + 16, z + 19, Blocks.log2, 1, 3);
		world.setBlock(x + 15, y + 16, z + 19, Blocks.log2, 1, 3);
		world.setBlock(x + 13, y + 16, z + 20, Blocks.log2, 1, 3);
		world.setBlock(x + 14, y + 16, z + 20, Blocks.log2, 1, 3);
		world.setBlock(x + 12, y + 17, z + 16, Blocks.log2, 1, 3);
		world.setBlock(x + 13, y + 17, z + 16, Blocks.log2, 1, 3);
		world.setBlock(x + 14, y + 17, z + 16, Blocks.log2, 1, 3);
		world.setBlock(x + 15, y + 17, z + 16, Blocks.log2, 1, 3);
		world.setBlock(x + 12, y + 17, z + 17, Blocks.log2, 1, 3);
		world.setBlock(x + 13, y + 17, z + 17, Blocks.log2, 1, 3);
		world.setBlock(x + 14, y + 17, z + 17, Blocks.log2, 1, 3);
		world.setBlock(x + 15, y + 17, z + 17, Blocks.log2, 1, 3);
		world.setBlock(x + 12, y + 17, z + 18, Blocks.log2, 1, 3);
		world.setBlock(x + 13, y + 17, z + 18, Blocks.log2, 1, 3);
		world.setBlock(x + 14, y + 17, z + 18, Blocks.log2, 1, 3);
		world.setBlock(x + 15, y + 17, z + 18, Blocks.log2, 1, 3);
		world.setBlock(x + 12, y + 17, z + 19, Blocks.log2, 1, 3);
		world.setBlock(x + 13, y + 17, z + 19, Blocks.log2, 1, 3);
		world.setBlock(x + 14, y + 17, z + 19, Blocks.log2, 1, 3);
		world.setBlock(x + 15, y + 17, z + 19, Blocks.log2, 1, 3);
		world.setBlock(x + 13, y + 18, z + 16, Blocks.log2, 1, 3);
		world.setBlock(x + 14, y + 18, z + 16, Blocks.log2, 1, 3);
		world.setBlock(x + 12, y + 18, z + 17, Blocks.log2, 1, 3);
		world.setBlock(x + 13, y + 18, z + 17, Blocks.log2, 1, 3);
		world.setBlock(x + 14, y + 18, z + 17, Blocks.log2, 1, 3);
		world.setBlock(x + 15, y + 18, z + 17, Blocks.log2, 1, 3);
		world.setBlock(x + 12, y + 18, z + 18, Blocks.log2, 1, 3);
		world.setBlock(x + 13, y + 18, z + 18, Blocks.log2, 1, 3);
		world.setBlock(x + 14, y + 18, z + 18, Blocks.log2, 1, 3);
		world.setBlock(x + 15, y + 18, z + 18, Blocks.log2, 1, 3);
		world.setBlock(x + 13, y + 18, z + 19, Blocks.log2, 1, 3);
		world.setBlock(x + 14, y + 18, z + 19, Blocks.log2, 1, 3);
		world.setBlock(x + 13, y + 19, z + 16, Blocks.log2, 1, 3);
		world.setBlock(x + 14, y + 19, z + 16, Blocks.log2, 1, 3);
		world.setBlock(x + 12, y + 19, z + 17, Blocks.log2, 1, 3);
		world.setBlock(x + 13, y + 19, z + 17, Blocks.log2, 1, 3);
		world.setBlock(x + 14, y + 19, z + 17, Blocks.log2, 1, 3);
		world.setBlock(x + 15, y + 19, z + 17, Blocks.log2, 1, 3);
		world.setBlock(x + 12, y + 19, z + 18, Blocks.log2, 1, 3);
		world.setBlock(x + 13, y + 19, z + 18, Blocks.log2, 1, 3);
		world.setBlock(x + 14, y + 19, z + 18, Blocks.log2, 1, 3);
		world.setBlock(x + 15, y + 19, z + 18, Blocks.log2, 1, 3);
		world.setBlock(x + 13, y + 19, z + 19, Blocks.log2, 1, 3);
		world.setBlock(x + 14, y + 19, z + 19, Blocks.log2, 1, 3);
		world.setBlock(x + 13, y + 20, z + 16, Blocks.log2, 1, 3);
		world.setBlock(x + 12, y + 20, z + 17, Blocks.log2, 1, 3);
		world.setBlock(x + 13, y + 20, z + 17, Blocks.log2, 1, 3);
		world.setBlock(x + 14, y + 20, z + 17, Blocks.log2, 1, 3);
		world.setBlock(x + 15, y + 20, z + 17, Blocks.log2, 1, 3);
		world.setBlock(x + 13, y + 20, z + 18, Blocks.log2, 1, 3);
		world.setBlock(x + 14, y + 20, z + 18, Blocks.log2, 1, 3);
		world.setBlock(x + 15, y + 20, z + 18, Blocks.log2, 1, 3);
		world.setBlock(x + 13, y + 20, z + 19, Blocks.log2, 1, 3);
		world.setBlock(x + 14, y + 20, z + 19, Blocks.log2, 1, 3);
		world.setBlock(x + 13, y + 21, z + 17, Blocks.log2, 1, 3);
		world.setBlock(x + 14, y + 21, z + 17, Blocks.log2, 1, 3);
		world.setBlock(x + 15, y + 21, z + 17, Blocks.log2, 1, 3);
		world.setBlock(x + 13, y + 21, z + 18, Blocks.log2, 1, 3);
		world.setBlock(x + 14, y + 21, z + 18, Blocks.log2, 1, 3);
		world.setBlock(x + 13, y + 21, z + 19, Blocks.log2, 1, 3);
		world.setBlock(x + 13, y + 22, z + 17, Blocks.log2, 1, 3);
		world.setBlock(x + 14, y + 22, z + 17, Blocks.log2, 1, 3);
		world.setBlock(x + 13, y + 22, z + 18, Blocks.log2, 1, 3);
		world.setBlock(x + 14, y + 22, z + 18, Blocks.log2, 1, 3);
		world.setBlock(x + 13, y + 23, z + 17, Blocks.log2, 1, 3);
		world.setBlock(x + 14, y + 23, z + 17, Blocks.log2, 1, 3);
		world.setBlock(x + 13, y + 23, z + 18, Blocks.log2, 1, 3);
		world.setBlock(x + 14, y + 23, z + 18, Blocks.log2, 1, 3);
		world.setBlock(x + 13, y + 24, z + 17, Blocks.log2, 1, 3);
		world.setBlock(x + 14, y + 24, z + 17, Blocks.log2, 1, 3);
		world.setBlock(x + 15, y + 24, z + 17, Blocks.log2, 1, 3);
		world.setBlock(x + 13, y + 24, z + 18, Blocks.log2, 1, 3);
		world.setBlock(x + 14, y + 24, z + 18, Blocks.log2, 1, 3);
		world.setBlock(x + 13, y + 25, z + 16, Blocks.log2, 1, 3);
		world.setBlock(x + 14, y + 25, z + 16, Blocks.leaves2, 5, 3);
		world.setBlock(x + 13, y + 25, z + 17, Blocks.log2, 1, 3);
		world.setBlock(x + 14, y + 25, z + 17, Blocks.log2, 1, 3);
		world.setBlock(x + 15, y + 25, z + 17, Blocks.log2, 1, 3);
		world.setBlock(x + 13, y + 25, z + 18, Blocks.log2, 1, 3);
		world.setBlock(x + 14, y + 25, z + 18, Blocks.log2, 1, 3);
		world.setBlock(x + 15, y + 25, z + 18, Blocks.leaves2, 5, 3);
		world.setBlock(x + 14, y + 25, z + 19, Blocks.log2, 1, 3);
		world.setBlock(x + 21, y + 25, z + 23, Blocks.leaves2, 5, 3);
		world.setBlock(x + 17, y + 26, z + 14, Blocks.leaves2, 5, 3);
		world.setBlock(x + 13, y + 26, z + 15, Blocks.log2, 1, 3);
		world.setBlock(x + 4, y + 26, z + 16, Blocks.leaves2, 5, 3);
		world.setBlock(x + 12, y + 26, z + 16, Blocks.leaves2, 5, 3);
		world.setBlock(x + 13, y + 26, z + 16, Blocks.log2, 1, 3);
		world.setBlock(x + 14, y + 26, z + 16, Blocks.log2, 1, 3);
		world.setBlock(x + 15, y + 26, z + 16, Blocks.leaves2, 5, 3);
		world.setBlock(x + 12, y + 26, z + 17, Blocks.log2, 1, 3);
		world.setBlock(x + 13, y + 26, z + 17, Blocks.log2, 1, 3);
		world.setBlock(x + 14, y + 26, z + 17, Blocks.log2, 1, 3);
		world.setBlock(x + 15, y + 26, z + 17, Blocks.log2, 1, 3);
		world.setBlock(x + 12, y + 26, z + 18, Blocks.leaves2, 5, 3);
		world.setBlock(x + 13, y + 26, z + 18, Blocks.log2, 1, 3);
		world.setBlock(x + 14, y + 26, z + 18, Blocks.log2, 1, 3);
		world.setBlock(x + 15, y + 26, z + 18, Blocks.log2, 1, 3);
		world.setBlock(x + 13, y + 26, z + 19, Blocks.log2, 1, 3);
		world.setBlock(x + 14, y + 26, z + 19, Blocks.log2, 1, 3);
		world.setBlock(x + 14, y + 26, z + 20, Blocks.leaves2, 13, 3);
		world.setBlock(x + 16, y + 26, z + 22, Blocks.leaves2, 13, 3);
		world.setBlock(x + 20, y + 26, z + 23, Blocks.leaves2, 5, 3);
		world.setBlock(x + 21, y + 26, z + 23, Blocks.leaves2, 5, 3);
		world.setBlock(x + 13, y + 27, z + 6, Blocks.leaves2, 13, 3);
		world.setBlock(x + 14, y + 27, z + 6, Blocks.leaves2, 13, 3);
		world.setBlock(x + 16, y + 27, z + 6, Blocks.leaves2, 5, 3);
		world.setBlock(x + 11, y + 27, z + 8, Blocks.leaves2, 13, 3);
		world.setBlock(x + 5, y + 27, z + 10, Blocks.leaves2, 5, 3);
		world.setBlock(x + 10, y + 27, z + 10, Blocks.leaves2, 5, 3);
		world.setBlock(x + 8, y + 27, z + 11, Blocks.leaves2, 5, 3);
		world.setBlock(x + 20, y + 27, z + 11, Blocks.leaves2, 5, 3);
		world.setBlock(x + 7, y + 27, z + 13, Blocks.leaves2, 5, 3);
		world.setBlock(x + 17, y + 27, z + 13, Blocks.leaves2, 13, 3);
		world.setBlock(x + 17, y + 27, z + 14, Blocks.leaves2, 13, 3);
		world.setBlock(x + 18, y + 27, z + 14, Blocks.leaves2, 5, 3);
		world.setBlock(x + 4, y + 27, z + 15, Blocks.leaves2, 5, 3);
		world.setBlock(x + 12, y + 27, z + 15, Blocks.leaves2, 5, 3);
		world.setBlock(x + 13, y + 27, z + 15, Blocks.log2, 1, 3);
		world.setBlock(x + 14, y + 27, z + 15, Blocks.leaves2, 5, 3);
		world.setBlock(x + 4, y + 27, z + 16, Blocks.leaves2, 5, 3);
		world.setBlock(x + 5, y + 27, z + 16, Blocks.leaves2, 5, 3);
		world.setBlock(x + 12, y + 27, z + 16, Blocks.log2, 1, 3);
		world.setBlock(x + 13, y + 27, z + 16, Blocks.log2, 1, 3);
		world.setBlock(x + 14, y + 27, z + 16, Blocks.log2, 1, 3);
		world.setBlock(x + 15, y + 27, z + 16, Blocks.leaves2, 5, 3);
		world.setBlock(x + 12, y + 27, z + 17, Blocks.log2, 1, 3);
		world.setBlock(x + 13, y + 27, z + 17, Blocks.log2, 1, 3);
		world.setBlock(x + 14, y + 27, z + 17, Blocks.log2, 1, 3);
		world.setBlock(x + 15, y + 27, z + 17, Blocks.log2, 1, 3);
		world.setBlock(x + 16, y + 27, z + 17, Blocks.log2, 1, 3);
		world.setBlock(x + 7, y + 27, z + 18, Blocks.leaves2, 5, 3);
		world.setBlock(x + 12, y + 27, z + 18, Blocks.log2, 1, 3);
		world.setBlock(x + 13, y + 27, z + 18, Blocks.log2, 1, 3);
		world.setBlock(x + 14, y + 27, z + 18, Blocks.log2, 1, 3);
		world.setBlock(x + 15, y + 27, z + 18, Blocks.log2, 1, 3);
		world.setBlock(x + 16, y + 27, z + 18, Blocks.leaves2, 5, 3);
		world.setBlock(x + 23, y + 27, z + 18, Blocks.leaves2, 5, 3);
		world.setBlock(x + 12, y + 27, z + 19, Blocks.leaves2, 13, 3);
		world.setBlock(x + 13, y + 27, z + 19, Blocks.log2, 1, 3);
		world.setBlock(x + 14, y + 27, z + 19, Blocks.log2, 1, 3);
		world.setBlock(x + 15, y + 27, z + 19, Blocks.log2, 1, 3);
		world.setBlock(x + 14, y + 27, z + 20, Blocks.log2, 1, 3);
		world.setBlock(x + 2, y + 27, z + 21, Blocks.leaves2, 5, 3);
		world.setBlock(x + 15, y + 27, z + 22, Blocks.leaves2, 5, 3);
		world.setBlock(x + 16, y + 27, z + 22, Blocks.leaves2, 13, 3);
		world.setBlock(x + 17, y + 27, z + 22, Blocks.leaves2, 13, 3);
		world.setBlock(x + 20, y + 27, z + 22, Blocks.leaves2, 13, 3);
		world.setBlock(x + 21, y + 27, z + 22, Blocks.leaves2, 5, 3);
		world.setBlock(x + 12, y + 27, z + 23, Blocks.leaves2, 5, 3);
		world.setBlock(x + 16, y + 27, z + 23, Blocks.leaves2, 13, 3);
		world.setBlock(x + 19, y + 27, z + 23, Blocks.leaves2, 5, 3);
		world.setBlock(x + 20, y + 27, z + 23, Blocks.leaves2, 13, 3);
		world.setBlock(x + 21, y + 27, z + 23, Blocks.leaves2, 13, 3);
		world.setBlock(x + 22, y + 27, z + 23, Blocks.leaves2, 5, 3);
		world.setBlock(x + 4, y + 27, z + 24, Blocks.leaves2, 5, 3);
		world.setBlock(x + 20, y + 27, z + 24, Blocks.leaves2, 5, 3);
		world.setBlock(x + 21, y + 27, z + 24, Blocks.leaves2, 5, 3);
		world.setBlock(x + 7, y + 27, z + 29, Blocks.leaves2, 13, 3);
		world.setBlock(x + 6, y + 27, z + 30, Blocks.leaves2, 13, 3);
		world.setBlock(x + 14, y + 27, z + 30, Blocks.leaves2, 5, 3);
		world.setBlock(x + 14, y + 27, z + 31, Blocks.leaves2, 5, 3);
		world.setBlock(x + 17, y + 28, z + 4, Blocks.leaves2, 5, 3);
		world.setBlock(x + 11, y + 28, z + 5, Blocks.leaves2, 5, 3);
		world.setBlock(x + 14, y + 28, z + 5, Blocks.leaves2, 13, 3);
		world.setBlock(x + 15, y + 28, z + 5, Blocks.leaves2, 5, 3);
		world.setBlock(x + 13, y + 28, z + 6, Blocks.leaves2, 13, 3);
		world.setBlock(x + 14, y + 28, z + 6, Blocks.leaves2, 13, 3);
		world.setBlock(x + 15, y + 28, z + 6, Blocks.leaves2, 5, 3);
		world.setBlock(x + 16, y + 28, z + 6, Blocks.leaves2, 5, 3);
		world.setBlock(x + 7, y + 28, z + 7, Blocks.leaves2, 5, 3);
		world.setBlock(x + 11, y + 28, z + 7, Blocks.leaves2, 5, 3);
		world.setBlock(x + 13, y + 28, z + 7, Blocks.leaves2, 13, 3);
		world.setBlock(x + 14, y + 28, z + 7, Blocks.leaves2, 5, 3);
		world.setBlock(x + 11, y + 28, z + 8, Blocks.leaves2, 13, 3);
		world.setBlock(x + 17, y + 28, z + 8, Blocks.leaves2, 5, 3);
		world.setBlock(x + 5, y + 28, z + 9, Blocks.leaves2, 5, 3);
		world.setBlock(x + 8, y + 28, z + 9, Blocks.leaves2, 5, 3);
		world.setBlock(x + 9, y + 28, z + 9, Blocks.leaves2, 5, 3);
		world.setBlock(x + 10, y + 28, z + 9, Blocks.leaves2, 5, 3);
		world.setBlock(x + 11, y + 28, z + 9, Blocks.leaves2, 13, 3);
		world.setBlock(x + 12, y + 28, z + 9, Blocks.leaves2, 13, 3);
		world.setBlock(x + 17, y + 28, z + 9, Blocks.leaves2, 5, 3);
		world.setBlock(x + 18, y + 28, z + 9, Blocks.leaves2, 5, 3);
		world.setBlock(x + 4, y + 28, z + 10, Blocks.leaves2, 5, 3);
		world.setBlock(x + 5, y + 28, z + 10, Blocks.leaves2, 5, 3);
		world.setBlock(x + 6, y + 28, z + 10, Blocks.leaves2, 5, 3);
		world.setBlock(x + 8, y + 28, z + 10, Blocks.leaves2, 5, 3);
		world.setBlock(x + 9, y + 28, z + 10, Blocks.leaves2, 5, 3);
		world.setBlock(x + 10, y + 28, z + 10, Blocks.leaves2, 5, 3);
		world.setBlock(x + 15, y + 28, z + 10, Blocks.leaves2, 5, 3);
		world.setBlock(x + 17, y + 28, z + 10, Blocks.leaves2, 5, 3);
		world.setBlock(x + 18, y + 28, z + 10, Blocks.leaves2, 5, 3);
		world.setBlock(x + 20, y + 28, z + 10, Blocks.leaves2, 13, 3);
		world.setBlock(x + 5, y + 28, z + 11, Blocks.leaves2, 5, 3);
		world.setBlock(x + 8, y + 28, z + 11, Blocks.leaves2, 5, 3);
		world.setBlock(x + 9, y + 28, z + 11, Blocks.leaves2, 5, 3);
		world.setBlock(x + 19, y + 28, z + 11, Blocks.leaves2, 5, 3);
		world.setBlock(x + 20, y + 28, z + 11, Blocks.leaves2, 13, 3);
		world.setBlock(x + 21, y + 28, z + 11, Blocks.leaves2, 13, 3);
		world.setBlock(x + 14, y + 28, z + 12, Blocks.leaves2, 5, 3);
		world.setBlock(x + 20, y + 28, z + 12, Blocks.leaves2, 13, 3);
		world.setBlock(x + 21, y + 28, z + 12, Blocks.leaves2, 13, 3);
		world.setBlock(x + 7, y + 28, z + 13, Blocks.leaves2, 5, 3);
		world.setBlock(x + 8, y + 28, z + 13, Blocks.leaves2, 5, 3);
		world.setBlock(x + 17, y + 28, z + 13, Blocks.leaves2, 13, 3);
		world.setBlock(x + 18, y + 28, z + 13, Blocks.leaves2, 13, 3);
		world.setBlock(x + 4, y + 28, z + 14, Blocks.leaves2, 5, 3);
		world.setBlock(x + 10, y + 28, z + 14, Blocks.leaves2, 5, 3);
		world.setBlock(x + 16, y + 28, z + 14, Blocks.leaves2, 5, 3);
		world.setBlock(x + 17, y + 28, z + 14, Blocks.leaves2, 13, 3);
		world.setBlock(x + 18, y + 28, z + 14, Blocks.leaves2, 5, 3);
		world.setBlock(x + 3, y + 28, z + 15, Blocks.leaves2, 5, 3);
		world.setBlock(x + 4, y + 28, z + 15, Blocks.leaves2, 5, 3);
		world.setBlock(x + 5, y + 28, z + 15, Blocks.leaves2, 5, 3);
		world.setBlock(x + 13, y + 28, z + 15, Blocks.log2, 1, 3);
		world.setBlock(x + 14, y + 28, z + 15, Blocks.log2, 1, 3);
		world.setBlock(x + 15, y + 28, z + 15, Blocks.leaves2, 5, 3);
		world.setBlock(x + 17, y + 28, z + 15, Blocks.leaves2, 5, 3);
		world.setBlock(x + 3, y + 28, z + 16, Blocks.leaves2, 13, 3);
		world.setBlock(x + 4, y + 28, z + 16, Blocks.leaves2, 13, 3);
		world.setBlock(x + 5, y + 28, z + 16, Blocks.leaves2, 5, 3);
		world.setBlock(x + 6, y + 28, z + 16, Blocks.leaves2, 5, 3);
		world.setBlock(x + 12, y + 28, z + 16, Blocks.log2, 1, 3);
		world.setBlock(x + 13, y + 28, z + 16, Blocks.log2, 1, 3);
		world.setBlock(x + 14, y + 28, z + 16, Blocks.log2, 1, 3);
		world.setBlock(x + 15, y + 28, z + 16, Blocks.log2, 1, 3);
		world.setBlock(x + 16, y + 28, z + 16, Blocks.leaves2, 5, 3);
		world.setBlock(x + 4, y + 28, z + 17, Blocks.leaves2, 5, 3);
		world.setBlock(x + 11, y + 28, z + 17, Blocks.log2, 1, 3);
		world.setBlock(x + 12, y + 28, z + 17, Blocks.log2, 1, 3);
		world.setBlock(x + 13, y + 28, z + 17, Blocks.leaves2, 13, 3);
		world.setBlock(x + 14, y + 28, z + 17, Blocks.leaves2, 13, 3);
		world.setBlock(x + 15, y + 28, z + 17, Blocks.log2, 1, 3);
		world.setBlock(x + 16, y + 28, z + 17, Blocks.log2, 1, 3);
		world.setBlock(x + 17, y + 28, z + 17, Blocks.leaves2, 5, 3);
		world.setBlock(x + 23, y + 28, z + 17, Blocks.leaves2, 5, 3);
		world.setBlock(x + 1, y + 28, z + 18, Blocks.leaves2, 5, 3);
		world.setBlock(x + 6, y + 28, z + 18, Blocks.leaves2, 5, 3);
		world.setBlock(x + 7, y + 28, z + 18, Blocks.leaves2, 5, 3);
		world.setBlock(x + 9, y + 28, z + 18, Blocks.leaves2, 5, 3);
		world.setBlock(x + 11, y + 28, z + 18, Blocks.leaves2, 5, 3);
		world.setBlock(x + 12, y + 28, z + 18, Blocks.log2, 1, 3);
		world.setBlock(x + 13, y + 28, z + 18, Blocks.leaves2, 13, 3);
		world.setBlock(x + 14, y + 28, z + 18, Blocks.leaves2, 13, 3);
		world.setBlock(x + 15, y + 28, z + 18, Blocks.log2, 1, 3);
		world.setBlock(x + 16, y + 28, z + 18, Blocks.log2, 1, 3);
		world.setBlock(x + 22, y + 28, z + 18, Blocks.leaves2, 13, 3);
		world.setBlock(x + 23, y + 28, z + 18, Blocks.leaves2, 13, 3);
		world.setBlock(x + 24, y + 28, z + 18, Blocks.leaves2, 13, 3);
		world.setBlock(x + 1, y + 28, z + 19, Blocks.leaves2, 5, 3);
		world.setBlock(x + 7, y + 28, z + 19, Blocks.leaves2, 5, 3);
		world.setBlock(x + 12, y + 28, z + 19, Blocks.log2, 1, 3);
		world.setBlock(x + 13, y + 28, z + 19, Blocks.log2, 1, 3);
		world.setBlock(x + 14, y + 28, z + 19, Blocks.log2, 1, 3);
		world.setBlock(x + 15, y + 28, z + 19, Blocks.log2, 1, 3);
		world.setBlock(x + 21, y + 28, z + 19, Blocks.leaves2, 5, 3);
		world.setBlock(x + 23, y + 28, z + 19, Blocks.leaves2, 5, 3);
		world.setBlock(x + 13, y + 28, z + 20, Blocks.leaves2, 13, 3);
		world.setBlock(x + 14, y + 28, z + 20, Blocks.log2, 1, 3);
		world.setBlock(x + 20, y + 28, z + 20, Blocks.leaves2, 5, 3);
		world.setBlock(x + 1, y + 28, z + 21, Blocks.leaves2, 5, 3);
		world.setBlock(x + 2, y + 28, z + 21, Blocks.leaves2, 5, 3);
		world.setBlock(x + 3, y + 28, z + 21, Blocks.leaves2, 5, 3);
		world.setBlock(x + 14, y + 28, z + 21, Blocks.leaves2, 5, 3);
		world.setBlock(x + 19, y + 28, z + 21, Blocks.leaves2, 5, 3);
		world.setBlock(x + 20, y + 28, z + 21, Blocks.leaves2, 5, 3);
		world.setBlock(x + 21, y + 28, z + 21, Blocks.leaves2, 5, 3);
		world.setBlock(x + 2, y + 28, z + 22, Blocks.leaves2, 5, 3);
		world.setBlock(x + 15, y + 28, z + 22, Blocks.leaves2, 13, 3);
		world.setBlock(x + 16, y + 28, z + 22, Blocks.leaves2, 13, 3);
		world.setBlock(x + 17, y + 28, z + 22, Blocks.leaves2, 5, 3);
		world.setBlock(x + 19, y + 28, z + 22, Blocks.leaves2, 5, 3);
		world.setBlock(x + 20, y + 28, z + 22, Blocks.leaves2, 5, 3);
		world.setBlock(x + 21, y + 28, z + 22, Blocks.leaves2, 5, 3);
		world.setBlock(x + 4, y + 28, z + 23, Blocks.leaves2, 5, 3);
		world.setBlock(x + 11, y + 28, z + 23, Blocks.leaves2, 5, 3);
		world.setBlock(x + 12, y + 28, z + 23, Blocks.leaves2, 5, 3);
		world.setBlock(x + 15, y + 28, z + 23, Blocks.leaves2, 13, 3);
		world.setBlock(x + 16, y + 28, z + 23, Blocks.leaves2, 13, 3);
		world.setBlock(x + 17, y + 28, z + 23, Blocks.leaves2, 5, 3);
		world.setBlock(x + 19, y + 28, z + 23, Blocks.leaves2, 5, 3);
		world.setBlock(x + 20, y + 28, z + 23, Blocks.leaves2, 5, 3);
		world.setBlock(x + 21, y + 28, z + 23, Blocks.leaves2, 5, 3);
		world.setBlock(x + 22, y + 28, z + 23, Blocks.leaves2, 5, 3);
		world.setBlock(x + 3, y + 28, z + 24, Blocks.leaves2, 5, 3);
		world.setBlock(x + 4, y + 28, z + 24, Blocks.leaves2, 5, 3);
		world.setBlock(x + 5, y + 28, z + 24, Blocks.leaves2, 5, 3);
		world.setBlock(x + 12, y + 28, z + 24, Blocks.leaves2, 5, 3);
		world.setBlock(x + 16, y + 28, z + 24, Blocks.leaves2, 5, 3);
		world.setBlock(x + 18, y + 28, z + 24, Blocks.leaves2, 5, 3);
		world.setBlock(x + 20, y + 28, z + 24, Blocks.leaves2, 5, 3);
		world.setBlock(x + 21, y + 28, z + 24, Blocks.leaves2, 5, 3);
		world.setBlock(x + 4, y + 28, z + 25, Blocks.leaves2, 5, 3);
		world.setBlock(x + 9, y + 28, z + 25, Blocks.leaves2, 5, 3);
		world.setBlock(x + 19, y + 28, z + 25, Blocks.leaves2, 5, 3);
		world.setBlock(x + 20, y + 28, z + 25, Blocks.leaves2, 5, 3);
		world.setBlock(x + 17, y + 28, z + 26, Blocks.leaves2, 5, 3);
		world.setBlock(x + 10, y + 28, z + 27, Blocks.leaves2, 5, 3);
		world.setBlock(x + 18, y + 28, z + 27, Blocks.leaves2, 5, 3);
		world.setBlock(x + 20, y + 28, z + 27, Blocks.leaves2, 5, 3);
		world.setBlock(x + 7, y + 28, z + 28, Blocks.leaves2, 13, 3);
		world.setBlock(x + 6, y + 28, z + 29, Blocks.leaves2, 13, 3);
		world.setBlock(x + 7, y + 28, z + 29, Blocks.leaves2, 13, 3);
		world.setBlock(x + 11, y + 28, z + 29, Blocks.leaves2, 5, 3);
		world.setBlock(x + 5, y + 28, z + 30, Blocks.leaves2, 13, 3);
		world.setBlock(x + 6, y + 28, z + 30, Blocks.leaves2, 13, 3);
		world.setBlock(x + 7, y + 28, z + 30, Blocks.leaves2, 13, 3);
		world.setBlock(x + 14, y + 28, z + 30, Blocks.leaves2, 5, 3);
		world.setBlock(x + 6, y + 28, z + 31, Blocks.leaves2, 5, 3);
		world.setBlock(x + 13, y + 28, z + 31, Blocks.leaves2, 5, 3);
		world.setBlock(x + 14, y + 28, z + 31, Blocks.leaves2, 5, 3);
		world.setBlock(x + 15, y + 28, z + 31, Blocks.leaves2, 5, 3);
		world.setBlock(x + 14, y + 28, z + 32, Blocks.leaves2, 5, 3);
		world.setBlock(x + 17, y + 29, z + 3, Blocks.leaves2, 13, 3);
		world.setBlock(x + 11, y + 29, z + 4, Blocks.leaves2, 5, 3);
		world.setBlock(x + 14, y + 29, z + 4, Blocks.leaves2, 13, 3);
		world.setBlock(x + 15, y + 29, z + 4, Blocks.leaves2, 13, 3);
		world.setBlock(x + 16, y + 29, z + 4, Blocks.leaves2, 13, 3);
		world.setBlock(x + 17, y + 29, z + 4, Blocks.leaves2, 5, 3);
		world.setBlock(x + 18, y + 29, z + 4, Blocks.leaves2, 5, 3);
		world.setBlock(x + 11, y + 29, z + 5, Blocks.leaves2, 5, 3);
		world.setBlock(x + 12, y + 29, z + 5, Blocks.leaves2, 5, 3);
		world.setBlock(x + 13, y + 29, z + 5, Blocks.leaves2, 13, 3);
		world.setBlock(x + 14, y + 29, z + 5, Blocks.leaves2, 13, 3);
		world.setBlock(x + 15, y + 29, z + 5, Blocks.leaves2, 5, 3);
		world.setBlock(x + 16, y + 29, z + 5, Blocks.leaves2, 5, 3);
		world.setBlock(x + 17, y + 29, z + 5, Blocks.leaves2, 13, 3);
		world.setBlock(x + 18, y + 29, z + 5, Blocks.leaves2, 5, 3);
		world.setBlock(x + 7, y + 29, z + 6, Blocks.leaves2, 13, 3);
		world.setBlock(x + 13, y + 29, z + 6, Blocks.leaves2, 13, 3);
		world.setBlock(x + 14, y + 29, z + 6, Blocks.leaves2, 13, 3);
		world.setBlock(x + 15, y + 29, z + 6, Blocks.leaves2, 5, 3);
		world.setBlock(x + 16, y + 29, z + 6, Blocks.leaves2, 5, 3);
		world.setBlock(x + 6, y + 29, z + 7, Blocks.leaves2, 13, 3);
		world.setBlock(x + 7, y + 29, z + 7, Blocks.leaves2, 13, 3);
		world.setBlock(x + 11, y + 29, z + 7, Blocks.leaves2, 5, 3);
		world.setBlock(x + 12, y + 29, z + 7, Blocks.leaves2, 13, 3);
		world.setBlock(x + 13, y + 29, z + 7, Blocks.leaves2, 13, 3);
		world.setBlock(x + 14, y + 29, z + 7, Blocks.leaves2, 5, 3);
		world.setBlock(x + 15, y + 29, z + 7, Blocks.leaves2, 5, 3);
		world.setBlock(x + 17, y + 29, z + 7, Blocks.leaves2, 13, 3);
		world.setBlock(x + 7, y + 29, z + 8, Blocks.leaves2, 5, 3);
		world.setBlock(x + 9, y + 29, z + 8, Blocks.leaves2, 5, 3);
		world.setBlock(x + 10, y + 29, z + 8, Blocks.leaves2, 5, 3);
		world.setBlock(x + 11, y + 29, z + 8, Blocks.leaves2, 13, 3);
		world.setBlock(x + 12, y + 29, z + 8, Blocks.leaves2, 13, 3);
		world.setBlock(x + 13, y + 29, z + 8, Blocks.leaves2, 13, 3);
		world.setBlock(x + 14, y + 29, z + 8, Blocks.leaves2, 5, 3);
		world.setBlock(x + 15, y + 29, z + 8, Blocks.leaves2, 5, 3);
		world.setBlock(x + 16, y + 29, z + 8, Blocks.leaves2, 5, 3);
		world.setBlock(x + 17, y + 29, z + 8, Blocks.leaves2, 5, 3);
		world.setBlock(x + 18, y + 29, z + 8, Blocks.leaves2, 5, 3);
		world.setBlock(x + 9, y + 29, z + 9, Blocks.leaves2, 5, 3);
		world.setBlock(x + 10, y + 29, z + 9, Blocks.leaves2, 5, 3);
		world.setBlock(x + 11, y + 29, z + 9, Blocks.leaves2, 13, 3);
		world.setBlock(x + 12, y + 29, z + 9, Blocks.leaves2, 13, 3);
		world.setBlock(x + 13, y + 29, z + 9, Blocks.leaves2, 13, 3);
		world.setBlock(x + 16, y + 29, z + 9, Blocks.leaves2, 5, 3);
		world.setBlock(x + 17, y + 29, z + 9, Blocks.leaves2, 5, 3);
		world.setBlock(x + 18, y + 29, z + 9, Blocks.leaves2, 5, 3);
		world.setBlock(x + 20, y + 29, z + 9, Blocks.leaves2, 5, 3);
		world.setBlock(x + 5, y + 29, z + 10, Blocks.leaves2, 5, 3);
		world.setBlock(x + 6, y + 29, z + 10, Blocks.leaves2, 5, 3);
		world.setBlock(x + 8, y + 29, z + 10, Blocks.leaves2, 5, 3);
		world.setBlock(x + 9, y + 29, z + 10, Blocks.leaves2, 5, 3);
		world.setBlock(x + 10, y + 29, z + 10, Blocks.leaves2, 5, 3);
		world.setBlock(x + 11, y + 29, z + 10, Blocks.leaves2, 5, 3);
		world.setBlock(x + 14, y + 29, z + 10, Blocks.leaves2, 5, 3);
		world.setBlock(x + 15, y + 29, z + 10, Blocks.leaves2, 5, 3);
		world.setBlock(x + 16, y + 29, z + 10, Blocks.leaves2, 5, 3);
		world.setBlock(x + 17, y + 29, z + 10, Blocks.leaves2, 5, 3);
		world.setBlock(x + 18, y + 29, z + 10, Blocks.leaves2, 5, 3);
		world.setBlock(x + 19, y + 29, z + 10, Blocks.leaves2, 5, 3);
		world.setBlock(x + 20, y + 29, z + 10, Blocks.leaves2, 5, 3);
		world.setBlock(x + 21, y + 29, z + 10, Blocks.leaves2, 5, 3);
		world.setBlock(x + 5, y + 29, z + 11, Blocks.leaves2, 5, 3);
		world.setBlock(x + 6, y + 29, z + 11, Blocks.leaves2, 5, 3);
		world.setBlock(x + 7, y + 29, z + 11, Blocks.leaves2, 5, 3);
		world.setBlock(x + 8, y + 29, z + 11, Blocks.leaves2, 5, 3);
		world.setBlock(x + 9, y + 29, z + 11, Blocks.leaves2, 5, 3);
		world.setBlock(x + 10, y + 29, z + 11, Blocks.leaves2, 5, 3);
		world.setBlock(x + 14, y + 29, z + 11, Blocks.leaves2, 5, 3);
		world.setBlock(x + 16, y + 29, z + 11, Blocks.leaves2, 13, 3);
		world.setBlock(x + 17, y + 29, z + 11, Blocks.leaves2, 13, 3);
		world.setBlock(x + 18, y + 29, z + 11, Blocks.leaves2, 13, 3);
		world.setBlock(x + 19, y + 29, z + 11, Blocks.leaves2, 5, 3);
		world.setBlock(x + 20, y + 29, z + 11, Blocks.leaves2, 5, 3);
		world.setBlock(x + 21, y + 29, z + 11, Blocks.leaves2, 5, 3);
		world.setBlock(x + 22, y + 29, z + 11, Blocks.leaves2, 13, 3);
		world.setBlock(x + 7, y + 29, z + 12, Blocks.leaves2, 13, 3);
		world.setBlock(x + 8, y + 29, z + 12, Blocks.leaves2, 5, 3);
		world.setBlock(x + 9, y + 29, z + 12, Blocks.leaves2, 5, 3);
		world.setBlock(x + 10, y + 29, z + 12, Blocks.leaves2, 5, 3);
		world.setBlock(x + 12, y + 29, z + 12, Blocks.leaves2, 5, 3);
		world.setBlock(x + 14, y + 29, z + 12, Blocks.leaves2, 5, 3);
		world.setBlock(x + 15, y + 29, z + 12, Blocks.leaves2, 5, 3);
		world.setBlock(x + 17, y + 29, z + 12, Blocks.leaves2, 5, 3);
		world.setBlock(x + 19, y + 29, z + 12, Blocks.leaves2, 5, 3);
		world.setBlock(x + 20, y + 29, z + 12, Blocks.leaves2, 5, 3);
		world.setBlock(x + 21, y + 29, z + 12, Blocks.leaves2, 5, 3);
		world.setBlock(x + 22, y + 29, z + 12, Blocks.leaves2, 13, 3);
		world.setBlock(x + 6, y + 29, z + 13, Blocks.leaves2, 5, 3);
		world.setBlock(x + 7, y + 29, z + 13, Blocks.leaves2, 13, 3);
		world.setBlock(x + 8, y + 29, z + 13, Blocks.leaves2, 5, 3);
		world.setBlock(x + 9, y + 29, z + 13, Blocks.leaves2, 5, 3);
		world.setBlock(x + 16, y + 29, z + 13, Blocks.leaves2, 13, 3);
		world.setBlock(x + 17, y + 29, z + 13, Blocks.leaves2, 13, 3);
		world.setBlock(x + 18, y + 29, z + 13, Blocks.leaves2, 13, 3);
		world.setBlock(x + 20, y + 29, z + 13, Blocks.leaves2, 5, 3);
		world.setBlock(x + 21, y + 29, z + 13, Blocks.leaves2, 5, 3);
		world.setBlock(x + 4, y + 29, z + 14, Blocks.leaves2, 5, 3);
		world.setBlock(x + 5, y + 29, z + 14, Blocks.leaves2, 5, 3);
		world.setBlock(x + 8, y + 29, z + 14, Blocks.leaves2, 5, 3);
		world.setBlock(x + 9, y + 29, z + 14, Blocks.leaves2, 5, 3);
		world.setBlock(x + 10, y + 29, z + 14, Blocks.leaves2, 5, 3);
		world.setBlock(x + 13, y + 29, z + 14, Blocks.log2, 1, 3);
		world.setBlock(x + 14, y + 29, z + 14, Blocks.leaves2, 5, 3);
		world.setBlock(x + 16, y + 29, z + 14, Blocks.leaves2, 5, 3);
		world.setBlock(x + 17, y + 29, z + 14, Blocks.leaves2, 5, 3);
		world.setBlock(x + 18, y + 29, z + 14, Blocks.leaves2, 5, 3);
		world.setBlock(x + 19, y + 29, z + 14, Blocks.leaves2, 5, 3);
		world.setBlock(x + 3, y + 29, z + 15, Blocks.leaves2, 5, 3);
		world.setBlock(x + 4, y + 29, z + 15, Blocks.leaves2, 5, 3);
		world.setBlock(x + 5, y + 29, z + 15, Blocks.leaves2, 5, 3);
		world.setBlock(x + 6, y + 29, z + 15, Blocks.leaves2, 5, 3);
		world.setBlock(x + 12, y + 29, z + 15, Blocks.leaves2, 5, 3);
		world.setBlock(x + 13, y + 29, z + 15, Blocks.log2, 1, 3);
		world.setBlock(x + 14, y + 29, z + 15, Blocks.log2, 1, 3);
		world.setBlock(x + 15, y + 29, z + 15, Blocks.leaves2, 5, 3);
		world.setBlock(x + 17, y + 29, z + 15, Blocks.leaves2, 5, 3);
		world.setBlock(x + 18, y + 29, z + 15, Blocks.leaves2, 5, 3);
		world.setBlock(x + 2, y + 29, z + 16, Blocks.leaves2, 5, 3);
		world.setBlock(x + 3, y + 29, z + 16, Blocks.leaves2, 5, 3);
		world.setBlock(x + 4, y + 29, z + 16, Blocks.leaves2, 5, 3);
		world.setBlock(x + 5, y + 29, z + 16, Blocks.leaves2, 5, 3);
		world.setBlock(x + 6, y + 29, z + 16, Blocks.leaves2, 5, 3);
		world.setBlock(x + 7, y + 29, z + 16, Blocks.leaves2, 5, 3);
		world.setBlock(x + 11, y + 29, z + 16, Blocks.leaves2, 5, 3);
		world.setBlock(x + 12, y + 29, z + 16, Blocks.log2, 1, 3);
		world.setBlock(x + 13, y + 29, z + 16, Blocks.leaves2, 13, 3);
		world.setBlock(x + 14, y + 29, z + 16, Blocks.leaves2, 13, 3);
		world.setBlock(x + 15, y + 29, z + 16, Blocks.log2, 1, 3);
		world.setBlock(x + 16, y + 29, z + 16, Blocks.leaves2, 5, 3);
		world.setBlock(x + 23, y + 29, z + 16, Blocks.leaves2, 5, 3);
		world.setBlock(x + 3, y + 29, z + 17, Blocks.leaves2, 5, 3);
		world.setBlock(x + 4, y + 29, z + 17, Blocks.leaves2, 5, 3);
		world.setBlock(x + 5, y + 29, z + 17, Blocks.leaves2, 5, 3);
		world.setBlock(x + 6, y + 29, z + 17, Blocks.leaves2, 5, 3);
		world.setBlock(x + 7, y + 29, z + 17, Blocks.leaves2, 5, 3);
		world.setBlock(x + 9, y + 29, z + 17, Blocks.leaves2, 5, 3);
		world.setBlock(x + 11, y + 29, z + 17, Blocks.log2, 1, 3);
		world.setBlock(x + 12, y + 29, z + 17, Blocks.leaves2, 13, 3);
		world.setBlock(x + 13, y + 29, z + 17, Blocks.leaves2, 13, 3);
		world.setBlock(x + 14, y + 29, z + 17, Blocks.leaves2, 13, 3);
		world.setBlock(x + 15, y + 29, z + 17, Blocks.leaves2, 13, 3);
		world.setBlock(x + 16, y + 29, z + 17, Blocks.log2, 1, 3);
		world.setBlock(x + 17, y + 29, z + 17, Blocks.leaves2, 5, 3);
		world.setBlock(x + 22, y + 29, z + 17, Blocks.leaves2, 5, 3);
		world.setBlock(x + 23, y + 29, z + 17, Blocks.leaves2, 5, 3);
		world.setBlock(x + 24, y + 29, z + 17, Blocks.leaves2, 5, 3);
		world.setBlock(x + 1, y + 29, z + 18, Blocks.leaves2, 5, 3);
		world.setBlock(x + 4, y + 29, z + 18, Blocks.leaves2, 5, 3);
		world.setBlock(x + 5, y + 29, z + 18, Blocks.leaves2, 5, 3);
		world.setBlock(x + 6, y + 29, z + 18, Blocks.leaves2, 5, 3);
		world.setBlock(x + 7, y + 29, z + 18, Blocks.leaves2, 5, 3);
		world.setBlock(x + 8, y + 29, z + 18, Blocks.leaves2, 5, 3);
		world.setBlock(x + 9, y + 29, z + 18, Blocks.leaves2, 5, 3);
		world.setBlock(x + 10, y + 29, z + 18, Blocks.leaves2, 5, 3);
		world.setBlock(x + 11, y + 29, z + 18, Blocks.log2, 1, 3);
		world.setBlock(x + 12, y + 29, z + 18, Blocks.leaves2, 13, 3);
		world.setBlock(x + 13, y + 29, z + 18, Blocks.leaves2, 13, 3);
		world.setBlock(x + 14, y + 29, z + 18, Blocks.leaves2, 13, 3);
		world.setBlock(x + 15, y + 29, z + 18, Blocks.leaves2, 13, 3);
		world.setBlock(x + 16, y + 29, z + 18, Blocks.log2, 1, 3);
		world.setBlock(x + 17, y + 29, z + 18, Blocks.leaves2, 5, 3);
		world.setBlock(x + 21, y + 29, z + 18, Blocks.leaves2, 13, 3);
		world.setBlock(x + 22, y + 29, z + 18, Blocks.leaves2, 13, 3);
		world.setBlock(x + 23, y + 29, z + 18, Blocks.leaves2, 5, 3);
		world.setBlock(x + 24, y + 29, z + 18, Blocks.leaves2, 13, 3);
		world.setBlock(x + 25, y + 29, z + 18, Blocks.leaves2, 5, 3);
		world.setBlock(x + 1, y + 29, z + 19, Blocks.leaves2, 5, 3);
		world.setBlock(x + 3, y + 29, z + 19, Blocks.leaves2, 5, 3);
		world.setBlock(x + 6, y + 29, z + 19, Blocks.leaves2, 5, 3);
		world.setBlock(x + 7, y + 29, z + 19, Blocks.leaves2, 5, 3);
		world.setBlock(x + 9, y + 29, z + 19, Blocks.leaves2, 5, 3);
		world.setBlock(x + 11, y + 29, z + 19, Blocks.leaves2, 5, 3);
		world.setBlock(x + 12, y + 29, z + 19, Blocks.log2, 1, 3);
		world.setBlock(x + 13, y + 29, z + 19, Blocks.leaves2, 13, 3);
		world.setBlock(x + 14, y + 29, z + 19, Blocks.leaves2, 13, 3);
		world.setBlock(x + 15, y + 29, z + 19, Blocks.log2, 1, 3);
		world.setBlock(x + 16, y + 29, z + 19, Blocks.leaves2, 5, 3);
		world.setBlock(x + 20, y + 29, z + 19, Blocks.leaves2, 5, 3);
		world.setBlock(x + 21, y + 29, z + 19, Blocks.leaves2, 5, 3);
		world.setBlock(x + 22, y + 29, z + 19, Blocks.leaves2, 5, 3);
		world.setBlock(x + 23, y + 29, z + 19, Blocks.leaves2, 5, 3);
		world.setBlock(x + 24, y + 29, z + 19, Blocks.leaves2, 5, 3);
		world.setBlock(x + 5, y + 29, z + 20, Blocks.leaves2, 5, 3);
		world.setBlock(x + 7, y + 29, z + 20, Blocks.leaves2, 5, 3);
		world.setBlock(x + 12, y + 29, z + 20, Blocks.leaves2, 5, 3);
		world.setBlock(x + 13, y + 29, z + 20, Blocks.log2, 1, 3);
		world.setBlock(x + 14, y + 29, z + 20, Blocks.log2, 1, 3);
		world.setBlock(x + 16, y + 29, z + 20, Blocks.leaves2, 5, 3);
		world.setBlock(x + 19, y + 29, z + 20, Blocks.leaves2, 5, 3);
		world.setBlock(x + 20, y + 29, z + 20, Blocks.leaves2, 5, 3);
		world.setBlock(x + 21, y + 29, z + 20, Blocks.leaves2, 5, 3);
		world.setBlock(x + 23, y + 29, z + 20, Blocks.leaves2, 5, 3);
		world.setBlock(x + 1, y + 29, z + 21, Blocks.leaves2, 5, 3);
		world.setBlock(x + 2, y + 29, z + 21, Blocks.leaves2, 5, 3);
		world.setBlock(x + 3, y + 29, z + 21, Blocks.leaves2, 5, 3);
		world.setBlock(x + 14, y + 29, z + 21, Blocks.leaves2, 13, 3);
		world.setBlock(x + 15, y + 29, z + 21, Blocks.leaves2, 13, 3);
		world.setBlock(x + 17, y + 29, z + 21, Blocks.leaves2, 13, 3);
		world.setBlock(x + 18, y + 29, z + 21, Blocks.leaves2, 13, 3);
		world.setBlock(x + 19, y + 29, z + 21, Blocks.leaves2, 5, 3);
		world.setBlock(x + 20, y + 29, z + 21, Blocks.leaves2, 5, 3);
		world.setBlock(x + 21, y + 29, z + 21, Blocks.leaves2, 5, 3);
		world.setBlock(x + 1, y + 29, z + 22, Blocks.leaves2, 5, 3);
		world.setBlock(x + 2, y + 29, z + 22, Blocks.leaves2, 5, 3);
		world.setBlock(x + 3, y + 29, z + 22, Blocks.leaves2, 5, 3);
		world.setBlock(x + 4, y + 29, z + 22, Blocks.leaves2, 5, 3);
		world.setBlock(x + 8, y + 29, z + 22, Blocks.leaves2, 5, 3);
		world.setBlock(x + 11, y + 29, z + 22, Blocks.leaves2, 5, 3);
		world.setBlock(x + 14, y + 29, z + 22, Blocks.leaves2, 5, 3);
		world.setBlock(x + 15, y + 29, z + 22, Blocks.leaves2, 5, 3);
		world.setBlock(x + 16, y + 29, z + 22, Blocks.leaves2, 13, 3);
		world.setBlock(x + 17, y + 29, z + 22, Blocks.leaves2, 5, 3);
		world.setBlock(x + 18, y + 29, z + 22, Blocks.leaves2, 13, 3);
		world.setBlock(x + 19, y + 29, z + 22, Blocks.leaves2, 5, 3);
		world.setBlock(x + 20, y + 29, z + 22, Blocks.leaves2, 5, 3);
		world.setBlock(x + 21, y + 29, z + 22, Blocks.leaves2, 5, 3);
		world.setBlock(x + 22, y + 29, z + 22, Blocks.leaves2, 5, 3);
		world.setBlock(x + 2, y + 29, z + 23, Blocks.leaves2, 5, 3);
		world.setBlock(x + 3, y + 29, z + 23, Blocks.leaves2, 5, 3);
		world.setBlock(x + 4, y + 29, z + 23, Blocks.leaves2, 5, 3);
		world.setBlock(x + 10, y + 29, z + 23, Blocks.leaves2, 5, 3);
		world.setBlock(x + 11, y + 29, z + 23, Blocks.leaves2, 5, 3);
		world.setBlock(x + 12, y + 29, z + 23, Blocks.leaves2, 5, 3);
		world.setBlock(x + 14, y + 29, z + 23, Blocks.leaves2, 5, 3);
		world.setBlock(x + 15, y + 29, z + 23, Blocks.leaves2, 5, 3);
		world.setBlock(x + 16, y + 29, z + 23, Blocks.leaves2, 13, 3);
		world.setBlock(x + 17, y + 29, z + 23, Blocks.leaves2, 13, 3);
		world.setBlock(x + 18, y + 29, z + 23, Blocks.leaves2, 13, 3);
		world.setBlock(x + 19, y + 29, z + 23, Blocks.leaves2, 5, 3);
		world.setBlock(x + 20, y + 29, z + 23, Blocks.leaves2, 5, 3);
		world.setBlock(x + 21, y + 29, z + 23, Blocks.leaves2, 5, 3);
		world.setBlock(x + 3, y + 29, z + 24, Blocks.leaves2, 5, 3);
		world.setBlock(x + 4, y + 29, z + 24, Blocks.leaves2, 5, 3);
		world.setBlock(x + 5, y + 29, z + 24, Blocks.leaves2, 5, 3);
		world.setBlock(x + 6, y + 29, z + 24, Blocks.leaves2, 5, 3);
		world.setBlock(x + 9, y + 29, z + 24, Blocks.leaves2, 5, 3);
		world.setBlock(x + 11, y + 29, z + 24, Blocks.leaves2, 5, 3);
		world.setBlock(x + 12, y + 29, z + 24, Blocks.leaves2, 5, 3);
		world.setBlock(x + 15, y + 29, z + 24, Blocks.leaves2, 5, 3);
		world.setBlock(x + 16, y + 29, z + 24, Blocks.leaves2, 5, 3);
		world.setBlock(x + 17, y + 29, z + 24, Blocks.leaves2, 5, 3);
		world.setBlock(x + 18, y + 29, z + 24, Blocks.leaves2, 5, 3);
		world.setBlock(x + 19, y + 29, z + 24, Blocks.leaves2, 5, 3);
		world.setBlock(x + 20, y + 29, z + 24, Blocks.leaves2, 5, 3);
		world.setBlock(x + 4, y + 29, z + 25, Blocks.leaves2, 5, 3);
		world.setBlock(x + 5, y + 29, z + 25, Blocks.leaves2, 5, 3);
		world.setBlock(x + 8, y + 29, z + 25, Blocks.leaves2, 5, 3);
		world.setBlock(x + 9, y + 29, z + 25, Blocks.leaves2, 5, 3);
		world.setBlock(x + 16, y + 29, z + 25, Blocks.leaves2, 5, 3);
		world.setBlock(x + 18, y + 29, z + 25, Blocks.leaves2, 5, 3);
		world.setBlock(x + 19, y + 29, z + 25, Blocks.leaves2, 5, 3);
		world.setBlock(x + 20, y + 29, z + 25, Blocks.leaves2, 5, 3);
		world.setBlock(x + 6, y + 29, z + 26, Blocks.leaves2, 5, 3);
		world.setBlock(x + 11, y + 29, z + 26, Blocks.leaves2, 5, 3);
		world.setBlock(x + 17, y + 29, z + 26, Blocks.leaves2, 5, 3);
		world.setBlock(x + 18, y + 29, z + 26, Blocks.leaves2, 5, 3);
		world.setBlock(x + 19, y + 29, z + 26, Blocks.leaves2, 5, 3);
		world.setBlock(x + 10, y + 29, z + 27, Blocks.leaves2, 5, 3);
		world.setBlock(x + 11, y + 29, z + 27, Blocks.leaves2, 5, 3);
		world.setBlock(x + 18, y + 29, z + 27, Blocks.leaves2, 5, 3);
		world.setBlock(x + 19, y + 29, z + 27, Blocks.leaves2, 5, 3);
		world.setBlock(x + 20, y + 29, z + 27, Blocks.leaves2, 5, 3);
		world.setBlock(x + 7, y + 29, z + 28, Blocks.leaves2, 5, 3);
		world.setBlock(x + 9, y + 29, z + 28, Blocks.leaves2, 13, 3);
		world.setBlock(x + 10, y + 29, z + 28, Blocks.leaves2, 5, 3);
		world.setBlock(x + 19, y + 29, z + 28, Blocks.leaves2, 5, 3);
		world.setBlock(x + 5, y + 29, z + 29, Blocks.leaves2, 5, 3);
		world.setBlock(x + 6, y + 29, z + 29, Blocks.leaves2, 5, 3);
		world.setBlock(x + 7, y + 29, z + 29, Blocks.leaves2, 5, 3);
		world.setBlock(x + 8, y + 29, z + 29, Blocks.leaves2, 13, 3);
		world.setBlock(x + 9, y + 29, z + 29, Blocks.leaves2, 13, 3);
		world.setBlock(x + 10, y + 29, z + 29, Blocks.leaves2, 13, 3);
		world.setBlock(x + 11, y + 29, z + 29, Blocks.leaves2, 13, 3);
		world.setBlock(x + 14, y + 29, z + 29, Blocks.leaves2, 5, 3);
		world.setBlock(x + 4, y + 29, z + 30, Blocks.leaves2, 5, 3);
		world.setBlock(x + 5, y + 29, z + 30, Blocks.leaves2, 5, 3);
		world.setBlock(x + 6, y + 29, z + 30, Blocks.leaves2, 5, 3);
		world.setBlock(x + 7, y + 29, z + 30, Blocks.leaves2, 5, 3);
		world.setBlock(x + 8, y + 29, z + 30, Blocks.leaves2, 13, 3);
		world.setBlock(x + 11, y + 29, z + 30, Blocks.leaves2, 13, 3);
		world.setBlock(x + 13, y + 29, z + 30, Blocks.leaves2, 13, 3);
		world.setBlock(x + 14, y + 29, z + 30, Blocks.leaves2, 5, 3);
		world.setBlock(x + 15, y + 29, z + 30, Blocks.leaves2, 5, 3);
		world.setBlock(x + 5, y + 29, z + 31, Blocks.leaves2, 5, 3);
		world.setBlock(x + 6, y + 29, z + 31, Blocks.leaves2, 5, 3);
		world.setBlock(x + 7, y + 29, z + 31, Blocks.leaves2, 5, 3);
		world.setBlock(x + 12, y + 29, z + 31, Blocks.leaves2, 13, 3);
		world.setBlock(x + 13, y + 29, z + 31, Blocks.leaves2, 13, 3);
		world.setBlock(x + 14, y + 29, z + 31, Blocks.leaves2, 5, 3);
		world.setBlock(x + 15, y + 29, z + 31, Blocks.leaves2, 5, 3);
		world.setBlock(x + 6, y + 29, z + 32, Blocks.leaves2, 5, 3);
		world.setBlock(x + 13, y + 29, z + 32, Blocks.leaves2, 5, 3);
		world.setBlock(x + 14, y + 29, z + 32, Blocks.leaves2, 5, 3);
		world.setBlock(x + 15, y + 29, z + 32, Blocks.leaves2, 5, 3);
		world.setBlock(x + 14, y + 29, z + 33, Blocks.leaves2, 5, 3);
		world.setBlock(x + 13, y + 30, z + 1, Blocks.leaves2, 5, 3);
		world.setBlock(x + 14, y + 30, z + 1, Blocks.leaves2, 5, 3);
		world.setBlock(x + 12, y + 30, z + 3, Blocks.leaves2, 5, 3);
		world.setBlock(x + 13, y + 30, z + 3, Blocks.leaves2, 5, 3);
		world.setBlock(x + 14, y + 30, z + 3, Blocks.leaves2, 5, 3);
		world.setBlock(x + 15, y + 30, z + 3, Blocks.leaves2, 13, 3);
		world.setBlock(x + 16, y + 30, z + 3, Blocks.leaves2, 13, 3);
		world.setBlock(x + 11, y + 30, z + 4, Blocks.leaves2, 5, 3);
		world.setBlock(x + 12, y + 30, z + 4, Blocks.leaves2, 5, 3);
		world.setBlock(x + 13, y + 30, z + 4, Blocks.leaves2, 5, 3);
		world.setBlock(x + 14, y + 30, z + 4, Blocks.leaves2, 13, 3);
		world.setBlock(x + 15, y + 30, z + 4, Blocks.leaves2, 13, 3);
		world.setBlock(x + 16, y + 30, z + 4, Blocks.leaves2, 13, 3);
		world.setBlock(x + 17, y + 30, z + 4, Blocks.leaves2, 5, 3);
		world.setBlock(x + 11, y + 30, z + 5, Blocks.leaves2, 5, 3);
		world.setBlock(x + 12, y + 30, z + 5, Blocks.leaves2, 5, 3);
		world.setBlock(x + 13, y + 30, z + 5, Blocks.leaves2, 5, 3);
		world.setBlock(x + 14, y + 30, z + 5, Blocks.leaves2, 5, 3);
		world.setBlock(x + 15, y + 30, z + 5, Blocks.leaves2, 5, 3);
		world.setBlock(x + 16, y + 30, z + 5, Blocks.leaves2, 5, 3);
		world.setBlock(x + 17, y + 30, z + 5, Blocks.leaves2, 13, 3);
		world.setBlock(x + 18, y + 30, z + 5, Blocks.leaves2, 13, 3);
		world.setBlock(x + 7, y + 30, z + 6, Blocks.leaves2, 5, 3);
		world.setBlock(x + 12, y + 30, z + 6, Blocks.leaves2, 5, 3);
		world.setBlock(x + 13, y + 30, z + 6, Blocks.leaves2, 5, 3);
		world.setBlock(x + 14, y + 30, z + 6, Blocks.leaves2, 5, 3);
		world.setBlock(x + 15, y + 30, z + 6, Blocks.leaves2, 5, 3);
		world.setBlock(x + 16, y + 30, z + 6, Blocks.leaves2, 13, 3);
		world.setBlock(x + 17, y + 30, z + 6, Blocks.leaves2, 13, 3);
		world.setBlock(x + 18, y + 30, z + 6, Blocks.leaves2, 13, 3);
		world.setBlock(x + 5, y + 30, z + 7, Blocks.leaves2, 13, 3);
		world.setBlock(x + 6, y + 30, z + 7, Blocks.leaves2, 13, 3);
		world.setBlock(x + 7, y + 30, z + 7, Blocks.leaves2, 5, 3);
		world.setBlock(x + 9, y + 30, z + 7, Blocks.leaves2, 5, 3);
		world.setBlock(x + 10, y + 30, z + 7, Blocks.leaves2, 5, 3);
		world.setBlock(x + 11, y + 30, z + 7, Blocks.leaves2, 5, 3);
		world.setBlock(x + 12, y + 30, z + 7, Blocks.leaves2, 5, 3);
		world.setBlock(x + 13, y + 30, z + 7, Blocks.leaves2, 5, 3);
		world.setBlock(x + 14, y + 30, z + 7, Blocks.leaves2, 5, 3);
		world.setBlock(x + 15, y + 30, z + 7, Blocks.leaves2, 5, 3);
		world.setBlock(x + 16, y + 30, z + 7, Blocks.leaves2, 13, 3);
		world.setBlock(x + 17, y + 30, z + 7, Blocks.leaves2, 13, 3);
		world.setBlock(x + 18, y + 30, z + 7, Blocks.leaves2, 13, 3);
		world.setBlock(x + 6, y + 30, z + 8, Blocks.leaves2, 13, 3);
		world.setBlock(x + 7, y + 30, z + 8, Blocks.leaves2, 5, 3);
		world.setBlock(x + 8, y + 30, z + 8, Blocks.leaves2, 5, 3);
		world.setBlock(x + 9, y + 30, z + 8, Blocks.leaves2, 5, 3);
		world.setBlock(x + 10, y + 30, z + 8, Blocks.leaves2, 5, 3);
		world.setBlock(x + 11, y + 30, z + 8, Blocks.leaves2, 5, 3);
		world.setBlock(x + 12, y + 30, z + 8, Blocks.leaves2, 5, 3);
		world.setBlock(x + 13, y + 30, z + 8, Blocks.leaves2, 5, 3);
		world.setBlock(x + 14, y + 30, z + 8, Blocks.leaves2, 5, 3);
		world.setBlock(x + 15, y + 30, z + 8, Blocks.leaves2, 5, 3);
		world.setBlock(x + 16, y + 30, z + 8, Blocks.leaves2, 5, 3);
		world.setBlock(x + 17, y + 30, z + 8, Blocks.leaves2, 5, 3);
		world.setBlock(x + 18, y + 30, z + 8, Blocks.leaves2, 5, 3);
		world.setBlock(x + 6, y + 30, z + 9, Blocks.leaves2, 13, 3);
		world.setBlock(x + 7, y + 30, z + 9, Blocks.leaves2, 5, 3);
		world.setBlock(x + 8, y + 30, z + 9, Blocks.leaves2, 5, 3);
		world.setBlock(x + 9, y + 30, z + 9, Blocks.leaves2, 5, 3);
		world.setBlock(x + 10, y + 30, z + 9, Blocks.leaves2, 5, 3);
		world.setBlock(x + 11, y + 30, z + 9, Blocks.leaves2, 5, 3);
		world.setBlock(x + 12, y + 30, z + 9, Blocks.leaves2, 5, 3);
		world.setBlock(x + 13, y + 30, z + 9, Blocks.leaves2, 5, 3);
		world.setBlock(x + 14, y + 30, z + 9, Blocks.leaves2, 5, 3);
		world.setBlock(x + 15, y + 30, z + 9, Blocks.leaves2, 5, 3);
		world.setBlock(x + 16, y + 30, z + 9, Blocks.leaves2, 5, 3);
		world.setBlock(x + 17, y + 30, z + 9, Blocks.leaves2, 5, 3);
		world.setBlock(x + 18, y + 30, z + 9, Blocks.leaves2, 5, 3);
		world.setBlock(x + 19, y + 30, z + 9, Blocks.leaves2, 5, 3);
		world.setBlock(x + 20, y + 30, z + 9, Blocks.leaves2, 5, 3);
		world.setBlock(x + 6, y + 30, z + 10, Blocks.leaves2, 5, 3);
		world.setBlock(x + 7, y + 30, z + 10, Blocks.leaves2, 5, 3);
		world.setBlock(x + 8, y + 30, z + 10, Blocks.leaves2, 5, 3);
		world.setBlock(x + 9, y + 30, z + 10, Blocks.leaves2, 5, 3);
		world.setBlock(x + 10, y + 30, z + 10, Blocks.leaves2, 5, 3);
		world.setBlock(x + 11, y + 30, z + 10, Blocks.leaves2, 5, 3);
		world.setBlock(x + 12, y + 30, z + 10, Blocks.leaves2, 5, 3);
		world.setBlock(x + 13, y + 30, z + 10, Blocks.leaves2, 5, 3);
		world.setBlock(x + 14, y + 30, z + 10, Blocks.leaves2, 5, 3);
		world.setBlock(x + 15, y + 30, z + 10, Blocks.leaves2, 5, 3);
		world.setBlock(x + 16, y + 30, z + 10, Blocks.leaves2, 5, 3);
		world.setBlock(x + 17, y + 30, z + 10, Blocks.leaves2, 5, 3);
		world.setBlock(x + 18, y + 30, z + 10, Blocks.leaves2, 5, 3);
		world.setBlock(x + 19, y + 30, z + 10, Blocks.leaves2, 5, 3);
		world.setBlock(x + 20, y + 30, z + 10, Blocks.leaves2, 5, 3);
		world.setBlock(x + 21, y + 30, z + 10, Blocks.leaves2, 5, 3);
		world.setBlock(x + 6, y + 30, z + 11, Blocks.leaves2, 5, 3);
		world.setBlock(x + 7, y + 30, z + 11, Blocks.leaves2, 5, 3);
		world.setBlock(x + 8, y + 30, z + 11, Blocks.leaves2, 5, 3);
		world.setBlock(x + 9, y + 30, z + 11, Blocks.leaves2, 5, 3);
		world.setBlock(x + 10, y + 30, z + 11, Blocks.leaves2, 5, 3);
		world.setBlock(x + 11, y + 30, z + 11, Blocks.leaves2, 5, 3);
		world.setBlock(x + 13, y + 30, z + 11, Blocks.leaves2, 5, 3);
		world.setBlock(x + 14, y + 30, z + 11, Blocks.leaves2, 5, 3);
		world.setBlock(x + 16, y + 30, z + 11, Blocks.leaves2, 5, 3);
		world.setBlock(x + 17, y + 30, z + 11, Blocks.leaves2, 5, 3);
		world.setBlock(x + 18, y + 30, z + 11, Blocks.leaves2, 5, 3);
		world.setBlock(x + 19, y + 30, z + 11, Blocks.leaves2, 5, 3);
		world.setBlock(x + 20, y + 30, z + 11, Blocks.leaves2, 5, 3);
		world.setBlock(x + 21, y + 30, z + 11, Blocks.leaves2, 5, 3);
		world.setBlock(x + 22, y + 30, z + 11, Blocks.leaves2, 13, 3);
		world.setBlock(x + 6, y + 30, z + 12, Blocks.leaves2, 5, 3);
		world.setBlock(x + 7, y + 30, z + 12, Blocks.leaves2, 13, 3);
		world.setBlock(x + 8, y + 30, z + 12, Blocks.leaves2, 5, 3);
		world.setBlock(x + 9, y + 30, z + 12, Blocks.leaves2, 5, 3);
		world.setBlock(x + 10, y + 30, z + 12, Blocks.leaves2, 5, 3);
		world.setBlock(x + 12, y + 30, z + 12, Blocks.leaves2, 5, 3);
		world.setBlock(x + 14, y + 30, z + 12, Blocks.leaves2, 5, 3);
		world.setBlock(x + 15, y + 30, z + 12, Blocks.leaves2, 5, 3);
		world.setBlock(x + 16, y + 30, z + 12, Blocks.leaves2, 5, 3);
		world.setBlock(x + 17, y + 30, z + 12, Blocks.leaves2, 5, 3);
		world.setBlock(x + 18, y + 30, z + 12, Blocks.leaves2, 5, 3);
		world.setBlock(x + 19, y + 30, z + 12, Blocks.leaves2, 5, 3);
		world.setBlock(x + 20, y + 30, z + 12, Blocks.leaves2, 5, 3);
		world.setBlock(x + 21, y + 30, z + 12, Blocks.leaves2, 5, 3);
		world.setBlock(x + 22, y + 30, z + 12, Blocks.leaves2, 13, 3);
		world.setBlock(x + 23, y + 30, z + 12, Blocks.leaves2, 13, 3);
		world.setBlock(x + 4, y + 30, z + 13, Blocks.leaves2, 5, 3);
		world.setBlock(x + 5, y + 30, z + 13, Blocks.leaves2, 5, 3);
		world.setBlock(x + 6, y + 30, z + 13, Blocks.leaves2, 5, 3);
		world.setBlock(x + 7, y + 30, z + 13, Blocks.leaves2, 13, 3);
		world.setBlock(x + 8, y + 30, z + 13, Blocks.leaves2, 5, 3);
		world.setBlock(x + 9, y + 30, z + 13, Blocks.leaves2, 5, 3);
		world.setBlock(x + 10, y + 30, z + 13, Blocks.leaves2, 5, 3);
		world.setBlock(x + 13, y + 30, z + 13, Blocks.leaves2, 5, 3);
		world.setBlock(x + 14, y + 30, z + 13, Blocks.leaves2, 5, 3);
		world.setBlock(x + 19, y + 30, z + 13, Blocks.leaves2, 5, 3);
		world.setBlock(x + 20, y + 30, z + 13, Blocks.leaves2, 5, 3);
		world.setBlock(x + 21, y + 30, z + 13, Blocks.leaves2, 5, 3);
		world.setBlock(x + 22, y + 30, z + 13, Blocks.leaves2, 5, 3);
		world.setBlock(x + 3, y + 30, z + 14, Blocks.leaves2, 5, 3);
		world.setBlock(x + 4, y + 30, z + 14, Blocks.leaves2, 13, 3);
		world.setBlock(x + 5, y + 30, z + 14, Blocks.leaves2, 5, 3);
		world.setBlock(x + 6, y + 30, z + 14, Blocks.leaves2, 5, 3);
		world.setBlock(x + 7, y + 30, z + 14, Blocks.leaves2, 5, 3);
		world.setBlock(x + 8, y + 30, z + 14, Blocks.leaves2, 5, 3);
		world.setBlock(x + 9, y + 30, z + 14, Blocks.leaves2, 5, 3);
		world.setBlock(x + 10, y + 30, z + 14, Blocks.leaves2, 5, 3);
		world.setBlock(x + 11, y + 30, z + 14, Blocks.leaves2, 5, 3);
		world.setBlock(x + 12, y + 30, z + 14, Blocks.log2, 1, 3);
		world.setBlock(x + 13, y + 30, z + 14, Blocks.leaves2, 5, 3);
		world.setBlock(x + 14, y + 30, z + 14, Blocks.log2, 1, 3);
		world.setBlock(x + 15, y + 30, z + 14, Blocks.leaves2, 5, 3);
		world.setBlock(x + 16, y + 30, z + 14, Blocks.leaves2, 5, 3);
		world.setBlock(x + 17, y + 30, z + 14, Blocks.leaves2, 5, 3);
		world.setBlock(x + 18, y + 30, z + 14, Blocks.leaves2, 5, 3);
		world.setBlock(x + 19, y + 30, z + 14, Blocks.leaves2, 5, 3);
		world.setBlock(x + 20, y + 30, z + 14, Blocks.leaves2, 5, 3);
		world.setBlock(x + 21, y + 30, z + 14, Blocks.leaves2, 5, 3);
		world.setBlock(x + 3, y + 30, z + 15, Blocks.leaves2, 13, 3);
		world.setBlock(x + 4, y + 30, z + 15, Blocks.leaves2, 13, 3);
		world.setBlock(x + 5, y + 30, z + 15, Blocks.leaves2, 5, 3);
		world.setBlock(x + 6, y + 30, z + 15, Blocks.leaves2, 5, 3);
		world.setBlock(x + 7, y + 30, z + 15, Blocks.leaves2, 5, 3);
		world.setBlock(x + 8, y + 30, z + 15, Blocks.leaves2, 5, 3);
		world.setBlock(x + 9, y + 30, z + 15, Blocks.leaves2, 5, 3);
		world.setBlock(x + 10, y + 30, z + 15, Blocks.leaves2, 5, 3);
		world.setBlock(x + 11, y + 30, z + 15, Blocks.leaves2, 5, 3);
		world.setBlock(x + 12, y + 30, z + 15, Blocks.leaves2, 5, 3);
		world.setBlock(x + 13, y + 30, z + 15, Blocks.leaves2, 5, 3);
		world.setBlock(x + 14, y + 30, z + 15, Blocks.leaves2, 5, 3);
		world.setBlock(x + 15, y + 30, z + 15, Blocks.leaves2, 5, 3);
		world.setBlock(x + 16, y + 30, z + 15, Blocks.leaves2, 5, 3);
		world.setBlock(x + 17, y + 30, z + 15, Blocks.leaves2, 5, 3);
		world.setBlock(x + 18, y + 30, z + 15, Blocks.leaves2, 5, 3);
		world.setBlock(x + 2, y + 30, z + 16, Blocks.leaves2, 5, 3);
		world.setBlock(x + 3, y + 30, z + 16, Blocks.leaves2, 5, 3);
		world.setBlock(x + 4, y + 30, z + 16, Blocks.leaves2, 13, 3);
		world.setBlock(x + 5, y + 30, z + 16, Blocks.leaves2, 5, 3);
		world.setBlock(x + 6, y + 30, z + 16, Blocks.leaves2, 5, 3);
		world.setBlock(x + 7, y + 30, z + 16, Blocks.leaves2, 5, 3);
		world.setBlock(x + 8, y + 30, z + 16, Blocks.leaves2, 5, 3);
		world.setBlock(x + 11, y + 30, z + 16, Blocks.log2, 1, 3);
		world.setBlock(x + 12, y + 30, z + 16, Blocks.leaves2, 5, 3);
		world.setBlock(x + 13, y + 30, z + 16, Blocks.log2, 1, 3);
		world.setBlock(x + 14, y + 30, z + 16, Blocks.leaves2, 5, 3);
		world.setBlock(x + 15, y + 30, z + 16, Blocks.leaves2, 5, 3);
		world.setBlock(x + 16, y + 30, z + 16, Blocks.log2, 1, 3);
		world.setBlock(x + 17, y + 30, z + 16, Blocks.leaves2, 5, 3);
		world.setBlock(x + 22, y + 30, z + 16, Blocks.leaves2, 5, 3);
		world.setBlock(x + 1, y + 30, z + 17, Blocks.leaves2, 5, 3);
		world.setBlock(x + 2, y + 30, z + 17, Blocks.leaves2, 5, 3);
		world.setBlock(x + 3, y + 30, z + 17, Blocks.leaves2, 5, 3);
		world.setBlock(x + 4, y + 30, z + 17, Blocks.leaves2, 5, 3);
		world.setBlock(x + 5, y + 30, z + 17, Blocks.leaves2, 5, 3);
		world.setBlock(x + 6, y + 30, z + 17, Blocks.leaves2, 5, 3);
		world.setBlock(x + 7, y + 30, z + 17, Blocks.leaves2, 5, 3);
		world.setBlock(x + 8, y + 30, z + 17, Blocks.leaves2, 5, 3);
		world.setBlock(x + 10, y + 30, z + 17, Blocks.leaves2, 5, 3);
		world.setBlock(x + 11, y + 30, z + 17, Blocks.leaves2, 5, 3);
		world.setBlock(x + 12, y + 30, z + 17, Blocks.log2, 1, 3);
		world.setBlock(x + 13, y + 30, z + 17, Blocks.leaves2, 5, 3);
		world.setBlock(x + 14, y + 30, z + 17, Blocks.log2, 1, 3);
		world.setBlock(x + 15, y + 30, z + 17, Blocks.leaves2, 5, 3);
		world.setBlock(x + 16, y + 30, z + 17, Blocks.leaves2, 5, 3);
		world.setBlock(x + 17, y + 30, z + 17, Blocks.leaves2, 5, 3);
		world.setBlock(x + 18, y + 30, z + 17, Blocks.leaves2, 5, 3);
		world.setBlock(x + 21, y + 30, z + 17, Blocks.leaves2, 5, 3);
		world.setBlock(x + 22, y + 30, z + 17, Blocks.leaves2, 5, 3);
		world.setBlock(x + 23, y + 30, z + 17, Blocks.leaves2, 5, 3);
		world.setBlock(x + 0, y + 30, z + 18, Blocks.leaves2, 5, 3);
		world.setBlock(x + 1, y + 30, z + 18, Blocks.leaves2, 5, 3);
		world.setBlock(x + 2, y + 30, z + 18, Blocks.leaves2, 5, 3);
		world.setBlock(x + 3, y + 30, z + 18, Blocks.leaves2, 5, 3);
		world.setBlock(x + 4, y + 30, z + 18, Blocks.leaves2, 5, 3);
		world.setBlock(x + 5, y + 30, z + 18, Blocks.leaves2, 5, 3);
		world.setBlock(x + 6, y + 30, z + 18, Blocks.leaves2, 5, 3);
		world.setBlock(x + 7, y + 30, z + 18, Blocks.leaves2, 5, 3);
		world.setBlock(x + 8, y + 30, z + 18, Blocks.leaves2, 5, 3);
		world.setBlock(x + 9, y + 30, z + 18, Blocks.leaves2, 5, 3);
		world.setBlock(x + 10, y + 30, z + 18, Blocks.log2, 1, 3);
		world.setBlock(x + 11, y + 30, z + 18, Blocks.leaves2, 5, 3);
		world.setBlock(x + 12, y + 30, z + 18, Blocks.leaves2, 5, 3);
		world.setBlock(x + 13, y + 30, z + 18, Blocks.leaves2, 5, 3);
		world.setBlock(x + 14, y + 30, z + 18, Blocks.leaves2, 5, 3);
		world.setBlock(x + 15, y + 30, z + 18, Blocks.leaves2, 5, 3);
		world.setBlock(x + 16, y + 30, z + 18, Blocks.leaves2, 5, 3);
		world.setBlock(x + 17, y + 30, z + 18, Blocks.log2, 1, 3);
		world.setBlock(x + 20, y + 30, z + 18, Blocks.leaves2, 13, 3);
		world.setBlock(x + 21, y + 30, z + 18, Blocks.leaves2, 5, 3);
		world.setBlock(x + 22, y + 30, z + 18, Blocks.leaves2, 13, 3);
		world.setBlock(x + 23, y + 30, z + 18, Blocks.leaves2, 5, 3);
		world.setBlock(x + 24, y + 30, z + 18, Blocks.leaves2, 13, 3);
		world.setBlock(x + 0, y + 30, z + 19, Blocks.leaves2, 5, 3);
		world.setBlock(x + 1, y + 30, z + 19, Blocks.leaves2, 5, 3);
		world.setBlock(x + 2, y + 30, z + 19, Blocks.leaves2, 5, 3);
		world.setBlock(x + 3, y + 30, z + 19, Blocks.leaves2, 5, 3);
		world.setBlock(x + 5, y + 30, z + 19, Blocks.leaves2, 5, 3);
		world.setBlock(x + 6, y + 30, z + 19, Blocks.leaves2, 5, 3);
		world.setBlock(x + 7, y + 30, z + 19, Blocks.leaves2, 5, 3);
		world.setBlock(x + 8, y + 30, z + 19, Blocks.leaves2, 5, 3);
		world.setBlock(x + 9, y + 30, z + 19, Blocks.leaves2, 5, 3);
		world.setBlock(x + 10, y + 30, z + 19, Blocks.leaves2, 5, 3);
		world.setBlock(x + 11, y + 30, z + 19, Blocks.leaves2, 5, 3);
		world.setBlock(x + 12, y + 30, z + 19, Blocks.leaves2, 5, 3);
		world.setBlock(x + 13, y + 30, z + 19, Blocks.leaves2, 5, 3);
		world.setBlock(x + 14, y + 30, z + 19, Blocks.leaves2, 5, 3);
		world.setBlock(x + 15, y + 30, z + 19, Blocks.leaves2, 5, 3);
		world.setBlock(x + 16, y + 30, z + 19, Blocks.log2, 1, 3);
		world.setBlock(x + 17, y + 30, z + 19, Blocks.leaves2, 5, 3);
		world.setBlock(x + 20, y + 30, z + 19, Blocks.leaves2, 5, 3);
		world.setBlock(x + 21, y + 30, z + 19, Blocks.leaves2, 5, 3);
		world.setBlock(x + 22, y + 30, z + 19, Blocks.leaves2, 5, 3);
		world.setBlock(x + 23, y + 30, z + 19, Blocks.leaves2, 5, 3);
		world.setBlock(x + 1, y + 30, z + 20, Blocks.leaves2, 5, 3);
		world.setBlock(x + 2, y + 30, z + 20, Blocks.leaves2, 5, 3);
		world.setBlock(x + 3, y + 30, z + 20, Blocks.leaves2, 5, 3);
		world.setBlock(x + 5, y + 30, z + 20, Blocks.leaves2, 5, 3);
		world.setBlock(x + 6, y + 30, z + 20, Blocks.leaves2, 5, 3);
		world.setBlock(x + 7, y + 30, z + 20, Blocks.leaves2, 5, 3);
		world.setBlock(x + 9, y + 30, z + 20, Blocks.leaves2, 5, 3);
		world.setBlock(x + 12, y + 30, z + 20, Blocks.log2, 1, 3);
		world.setBlock(x + 13, y + 30, z + 20, Blocks.leaves2, 5, 3);
		world.setBlock(x + 14, y + 30, z + 20, Blocks.leaves2, 5, 3);
		world.setBlock(x + 15, y + 30, z + 20, Blocks.leaves2, 5, 3);
		world.setBlock(x + 16, y + 30, z + 20, Blocks.leaves2, 5, 3);
		world.setBlock(x + 18, y + 30, z + 20, Blocks.leaves2, 5, 3);
		world.setBlock(x + 19, y + 30, z + 20, Blocks.leaves2, 5, 3);
		world.setBlock(x + 20, y + 30, z + 20, Blocks.leaves2, 5, 3);
		world.setBlock(x + 21, y + 30, z + 20, Blocks.leaves2, 5, 3);
		world.setBlock(x + 22, y + 30, z + 20, Blocks.leaves2, 5, 3);
		world.setBlock(x + 2, y + 30, z + 21, Blocks.leaves2, 5, 3);
		world.setBlock(x + 3, y + 30, z + 21, Blocks.leaves2, 5, 3);
		world.setBlock(x + 5, y + 30, z + 21, Blocks.leaves2, 5, 3);
		world.setBlock(x + 7, y + 30, z + 21, Blocks.leaves2, 5, 3);
		world.setBlock(x + 8, y + 30, z + 21, Blocks.leaves2, 5, 3);
		world.setBlock(x + 12, y + 30, z + 21, Blocks.leaves2, 5, 3);
		world.setBlock(x + 14, y + 30, z + 21, Blocks.log2, 1, 3);
		world.setBlock(x + 15, y + 30, z + 21, Blocks.leaves2, 13, 3);
		world.setBlock(x + 17, y + 30, z + 21, Blocks.leaves2, 5, 3);
		world.setBlock(x + 18, y + 30, z + 21, Blocks.leaves2, 5, 3);
		world.setBlock(x + 19, y + 30, z + 21, Blocks.leaves2, 5, 3);
		world.setBlock(x + 20, y + 30, z + 21, Blocks.leaves2, 5, 3);

		generate_r02(world,  x, y, z);
		return true;

	}
	
	
	public static void VerqueBloqueGenerar() {
	   int detectaradn = 0;
		Random generator2 = new Random(); 
        int nSelection = generator2.nextInt(posiblesbloques.length); 
        String bloque1 = posiblesbloques[nSelection]; 
        
        
        if(bloque1.equalsIgnoreCase("hueso")) {
        	bloque = MaderaHueso;
        }else if(bloque1.equalsIgnoreCase("adn")) {
        	
        	detectaradn = 1 + generator2.nextInt(10);
        	if(detectaradn <= 3) {
        		bloque = Maderaadn;
        	}else {
        		bloque = MaderaFosil;
        	}
        }else if(bloque1.equalsIgnoreCase("ambar")) {
        	bloque = Maderaambar;
        }else if(bloque1.equalsIgnoreCase("normal")) {
        	bloque = MaderaFosil;
        }
		
	}
	
	
	private static String[] posiblesbloques = {
			"normal",
			"hueso",
			"normal",
			"adn",
			"normal",
			"ambar",
			"normal",
			
	};
	
	public boolean generate_r02(World world,  int x, int y, int z)
	{

		world.setBlock(x + 21, y + 30, z + 21, Blocks.leaves2, 5, 3);
		world.setBlock(x + 22, y + 30, z + 21, Blocks.leaves2, 5, 3);
		world.setBlock(x + 1, y + 30, z + 22, Blocks.leaves2, 5, 3);
		world.setBlock(x + 2, y + 30, z + 22, Blocks.leaves2, 5, 3);
		world.setBlock(x + 3, y + 30, z + 22, Blocks.leaves2, 5, 3);
		world.setBlock(x + 4, y + 30, z + 22, Blocks.leaves2, 5, 3);
		world.setBlock(x + 7, y + 30, z + 22, Blocks.leaves2, 5, 3);
		world.setBlock(x + 8, y + 30, z + 22, Blocks.leaves2, 5, 3);
		world.setBlock(x + 9, y + 30, z + 22, Blocks.leaves2, 5, 3);
		world.setBlock(x + 11, y + 30, z + 22, Blocks.leaves2, 5, 3);
		world.setBlock(x + 13, y + 30, z + 22, Blocks.leaves2, 5, 3);
		world.setBlock(x + 14, y + 30, z + 22, Blocks.leaves2, 13, 3);
		world.setBlock(x + 15, y + 30, z + 22, Blocks.leaves2, 5, 3);
		world.setBlock(x + 16, y + 30, z + 22, Blocks.leaves2, 13, 3);
		world.setBlock(x + 17, y + 30, z + 22, Blocks.leaves2, 5, 3);
		world.setBlock(x + 18, y + 30, z + 22, Blocks.leaves2, 5, 3);
		world.setBlock(x + 19, y + 30, z + 22, Blocks.leaves2, 5, 3);
		world.setBlock(x + 20, y + 30, z + 22, Blocks.leaves2, 5, 3);
		world.setBlock(x + 24, y + 30, z + 22, Blocks.leaves2, 5, 3);
		world.setBlock(x + 2, y + 30, z + 23, Blocks.leaves2, 5, 3);
		world.setBlock(x + 3, y + 30, z + 23, Blocks.leaves2, 5, 3);
		world.setBlock(x + 4, y + 30, z + 23, Blocks.leaves2, 5, 3);
		world.setBlock(x + 9, y + 30, z + 23, Blocks.leaves2, 5, 3);
		world.setBlock(x + 10, y + 30, z + 23, Blocks.leaves2, 5, 3);
		world.setBlock(x + 11, y + 30, z + 23, Blocks.leaves2, 5, 3);
		world.setBlock(x + 12, y + 30, z + 23, Blocks.leaves2, 5, 3);
		world.setBlock(x + 14, y + 30, z + 23, Blocks.leaves2, 5, 3);
		world.setBlock(x + 15, y + 30, z + 23, Blocks.leaves2, 13, 3);
		world.setBlock(x + 16, y + 30, z + 23, Blocks.leaves2, 5, 3);
		world.setBlock(x + 17, y + 30, z + 23, Blocks.leaves2, 5, 3);
		world.setBlock(x + 18, y + 30, z + 23, Blocks.leaves2, 5, 3);
		world.setBlock(x + 19, y + 30, z + 23, Blocks.leaves2, 5, 3);
		world.setBlock(x + 20, y + 30, z + 23, Blocks.leaves2, 5, 3);
		world.setBlock(x + 25, y + 30, z + 23, Blocks.leaves2, 5, 3);
		world.setBlock(x + 2, y + 30, z + 24, Blocks.leaves2, 5, 3);
		world.setBlock(x + 3, y + 30, z + 24, Blocks.leaves2, 5, 3);
		world.setBlock(x + 4, y + 30, z + 24, Blocks.leaves2, 5, 3);
		world.setBlock(x + 5, y + 30, z + 24, Blocks.leaves2, 5, 3);
		world.setBlock(x + 6, y + 30, z + 24, Blocks.leaves2, 5, 3);
		world.setBlock(x + 7, y + 30, z + 24, Blocks.leaves2, 5, 3);
		world.setBlock(x + 8, y + 30, z + 24, Blocks.leaves2, 5, 3);
		world.setBlock(x + 9, y + 30, z + 24, Blocks.leaves2, 5, 3);
		world.setBlock(x + 10, y + 30, z + 24, Blocks.leaves2, 5, 3);
		world.setBlock(x + 11, y + 30, z + 24, Blocks.leaves2, 5, 3);
		world.setBlock(x + 12, y + 30, z + 24, Blocks.leaves2, 5, 3);
