//Schematic to java Structure by jajo_11 | inspired by "MITHION'S .SCHEMATIC TO JAVA CONVERTINGTOOL"

package RubyCraft.Estructuras;

import java.util.Random;

import RubyCraft.xJuanathan.Principal;
import net.minecraft.init.Blocks;
import net.minecraft.world.World;
import net.minecraft.world.gen.feature.WorldGenMinable;
import net.minecraft.world.gen.feature.WorldGenerator;


public class Arbol extends WorldGenerator
{
	
public static int x1;
public static int y1 = 0;
public static int z1;
	public boolean generate(World world, Random rand, int x, int y, int z)
	{
	
		    generate_r0(world,  x, y, z);
		

       return true;

	}

	public boolean generate_r0(World world,  int x, int y, int z)
	{
		

		world.setBlock(x + 9, y + 1, z + 12, Blocks.log2, 1, 3);
		world.setBlock(x + 20, y + 1, z + 12, Blocks.log2, 1, 3);
		world.setBlock(x + 15, y + 1, z + 17, Principal.Madera_Fosil, 0, 3);
		world.setBlock(x + 9, y + 1, z + 23, Blocks.log2, 1, 3);
		world.setBlock(x + 20, y + 1, z + 23, Blocks.log2, 1, 3);
		world.setBlock(x + 9, y + 2, z + 11, Blocks.log2, 1, 3);
		world.setBlock(x + 20, y + 2, z + 11, Blocks.log2, 1, 3);
		world.setBlock(x + 8, y + 2, z + 12, Blocks.log2, 1, 3);
		world.setBlock(x + 9, y + 2, z + 12, Blocks.log2, 1, 3);
		world.setBlock(x + 10, y + 2, z + 12, Blocks.log2, 1, 3);
		world.setBlock(x + 20, y + 2, z + 12, Blocks.log2, 1, 3);
		world.setBlock(x + 21, y + 2, z + 12, Blocks.log2, 1, 3);
		world.setBlock(x + 9, y + 2, z + 13, Blocks.log2, 1, 3);
		world.setBlock(x + 14, y + 2, z + 17, Blocks.log2, 1, 3);
		world.setBlock(x + 15, y + 2, z + 17, Blocks.log2, 1, 3);
		world.setBlock(x + 14, y + 2, z + 18, Blocks.log2, 1, 3);
		world.setBlock(x + 15, y + 2, z + 18, Blocks.log2, 1, 3);
		world.setBlock(x + 9, y + 2, z + 22, Blocks.log2, 1, 3);
		world.setBlock(x + 20, y + 2, z + 22, Blocks.log2, 1, 3);
		world.setBlock(x + 8, y + 2, z + 23, Blocks.log2, 1, 3);
		world.setBlock(x + 9, y + 2, z + 23, Blocks.log2, 1, 3);
		world.setBlock(x + 10, y + 2, z + 23, Blocks.log2, 1, 3);
		world.setBlock(x + 19, y + 2, z + 23, Blocks.log2, 1, 3);
		world.setBlock(x + 20, y + 2, z + 23, Blocks.log2, 1, 3);
		world.setBlock(x + 21, y + 2, z + 23, Blocks.log2, 1, 3);
		world.setBlock(x + 9, y + 2, z + 24, Blocks.log2, 1, 3);
		world.setBlock(x + 20, y + 2, z + 24, Blocks.log2, 1, 3);
		world.setBlock(x + 9, y + 3, z + 10, Blocks.log2, 1, 3);
		world.setBlock(x + 20, y + 3, z + 10, Blocks.log2, 1, 3);
		world.setBlock(x + 8, y + 3, z + 11, Blocks.log2, 1, 3);
		world.setBlock(x + 9, y + 3, z + 11, Blocks.log2, 1, 3);
		world.setBlock(x + 10, y + 3, z + 11, Blocks.log2, 1, 3);
		world.setBlock(x + 19, y + 3, z + 11, Blocks.log2, 1, 3);
		world.setBlock(x + 20, y + 3, z + 11, Blocks.log2, 1, 3);
		world.setBlock(x + 21, y + 3, z + 11, Blocks.log2, 1, 3);
		world.setBlock(x + 7, y + 3, z + 12, Blocks.log2, 1, 3);
		world.setBlock(x + 8, y + 3, z + 12, Blocks.log2, 1, 3);
		world.setBlock(x + 9, y + 3, z + 12, Blocks.log2, 1, 3);
		world.setBlock(x + 10, y + 3, z + 12, Blocks.log2, 1, 3);
		world.setBlock(x + 20, y + 3, z + 12, Blocks.log2, 1, 3);
		world.setBlock(x + 21, y + 3, z + 12, Blocks.log2, 1, 3);
		world.setBlock(x + 22, y + 3, z + 12, Blocks.log2, 1, 3);
		world.setBlock(x + 8, y + 3, z + 13, Blocks.log2, 1, 3);
		world.setBlock(x + 9, y + 3, z + 13, Blocks.log2, 1, 3);
		world.setBlock(x + 10, y + 3, z + 13, Blocks.log2, 1, 3);
		world.setBlock(x + 21, y + 3, z + 13, Blocks.log2, 1, 3);
		world.setBlock(x + 9, y + 3, z + 14, Blocks.log2, 1, 3);
		world.setBlock(x + 13, y + 3, z + 16, Blocks.log2, 1, 3);
		world.setBlock(x + 16, y + 3, z + 16, Blocks.log2, 1, 3);
		world.setBlock(x + 14, y + 3, z + 17, Blocks.log2, 1, 3);
		world.setBlock(x + 15, y + 3, z + 17, Blocks.log2, 1, 3);
		world.setBlock(x + 14, y + 3, z + 18, Blocks.log2, 1, 3);
		world.setBlock(x + 15, y + 3, z + 18, Blocks.log2, 1, 3);
		world.setBlock(x + 13, y + 3, z + 19, Blocks.log2, 1, 3);
		world.setBlock(x + 16, y + 3, z + 19, Blocks.log2, 1, 3);
		world.setBlock(x + 9, y + 3, z + 21, Blocks.log2, 1, 3);
		world.setBlock(x + 20, y + 3, z + 21, Blocks.log2, 1, 3);
		world.setBlock(x + 8, y + 3, z + 22, Blocks.log2, 1, 3);
		world.setBlock(x + 9, y + 3, z + 22, Blocks.log2, 1, 3);
		world.setBlock(x + 10, y + 3, z + 22, Blocks.log2, 1, 3);
		world.setBlock(x + 19, y + 3, z + 22, Blocks.log2, 1, 3);
		world.setBlock(x + 20, y + 3, z + 22, Blocks.log2, 1, 3);
		world.setBlock(x + 21, y + 3, z + 22, Blocks.log2, 1, 3);
		world.setBlock(x + 7, y + 3, z + 23, Blocks.log2, 1, 3);
		world.setBlock(x + 8, y + 3, z + 23, Blocks.log2, 1, 3);
		world.setBlock(x + 9, y + 3, z + 23, Blocks.log2, 1, 3);
		world.setBlock(x + 10, y + 3, z + 23, Blocks.log2, 1, 3);
		world.setBlock(x + 11, y + 3, z + 23, Blocks.log2, 1, 3);
		world.setBlock(x + 19, y + 3, z + 23, Blocks.log2, 1, 3);
		world.setBlock(x + 20, y + 3, z + 23, Blocks.log2, 1, 3);
		world.setBlock(x + 21, y + 3, z + 23, Blocks.log2, 1, 3);
		world.setBlock(x + 22, y + 3, z + 23, Blocks.log2, 1, 3);
		world.setBlock(x + 8, y + 3, z + 24, Blocks.log2, 1, 3);
		world.setBlock(x + 9, y + 3, z + 24, Blocks.log2, 1, 3);
		world.setBlock(x + 10, y + 3, z + 24, Blocks.log2, 1, 3);
		world.setBlock(x + 19, y + 3, z + 24, Blocks.log2, 1, 3);
		world.setBlock(x + 20, y + 3, z + 24, Blocks.log2, 1, 3);
		world.setBlock(x + 21, y + 3, z + 24, Blocks.log2, 1, 3);
		world.setBlock(x + 9, y + 3, z + 25, Blocks.log2, 1, 3);
		world.setBlock(x + 20, y + 3, z + 25, Blocks.log2, 1, 3);
		world.setBlock(x + 9, y + 4, z + 10, Blocks.log2, 1, 3);
		world.setBlock(x + 20, y + 4, z + 10, Blocks.log2, 1, 3);
		world.setBlock(x + 8, y + 4, z + 11, Blocks.log2, 1, 3);
		world.setBlock(x + 9, y + 4, z + 11, Blocks.log2, 1, 3);
		world.setBlock(x + 10, y + 4, z + 11, Blocks.log2, 1, 3);
		world.setBlock(x + 19, y + 4, z + 11, Blocks.log2, 1, 3);
		world.setBlock(x + 20, y + 4, z + 11, Blocks.log2, 1, 3);
		world.setBlock(x + 21, y + 4, z + 11, Blocks.log2, 1, 3);
		world.setBlock(x + 7, y + 4, z + 12, Blocks.log2, 1, 3);
		world.setBlock(x + 8, y + 4, z + 12, Blocks.log2, 1, 3);
		world.setBlock(x + 9, y + 4, z + 12, Blocks.log2, 1, 3);
		world.setBlock(x + 10, y + 4, z + 12, Blocks.log2, 1, 3);
		world.setBlock(x + 19, y + 4, z + 12, Blocks.log2, 1, 3);
		world.setBlock(x + 20, y + 4, z + 12, Blocks.log2, 1, 3);
		world.setBlock(x + 21, y + 4, z + 12, Blocks.log2, 1, 3);
		world.setBlock(x + 22, y + 4, z + 12, Blocks.log2, 1, 3);
		world.setBlock(x + 8, y + 4, z + 13, Blocks.log2, 1, 3);
		world.setBlock(x + 9, y + 4, z + 13, Blocks.log2, 1, 3);
		world.setBlock(x + 10, y + 4, z + 13, Blocks.log2, 1, 3);
		world.setBlock(x + 19, y + 4, z + 13, Blocks.log2, 1, 3);
		world.setBlock(x + 21, y + 4, z + 13, Blocks.log2, 1, 3);
		world.setBlock(x + 9, y + 4, z + 14, Blocks.log2, 1, 3);
		world.setBlock(x + 10, y + 4, z + 14, Blocks.log2, 1, 3);
		world.setBlock(x + 11, y + 4, z + 14, Blocks.log2, 1, 3);
		world.setBlock(x + 18, y + 4, z + 14, Blocks.log2, 1, 3);
		world.setBlock(x + 12, y + 4, z + 15, Blocks.log2, 1, 3);
		world.setBlock(x + 17, y + 4, z + 15, Blocks.log2, 1, 3);
		world.setBlock(x + 13, y + 4, z + 16, Blocks.log2, 1, 3);
		world.setBlock(x + 14, y + 4, z + 16, Blocks.log2, 1, 3);
		world.setBlock(x + 15, y + 4, z + 16, Blocks.log2, 1, 3);
		world.setBlock(x + 16, y + 4, z + 16, Blocks.log2, 1, 3);
		world.setBlock(x + 13, y + 4, z + 17, Blocks.log2, 1, 3);
		world.setBlock(x + 14, y + 4, z + 17, Blocks.log2, 1, 3);
		world.setBlock(x + 15, y + 4, z + 17, Blocks.log2, 1, 3);
		world.setBlock(x + 16, y + 4, z + 17, Blocks.log2, 1, 3);
		world.setBlock(x + 13, y + 4, z + 18, Blocks.log2, 1, 3);
		world.setBlock(x + 14, y + 4, z + 18, Blocks.log2, 1, 3);
		world.setBlock(x + 15, y + 4, z + 18, Blocks.log2, 1, 3);
		world.setBlock(x + 16, y + 4, z + 18, Blocks.log2, 1, 3);
		world.setBlock(x + 13, y + 4, z + 19, Blocks.log2, 1, 3);
		world.setBlock(x + 14, y + 4, z + 19, Blocks.log2, 1, 3);
		world.setBlock(x + 15, y + 4, z + 19, Blocks.log2, 1, 3);
		world.setBlock(x + 16, y + 4, z + 19, Blocks.log2, 1, 3);
		world.setBlock(x + 12, y + 4, z + 20, Blocks.log2, 1, 3);
		world.setBlock(x + 17, y + 4, z + 20, Blocks.log2, 1, 3);
		world.setBlock(x + 9, y + 4, z + 21, Blocks.log2, 1, 3);
		world.setBlock(x + 11, y + 4, z + 21, Blocks.log2, 1, 3);
		world.setBlock(x + 18, y + 4, z + 21, Blocks.log2, 1, 3);
		world.setBlock(x + 19, y + 4, z + 21, Blocks.log2, 1, 3);
		world.setBlock(x + 20, y + 4, z + 21, Blocks.log2, 1, 3);
		world.setBlock(x + 8, y + 4, z + 22, Blocks.log2, 1, 3);
		world.setBlock(x + 9, y + 4, z + 22, Blocks.log2, 1, 3);
		world.setBlock(x + 10, y + 4, z + 22, Blocks.log2, 1, 3);
		world.setBlock(x + 11, y + 4, z + 22, Blocks.log2, 1, 3);
		world.setBlock(x + 19, y + 4, z + 22, Blocks.log2, 1, 3);
		world.setBlock(x + 20, y + 4, z + 22, Blocks.log2, 1, 3);
		world.setBlock(x + 21, y + 4, z + 22, Blocks.log2, 1, 3);
		world.setBlock(x + 7, y + 4, z + 23, Blocks.log2, 1, 3);
		world.setBlock(x + 8, y + 4, z + 23, Blocks.log2, 1, 3);
		world.setBlock(x + 9, y + 4, z + 23, Blocks.log2, 1, 3);
		world.setBlock(x + 10, y + 4, z + 23, Blocks.log2, 1, 3);
		world.setBlock(x + 11, y + 4, z + 23, Blocks.log2, 1, 3);
		world.setBlock(x + 18, y + 4, z + 23, Blocks.log2, 1, 3);
		world.setBlock(x + 19, y + 4, z + 23, Blocks.log2, 1, 3);
		world.setBlock(x + 20, y + 4, z + 23, Blocks.log2, 1, 3);
		world.setBlock(x + 21, y + 4, z + 23, Blocks.log2, 1, 3);
		world.setBlock(x + 22, y + 4, z + 23, Blocks.log2, 1, 3);
		world.setBlock(x + 8, y + 4, z + 24, Blocks.log2, 1, 3);
		world.setBlock(x + 9, y + 4, z + 24, Blocks.log2, 1, 3);
		world.setBlock(x + 10, y + 4, z + 24, Blocks.log2, 1, 3);
		world.setBlock(x + 19, y + 4, z + 24, Blocks.log2, 1, 3);
		world.setBlock(x + 20, y + 4, z + 24, Blocks.log2, 1, 3);
		world.setBlock(x + 21, y + 4, z + 24, Blocks.log2, 1, 3);
		world.setBlock(x + 9, y + 4, z + 25, Blocks.log2, 1, 3);
		world.setBlock(x + 20, y + 4, z + 25, Blocks.log2, 1, 3);
		world.setBlock(x + 9, y + 5, z + 11, Blocks.log2, 1, 3);
		world.setBlock(x + 20, y + 5, z + 11, Blocks.log2, 1, 3);
		world.setBlock(x + 8, y + 5, z + 12, Blocks.log2, 1, 3);
		world.setBlock(x + 9, y + 5, z + 12, Blocks.log2, 1, 3);
		world.setBlock(x + 10, y + 5, z + 12, Blocks.log2, 1, 3);
		world.setBlock(x + 18, y + 5, z + 12, Blocks.log2, 1, 3);
		world.setBlock(x + 19, y + 5, z + 12, Blocks.log2, 1, 3);
		world.setBlock(x + 20, y + 5, z + 12, Blocks.log2, 1, 3);
		world.setBlock(x + 21, y + 5, z + 12, Blocks.log2, 1, 3);
		world.setBlock(x + 9, y + 5, z + 13, Blocks.log2, 1, 3);
		world.setBlock(x + 10, y + 5, z + 13, Blocks.log2, 1, 3);
		world.setBlock(x + 11, y + 5, z + 13, Blocks.log2, 1, 3);
		world.setBlock(x + 18, y + 5, z + 13, Blocks.log2, 1, 3);
		world.setBlock(x + 19, y + 5, z + 13, Blocks.log2, 1, 3);
		world.setBlock(x + 20, y + 5, z + 13, Blocks.log2, 1, 3);
		world.setBlock(x + 10, y + 5, z + 14, Blocks.log2, 1, 3);
		world.setBlock(x + 11, y + 5, z + 14, Blocks.log2, 1, 3);
		world.setBlock(x + 12, y + 5, z + 14, Blocks.log2, 1, 3);
		world.setBlock(x + 17, y + 5, z + 14, Blocks.log2, 1, 3);
		world.setBlock(x + 18, y + 5, z + 14, Blocks.log2, 1, 3);
		world.setBlock(x + 19, y + 5, z + 14, Blocks.log2, 1, 3);
		world.setBlock(x + 11, y + 5, z + 15, Blocks.log2, 1, 3);
		world.setBlock(x + 12, y + 5, z + 15, Blocks.log2, 1, 3);
		world.setBlock(x + 14, y + 5, z + 15, Blocks.log2, 1, 3);
		world.setBlock(x + 15, y + 5, z + 15, Blocks.log2, 1, 3);
		world.setBlock(x + 17, y + 5, z + 15, Blocks.log2, 1, 3);
		world.setBlock(x + 18, y + 5, z + 15, Blocks.log2, 1, 3);
		world.setBlock(x + 13, y + 5, z + 16, Blocks.log2, 1, 3);
		world.setBlock(x + 14, y + 5, z + 16, Blocks.log2, 1, 3);
		world.setBlock(x + 15, y + 5, z + 16, Blocks.log2, 1, 3);
		world.setBlock(x + 16, y + 5, z + 16, Blocks.log2, 1, 3);
		world.setBlock(x + 12, y + 5, z + 17, Blocks.log2, 1, 3);
		world.setBlock(x + 13, y + 5, z + 17, Blocks.log2, 1, 3);
		world.setBlock(x + 14, y + 5, z + 17, Blocks.log2, 1, 3);
		world.setBlock(x + 15, y + 5, z + 17, Blocks.log2, 1, 3);
		world.setBlock(x + 16, y + 5, z + 17, Blocks.log2, 1, 3);
		world.setBlock(x + 17, y + 5, z + 17, Blocks.log2, 1, 3);
		world.setBlock(x + 12, y + 5, z + 18, Blocks.log2, 1, 3);
		world.setBlock(x + 13, y + 5, z + 18, Blocks.log2, 1, 3);
		world.setBlock(x + 14, y + 5, z + 18, Blocks.log2, 1, 3);
		world.setBlock(x + 15, y + 5, z + 18, Blocks.log2, 1, 3);
		world.setBlock(x + 16, y + 5, z + 18, Blocks.log2, 1, 3);
		world.setBlock(x + 17, y + 5, z + 18, Blocks.log2, 1, 3);
		world.setBlock(x + 13, y + 5, z + 19, Blocks.log2, 1, 3);
		world.setBlock(x + 14, y + 5, z + 19, Blocks.log2, 1, 3);
		world.setBlock(x + 15, y + 5, z + 19, Blocks.log2, 1, 3);
		world.setBlock(x + 16, y + 5, z + 19, Blocks.log2, 1, 3);
		world.setBlock(x + 11, y + 5, z + 20, Blocks.log2, 1, 3);
		world.setBlock(x + 12, y + 5, z + 20, Blocks.log2, 1, 3);
		world.setBlock(x + 14, y + 5, z + 20, Blocks.log2, 1, 3);
		world.setBlock(x + 15, y + 5, z + 20, Blocks.log2, 1, 3);
		world.setBlock(x + 17, y + 5, z + 20, Blocks.log2, 1, 3);
		world.setBlock(x + 18, y + 5, z + 20, Blocks.log2, 1, 3);
		world.setBlock(x + 10, y + 5, z + 21, Blocks.log2, 1, 3);
		world.setBlock(x + 11, y + 5, z + 21, Blocks.log2, 1, 3);
		world.setBlock(x + 12, y + 5, z + 21, Blocks.log2, 1, 3);
		world.setBlock(x + 17, y + 5, z + 21, Blocks.log2, 1, 3);
		world.setBlock(x + 18, y + 5, z + 21, Blocks.log2, 1, 3);
		world.setBlock(x + 19, y + 5, z + 21, Blocks.log2, 1, 3);
		world.setBlock(x + 9, y + 5, z + 22, Blocks.log2, 1, 3);
		world.setBlock(x + 10, y + 5, z + 22, Blocks.log2, 1, 3);
		world.setBlock(x + 11, y + 5, z + 22, Blocks.log2, 1, 3);
		world.setBlock(x + 18, y + 5, z + 22, Blocks.log2, 1, 3);
		world.setBlock(x + 19, y + 5, z + 22, Blocks.log2, 1, 3);
		world.setBlock(x + 20, y + 5, z + 22, Blocks.log2, 1, 3);
		world.setBlock(x + 8, y + 5, z + 23, Blocks.log2, 1, 3);
		world.setBlock(x + 9, y + 5, z + 23, Blocks.log2, 1, 3);
		world.setBlock(x + 10, y + 5, z + 23, Blocks.log2, 1, 3);
		world.setBlock(x + 18, y + 5, z + 23, Blocks.log2, 1, 3);
		world.setBlock(x + 19, y + 5, z + 23, Blocks.log2, 1, 3);
		world.setBlock(x + 20, y + 5, z + 23, Blocks.log2, 1, 3);
		world.setBlock(x + 21, y + 5, z + 23, Blocks.log2, 1, 3);
		world.setBlock(x + 9, y + 5, z + 24, Blocks.log2, 1, 3);
		world.setBlock(x + 20, y + 5, z + 24, Blocks.log2, 1, 3);
		world.setBlock(x + 9, y + 6, z + 12, Blocks.log2, 5, 3);
		world.setBlock(x + 20, y + 6, z + 12, Blocks.log2, 5, 3);
		world.setBlock(x + 10, y + 6, z + 13, Blocks.log2, 1, 3);
		world.setBlock(x + 12, y + 6, z + 15, Blocks.log2, 1, 3);
		world.setBlock(x + 9, y + 6, z + 23, Blocks.log2, 9, 3);
		world.setBlock(x + 20, y + 6, z + 23, Blocks.log2, 5, 3);
		world.setBlock(x + 10, y + 7, z + 13, Blocks.log2, 1, 3);
		world.setBlock(x + 14, y + 7, z + 13, Blocks.log2, 1, 3);
		world.setBlock(x + 15, y + 7, z + 13, Blocks.log2, 1, 3);
		world.setBlock(x + 19, y + 7, z + 13, Blocks.log2, 1, 3);
		world.setBlock(x + 11, y + 7, z + 14, Blocks.log2, 1, 3);
		world.setBlock(x + 13, y + 7, z + 14, Blocks.log2, 1, 3);
		world.setBlock(x + 14, y + 7, z + 14, Blocks.log2, 1, 3);
		world.setBlock(x + 15, y + 7, z + 14, Blocks.log2, 1, 3);
		world.setBlock(x + 16, y + 7, z + 14, Blocks.log2, 1, 3);
		world.setBlock(x + 18, y + 7, z + 14, Blocks.log2, 1, 3);
		world.setBlock(x + 12, y + 7, z + 15, Blocks.log2, 1, 3);
		world.setBlock(x + 13, y + 7, z + 15, Blocks.log2, 1, 3);
		world.setBlock(x + 14, y + 7, z + 15, Blocks.log2, 1, 3);
		world.setBlock(x + 15, y + 7, z + 15, Blocks.log2, 1, 3);
		world.setBlock(x + 16, y + 7, z + 15, Blocks.log2, 1, 3);
		world.setBlock(x + 17, y + 7, z + 15, Blocks.log2, 1, 3);
		world.setBlock(x + 11, y + 7, z + 16, Blocks.log2, 1, 3);
		world.setBlock(x + 12, y + 7, z + 16, Blocks.log2, 1, 3);
		world.setBlock(x + 13, y + 7, z + 16, Blocks.log2, 1, 3);
		world.setBlock(x + 14, y + 7, z + 16, Blocks.log2, 1, 3);
		world.setBlock(x + 15, y + 7, z + 16, Blocks.log2, 1, 3);
		world.setBlock(x + 16, y + 7, z + 16, Blocks.log2, 1, 3);
		world.setBlock(x + 17, y + 7, z + 16, Blocks.log2, 1, 3);
		world.setBlock(x + 18, y + 7, z + 16, Blocks.log2, 1, 3);
		world.setBlock(x + 10, y + 7, z + 17, Blocks.log2, 1, 3);
		world.setBlock(x + 11, y + 7, z + 17, Blocks.log2, 1, 3);
		world.setBlock(x + 12, y + 7, z + 17, Blocks.log2, 1, 3);
		world.setBlock(x + 13, y + 7, z + 17, Blocks.log2, 1, 3);
		world.setBlock(x + 14, y + 7, z + 17, Blocks.log2, 1, 3);
		world.setBlock(x + 15, y + 7, z + 17, Blocks.log2, 1, 3);
		world.setBlock(x + 16, y + 7, z + 17, Blocks.log2, 1, 3);
		world.setBlock(x + 17, y + 7, z + 17, Blocks.log2, 1, 3);
		world.setBlock(x + 18, y + 7, z + 17, Blocks.log2, 1, 3);
		world.setBlock(x + 19, y + 7, z + 17, Blocks.log2, 1, 3);
		world.setBlock(x + 10, y + 7, z + 18, Blocks.log2, 1, 3);
		world.setBlock(x + 11, y + 7, z + 18, Blocks.log2, 1, 3);
		world.setBlock(x + 12, y + 7, z + 18, Blocks.log2, 1, 3);
		world.setBlock(x + 13, y + 7, z + 18, Blocks.log2, 1, 3);
		world.setBlock(x + 14, y + 7, z + 18, Blocks.log2, 1, 3);
		world.setBlock(x + 15, y + 7, z + 18, Blocks.log2, 1, 3);
		world.setBlock(x + 16, y + 7, z + 18, Blocks.log2, 1, 3);
		world.setBlock(x + 17, y + 7, z + 18, Blocks.log2, 1, 3);
		world.setBlock(x + 18, y + 7, z + 18, Blocks.log2, 1, 3);
		world.setBlock(x + 19, y + 7, z + 18, Blocks.log2, 1, 3);
		world.setBlock(x + 11, y + 7, z + 19, Blocks.log2, 1, 3);
		world.setBlock(x + 12, y + 7, z + 19, Blocks.log2, 1, 3);
		world.setBlock(x + 13, y + 7, z + 19, Blocks.log2, 1, 3);
		world.setBlock(x + 14, y + 7, z + 19, Blocks.log2, 1, 3);
		world.setBlock(x + 15, y + 7, z + 19, Blocks.log2, 1, 3);
		world.setBlock(x + 16, y + 7, z + 19, Blocks.log2, 1, 3);
		world.setBlock(x + 17, y + 7, z + 19, Blocks.log2, 1, 3);
		world.setBlock(x + 18, y + 7, z + 19, Blocks.log2, 1, 3);
		world.setBlock(x + 12, y + 7, z + 20, Blocks.log2, 1, 3);
		world.setBlock(x + 13, y + 7, z + 20, Blocks.log2, 1, 3);
		world.setBlock(x + 14, y + 7, z + 20, Blocks.log2, 1, 3);
		world.setBlock(x + 15, y + 7, z + 20, Blocks.log2, 1, 3);
		world.setBlock(x + 16, y + 7, z + 20, Blocks.log2, 1, 3);
		world.setBlock(x + 17, y + 7, z + 20, Blocks.log2, 1, 3);
		world.setBlock(x + 11, y + 7, z + 21, Blocks.log2, 1, 3);
		world.setBlock(x + 13, y + 7, z + 21, Blocks.log2, 1, 3);
		world.setBlock(x + 14, y + 7, z + 21, Blocks.log2, 1, 3);
		world.setBlock(x + 15, y + 7, z + 21, Blocks.log2, 1, 3);
		world.setBlock(x + 16, y + 7, z + 21, Blocks.log2, 1, 3);
		world.setBlock(x + 18, y + 7, z + 21, Blocks.log2, 1, 3);
		world.setBlock(x + 10, y + 7, z + 22, Blocks.log2, 1, 3);
		world.setBlock(x + 14, y + 7, z + 22, Blocks.log2, 1, 3);
		world.setBlock(x + 15, y + 7, z + 22, Blocks.log2, 1, 3);
		world.setBlock(x + 19, y + 7, z + 22, Blocks.log2, 1, 3);
		world.setBlock(x + 14, y + 8, z + 14, Blocks.log2, 1, 3);
		world.setBlock(x + 15, y + 8, z + 14, Blocks.log2, 1, 3);
		world.setBlock(x + 12, y + 8, z + 15, Blocks.log2, 1, 3);
		world.setBlock(x + 13, y + 8, z + 15, Blocks.log2, 1, 3);
		world.setBlock(x + 14, y + 8, z + 15, Blocks.log2, 1, 3);
		world.setBlock(x + 15, y + 8, z + 15, Blocks.log2, 1, 3);
		world.setBlock(x + 16, y + 8, z + 15, Blocks.log2, 1, 3);
		world.setBlock(x + 17, y + 8, z + 15, Blocks.log2, 1, 3);
		world.setBlock(x + 12, y + 8, z + 16, Blocks.log2, 1, 3);
		world.setBlock(x + 13, y + 8, z + 16, Blocks.log2, 1, 3);
		world.setBlock(x + 14, y + 8, z + 16, Blocks.log2, 1, 3);
		world.setBlock(x + 15, y + 8, z + 16, Blocks.log2, 1, 3);
		world.setBlock(x + 16, y + 8, z + 16, Blocks.log2, 1, 3);
		world.setBlock(x + 17, y + 8, z + 16, Blocks.log2, 1, 3);
		world.setBlock(x + 11, y + 8, z + 17, Blocks.log2, 1, 3);
		world.setBlock(x + 12, y + 8, z + 17, Blocks.log2, 1, 3);
		world.setBlock(x + 13, y + 8, z + 17, Blocks.log2, 1, 3);
		world.setBlock(x + 14, y + 8, z + 17, Blocks.log2, 1, 3);
		world.setBlock(x + 15, y + 8, z + 17, Blocks.log2, 1, 3);
		world.setBlock(x + 16, y + 8, z + 17, Blocks.log2, 1, 3);
		world.setBlock(x + 17, y + 8, z + 17, Blocks.log2, 1, 3);
		world.setBlock(x + 18, y + 8, z + 17, Blocks.log2, 1, 3);
		world.setBlock(x + 11, y + 8, z + 18, Blocks.log2, 1, 3);
		world.setBlock(x + 12, y + 8, z + 18, Blocks.log2, 1, 3);
		world.setBlock(x + 13, y + 8, z + 18, Blocks.log2, 1, 3);
		world.setBlock(x + 14, y + 8, z + 18, Blocks.log2, 1, 3);
		world.setBlock(x + 15, y + 8, z + 18, Blocks.log2, 1, 3);
		world.setBlock(x + 16, y + 8, z + 18, Blocks.log2, 1, 3);
		world.setBlock(x + 17, y + 8, z + 18, Blocks.log2, 1, 3);
		world.setBlock(x + 18, y + 8, z + 18, Blocks.log2, 1, 3);
		world.setBlock(x + 12, y + 8, z + 19, Blocks.log2, 1, 3);
		world.setBlock(x + 13, y + 8, z + 19, Blocks.log2, 1, 3);
		world.setBlock(x + 14, y + 8, z + 19, Blocks.log2, 1, 3);
		world.setBlock(x + 15, y + 8, z + 19, Blocks.log2, 1, 3);
		world.setBlock(x + 16, y + 8, z + 19, Blocks.log2, 1, 3);
		world.setBlock(x + 17, y + 8, z + 19, Blocks.log2, 1, 3);
		world.setBlock(x + 12, y + 8, z + 20, Blocks.log2, 1, 3);
		world.setBlock(x + 13, y + 8, z + 20, Blocks.log2, 1, 3);
		world.setBlock(x + 14, y + 8, z + 20, Blocks.log2, 1, 3);
		world.setBlock(x + 15, y + 8, z + 20, Blocks.log2, 1, 3);
		world.setBlock(x + 16, y + 8, z + 20, Blocks.log2, 1, 3);
		world.setBlock(x + 17, y + 8, z + 20, Blocks.log2, 1, 3);
		world.setBlock(x + 14, y + 8, z + 21, Blocks.log2, 1, 3);
		world.setBlock(x + 15, y + 8, z + 21, Blocks.log2, 1, 3);
		world.setBlock(x + 13, y + 9, z + 15, Blocks.log2, 1, 3);
		world.setBlock(x + 14, y + 9, z + 15, Blocks.log2, 1, 3);
		world.setBlock(x + 15, y + 9, z + 15, Blocks.log2, 1, 3);
		world.setBlock(x + 16, y + 9, z + 15, Blocks.log2, 1, 3);
		world.setBlock(x + 12, y + 9, z + 16, Blocks.log2, 1, 3);
		world.setBlock(x + 13, y + 9, z + 16, Blocks.log2, 1, 3);
		world.setBlock(x + 14, y + 9, z + 16, Blocks.log2, 1, 3);
		world.setBlock(x + 15, y + 9, z + 16, Blocks.log2, 1, 3);
		world.setBlock(x + 16, y + 9, z + 16, Blocks.log2, 1, 3);
		world.setBlock(x + 17, y + 9, z + 16, Blocks.log2, 1, 3);
		world.setBlock(x + 12, y + 9, z + 17, Blocks.log2, 1, 3);
		world.setBlock(x + 13, y + 9, z + 17, Blocks.log2, 1, 3);
		world.setBlock(x + 14, y + 9, z + 17, Blocks.log2, 1, 3);
		world.setBlock(x + 15, y + 9, z + 17, Blocks.log2, 1, 3);
		world.setBlock(x + 16, y + 9, z + 17, Blocks.log2, 1, 3);
		world.setBlock(x + 17, y + 9, z + 17, Blocks.log2, 1, 3);
		world.setBlock(x + 12, y + 9, z + 18, Blocks.log2, 1, 3);
		world.setBlock(x + 13, y + 9, z + 18, Blocks.log2, 1, 3);
		world.setBlock(x + 14, y + 9, z + 18, Blocks.log2, 1, 3);
		world.setBlock(x + 15, y + 9, z + 18, Blocks.log2, 1, 3);
		world.setBlock(x + 16, y + 9, z + 18, Blocks.log2, 1, 3);
		world.setBlock(x + 17, y + 9, z + 18, Blocks.log2, 1, 3);
		world.setBlock(x + 12, y + 9, z + 19, Blocks.log2, 1, 3);
		world.setBlock(x + 13, y + 9, z + 19, Blocks.log2, 1, 3);
		world.setBlock(x + 14, y + 9, z + 19, Blocks.log2, 1, 3);
		world.setBlock(x + 15, y + 9, z + 19, Blocks.log2, 1, 3);
		world.setBlock(x + 16, y + 9, z + 19, Blocks.log2, 1, 3);
		world.setBlock(x + 17, y + 9, z + 19, Blocks.log2, 1, 3);
		world.setBlock(x + 13, y + 9, z + 20, Blocks.log2, 1, 3);
		world.setBlock(x + 14, y + 9, z + 20, Blocks.log2, 1, 3);
		world.setBlock(x + 15, y + 9, z + 20, Blocks.log2, 1, 3);
		world.setBlock(x + 16, y + 9, z + 20, Blocks.log2, 1, 3);
		world.setBlock(x + 14, y + 10, z + 15, Blocks.log2, 1, 3);
		world.setBlock(x + 15, y + 10, z + 15, Blocks.log2, 1, 3);
		world.setBlock(x + 13, y + 10, z + 16, Blocks.log2, 1, 3);
		world.setBlock(x + 14, y + 10, z + 16, Blocks.log2, 1, 3);
		world.setBlock(x + 15, y + 10, z + 16, Blocks.log2, 1, 3);
		world.setBlock(x + 16, y + 10, z + 16, Blocks.log2, 1, 3);
		world.setBlock(x + 12, y + 10, z + 17, Blocks.log2, 1, 3);
		world.setBlock(x + 13, y + 10, z + 17, Blocks.log2, 1, 3);
		world.setBlock(x + 14, y + 10, z + 17, Blocks.log2, 1, 3);
		world.setBlock(x + 15, y + 10, z + 17, Blocks.log2, 1, 3);
		world.setBlock(x + 16, y + 10, z + 17, Blocks.log2, 1, 3);
		world.setBlock(x + 17, y + 10, z + 17, Blocks.log2, 1, 3);
		world.setBlock(x + 12, y + 10, z + 18, Blocks.log2, 1, 3);
		world.setBlock(x + 13, y + 10, z + 18, Blocks.log2, 1, 3);
		world.setBlock(x + 14, y + 10, z + 18, Blocks.log2, 1, 3);
		world.setBlock(x + 15, y + 10, z + 18, Blocks.log2, 1, 3);
		world.setBlock(x + 16, y + 10, z + 18, Blocks.log2, 1, 3);
		world.setBlock(x + 17, y + 10, z + 18, Blocks.log2, 1, 3);
		world.setBlock(x + 13, y + 10, z + 19, Blocks.log2, 1, 3);
		world.setBlock(x + 14, y + 10, z + 19, Blocks.log2, 1, 3);
		world.setBlock(x + 15, y + 10, z + 19, Blocks.log2, 1, 3);
		world.setBlock(x + 16, y + 10, z + 19, Blocks.log2, 1, 3);
		world.setBlock(x + 14, y + 10, z + 20, Blocks.log2, 1, 3);
		world.setBlock(x + 15, y + 10, z + 20, Blocks.log2, 1, 3);
		world.setBlock(x + 13, y + 11, z + 16, Blocks.log2, 1, 3);
		world.setBlock(x + 14, y + 11, z + 16, Blocks.log2, 1, 3);
		world.setBlock(x + 15, y + 11, z + 16, Blocks.log2, 1, 3);
		world.setBlock(x + 16, y + 11, z + 16, Blocks.log2, 1, 3);
		world.setBlock(x + 13, y + 11, z + 17, Blocks.log2, 1, 3);
		world.setBlock(x + 14, y + 11, z + 17, Blocks.log2, 1, 3);
		world.setBlock(x + 15, y + 11, z + 17, Blocks.log2, 1, 3);
		world.setBlock(x + 16, y + 11, z + 17, Blocks.log2, 1, 3);
		world.setBlock(x + 17, y + 11, z + 17, Blocks.log2, 1, 3);
		world.setBlock(x + 13, y + 11, z + 18, Blocks.log2, 1, 3);
		world.setBlock(x + 14, y + 11, z + 18, Blocks.log2, 1, 3);
		world.setBlock(x + 15, y + 11, z + 18, Blocks.log2, 1, 3);
		world.setBlock(x + 16, y + 11, z + 18, Blocks.log2, 1, 3);
		world.setBlock(x + 17, y + 11, z + 18, Blocks.log2, 1, 3);
		world.setBlock(x + 13, y + 11, z + 19, Blocks.log2, 1, 3);
		world.setBlock(x + 14, y + 11, z + 19, Blocks.log2, 1, 3);
		world.setBlock(x + 15, y + 11, z + 19, Blocks.log2, 1, 3);
		world.setBlock(x + 16, y + 11, z + 19, Blocks.log2, 1, 3);
		world.setBlock(x + 14, y + 11, z + 20, Blocks.log2, 1, 3);
		world.setBlock(x + 15, y + 11, z + 20, Blocks.log2, 1, 3);
		world.setBlock(x + 13, y + 12, z + 16, Blocks.log2, 1, 3);
		world.setBlock(x + 14, y + 12, z + 16, Blocks.log2, 1, 3);
		world.setBlock(x + 15, y + 12, z + 16, Blocks.log2, 1, 3);
		world.setBlock(x + 16, y + 12, z + 16, Blocks.log2, 1, 3);
		world.setBlock(x + 13, y + 12, z + 17, Blocks.log2, 1, 3);
		world.setBlock(x + 14, y + 12, z + 17, Blocks.log2, 1, 3);
		world.setBlock(x + 15, y + 12, z + 17, Blocks.log2, 1, 3);
		world.setBlock(x + 16, y + 12, z + 17, Blocks.log2, 1, 3);
		world.setBlock(x + 13, y + 12, z + 18, Blocks.log2, 1, 3);
		world.setBlock(x + 14, y + 12, z + 18, Blocks.log2, 1, 3);
		world.setBlock(x + 15, y + 12, z + 18, Blocks.log2, 1, 3);
		world.setBlock(x + 16, y + 12, z + 18, Blocks.log2, 1, 3);
		world.setBlock(x + 13, y + 12, z + 19, Blocks.log2, 1, 3);
		world.setBlock(x + 14, y + 12, z + 19, Blocks.log2, 1, 3);
		world.setBlock(x + 15, y + 12, z + 19, Blocks.log2, 1, 3);
		world.setBlock(x + 16, y + 12, z + 19, Blocks.log2, 1, 3);
		world.setBlock(x + 14, y + 13, z + 16, Blocks.log2, 1, 3);
		world.setBlock(x + 15, y + 13, z + 16, Blocks.log2, 1, 3);
		world.setBlock(x + 13, y + 13, z + 17, Blocks.log2, 1, 3);
		world.setBlock(x + 14, y + 13, z + 17, Blocks.log2, 1, 3);
		world.setBlock(x + 15, y + 13, z + 17, Blocks.log2, 1, 3);
		world.setBlock(x + 16, y + 13, z + 17, Blocks.log2, 1, 3);
		world.setBlock(x + 13, y + 13, z + 18, Blocks.log2, 1, 3);
		world.setBlock(x + 14, y + 13, z + 18, Blocks.log2, 1, 3);
		world.setBlock(x + 15, y + 13, z + 18, Blocks.log2, 1, 3);
		world.setBlock(x + 16, y + 13, z + 18, Blocks.log2, 1, 3);
		world.setBlock(x + 14, y + 13, z + 19, Blocks.log2, 1, 3);
		world.setBlock(x + 15, y + 13, z + 19, Blocks.log2, 1, 3);
		world.setBlock(x + 14, y + 14, z + 16, Blocks.log2, 1, 3);
		world.setBlock(x + 15, y + 14, z + 16, Blocks.log2, 1, 3);
		world.setBlock(x + 13, y + 14, z + 17, Blocks.log2, 1, 3);
		world.setBlock(x + 14, y + 14, z + 17, Blocks.log2, 1, 3);
		world.setBlock(x + 15, y + 14, z + 17, Blocks.log2, 1, 3);
		world.setBlock(x + 16, y + 14, z + 17, Blocks.log2, 1, 3);
		world.setBlock(x + 13, y + 14, z + 18, Blocks.log2, 1, 3);
		world.setBlock(x + 14, y + 14, z + 18, Blocks.log2, 1, 3);
		world.setBlock(x + 15, y + 14, z + 18, Blocks.log2, 1, 3);
		world.setBlock(x + 16, y + 14, z + 18, Blocks.log2, 1, 3);
		world.setBlock(x + 14, y + 14, z + 19, Blocks.log2, 1, 3);
		world.setBlock(x + 15, y + 14, z + 19, Blocks.log2, 1, 3);
		world.setBlock(x + 14, y + 15, z + 16, Blocks.log2, 1, 3);
		world.setBlock(x + 13, y + 15, z + 17, Blocks.log2, 1, 3);
		world.setBlock(x + 14, y + 15, z + 17, Blocks.log2, 1, 3);
		world.setBlock(x + 15, y + 15, z + 17, Blocks.log2, 1, 3);
		world.setBlock(x + 16, y + 15, z + 17, Blocks.log2, 1, 3);
		world.setBlock(x + 14, y + 15, z + 18, Blocks.log2, 1, 3);
		world.setBlock(x + 15, y + 15, z + 18, Blocks.log2, 1, 3);
		world.setBlock(x + 16, y + 15, z + 18, Blocks.log2, 1, 3);
		world.setBlock(x + 14, y + 15, z + 19, Blocks.log2, 1, 3);
		world.setBlock(x + 15, y + 15, z + 19, Blocks.log2, 1, 3);
		world.setBlock(x + 14, y + 16, z + 17, Blocks.log2, 1, 3);
		world.setBlock(x + 15, y + 16, z + 17, Blocks.log2, 1, 3);
		world.setBlock(x + 16, y + 16, z + 17, Blocks.log2, 1, 3);
		world.setBlock(x + 14, y + 16, z + 18, Blocks.log2, 1, 3);
		world.setBlock(x + 15, y + 16, z + 18, Blocks.log2, 1, 3);
		world.setBlock(x + 14, y + 16, z + 19, Blocks.log2, 1, 3);
		world.setBlock(x + 14, y + 17, z + 17, Blocks.log2, 1, 3);
		world.setBlock(x + 15, y + 17, z + 17, Blocks.log2, 1, 3);
		world.setBlock(x + 14, y + 17, z + 18, Blocks.log2, 1, 3);
		world.setBlock(x + 15, y + 17, z + 18, Blocks.log2, 1, 3);
		world.setBlock(x + 14, y + 18, z + 17, Blocks.log2, 1, 3);
		world.setBlock(x + 15, y + 18, z + 17, Blocks.log2, 1, 3);
		world.setBlock(x + 14, y + 18, z + 18, Blocks.log2, 1, 3);
		world.setBlock(x + 15, y + 18, z + 18, Blocks.log2, 1, 3);
		world.setBlock(x + 14, y + 19, z + 17, Blocks.log2, 1, 3);
		world.setBlock(x + 15, y + 19, z + 17, Blocks.log2, 1, 3);
		world.setBlock(x + 16, y + 19, z + 17, Blocks.log2, 1, 3);
		world.setBlock(x + 14, y + 19, z + 18, Blocks.log2, 1, 3);
		world.setBlock(x + 15, y + 19, z + 18, Blocks.log2, 1, 3);
		world.setBlock(x + 14, y + 20, z + 16, Blocks.log2, 1, 3);
		world.setBlock(x + 15, y + 20, z + 16, Blocks.leaves2, 5, 3);
		world.setBlock(x + 14, y + 20, z + 17, Blocks.log2, 1, 3);
		world.setBlock(x + 15, y + 20, z + 17, Blocks.log2, 1, 3);
		world.setBlock(x + 16, y + 20, z + 17, Blocks.log2, 1, 3);
		world.setBlock(x + 14, y + 20, z + 18, Blocks.log2, 1, 3);
		world.setBlock(x + 15, y + 20, z + 18, Blocks.log2, 1, 3);
		world.setBlock(x + 16, y + 20, z + 18, Blocks.leaves2, 5, 3);
		world.setBlock(x + 15, y + 20, z + 19, Blocks.log2, 1, 3);
		world.setBlock(x + 22, y + 20, z + 23, Blocks.leaves2, 5, 3);
		world.setBlock(x + 18, y + 21, z + 14, Blocks.leaves2, 5, 3);
		world.setBlock(x + 14, y + 21, z + 15, Blocks.log2, 1, 3);
		world.setBlock(x + 5, y + 21, z + 16, Blocks.leaves2, 5, 3);
		world.setBlock(x + 13, y + 21, z + 16, Blocks.leaves2, 5, 3);
		world.setBlock(x + 14, y + 21, z + 16, Blocks.log2, 1, 3);
		world.setBlock(x + 15, y + 21, z + 16, Blocks.log2, 1, 3);
		world.setBlock(x + 16, y + 21, z + 16, Blocks.leaves2, 5, 3);
		world.setBlock(x + 13, y + 21, z + 17, Blocks.log2, 1, 3);
		world.setBlock(x + 14, y + 21, z + 17, Blocks.log2, 1, 3);
		world.setBlock(x + 15, y + 21, z + 17, Blocks.log2, 1, 3);
		world.setBlock(x + 16, y + 21, z + 17, Blocks.log2, 1, 3);
		world.setBlock(x + 13, y + 21, z + 18, Blocks.leaves2, 5, 3);
		world.setBlock(x + 14, y + 21, z + 18, Blocks.log2, 1, 3);
		world.setBlock(x + 15, y + 21, z + 18, Blocks.log2, 1, 3);
		world.setBlock(x + 16, y + 21, z + 18, Blocks.log2, 1, 3);
		world.setBlock(x + 14, y + 21, z + 19, Blocks.log2, 1, 3);
		world.setBlock(x + 15, y + 21, z + 19, Blocks.log2, 1, 3);
		world.setBlock(x + 15, y + 21, z + 20, Blocks.leaves2, 13, 3);
		world.setBlock(x + 17, y + 21, z + 22, Blocks.leaves2, 13, 3);
		world.setBlock(x + 21, y + 21, z + 23, Blocks.leaves2, 5, 3);
		world.setBlock(x + 22, y + 21, z + 23, Blocks.leaves2, 5, 3);
		world.setBlock(x + 14, y + 22, z + 6, Blocks.leaves2, 13, 3);
		world.setBlock(x + 15, y + 22, z + 6, Blocks.leaves2, 13, 3);
		world.setBlock(x + 17, y + 22, z + 6, Blocks.leaves2, 5, 3);
		world.setBlock(x + 12, y + 22, z + 8, Blocks.leaves2, 13, 3);
		world.setBlock(x + 6, y + 22, z + 10, Blocks.leaves2, 5, 3);
		world.setBlock(x + 11, y + 22, z + 10, Blocks.leaves2, 5, 3);
		world.setBlock(x + 9, y + 22, z + 11, Blocks.leaves2, 5, 3);
		world.setBlock(x + 21, y + 22, z + 11, Blocks.leaves2, 5, 3);
		world.setBlock(x + 8, y + 22, z + 13, Blocks.leaves2, 5, 3);
		world.setBlock(x + 18, y + 22, z + 13, Blocks.leaves2, 13, 3);
		world.setBlock(x + 18, y + 22, z + 14, Blocks.leaves2, 13, 3);
		world.setBlock(x + 19, y + 22, z + 14, Blocks.leaves2, 5, 3);
		world.setBlock(x + 5, y + 22, z + 15, Blocks.leaves2, 5, 3);
		world.setBlock(x + 13, y + 22, z + 15, Blocks.leaves2, 5, 3);
		world.setBlock(x + 14, y + 22, z + 15, Blocks.log2, 1, 3);
		world.setBlock(x + 15, y + 22, z + 15, Blocks.leaves2, 5, 3);
		world.setBlock(x + 5, y + 22, z + 16, Blocks.leaves2, 5, 3);
		world.setBlock(x + 6, y + 22, z + 16, Blocks.leaves2, 5, 3);
		world.setBlock(x + 13, y + 22, z + 16, Blocks.log2, 1, 3);
		world.setBlock(x + 14, y + 22, z + 16, Blocks.log2, 1, 3);
		world.setBlock(x + 15, y + 22, z + 16, Blocks.log2, 1, 3);
		world.setBlock(x + 16, y + 22, z + 16, Blocks.leaves2, 5, 3);
		world.setBlock(x + 13, y + 22, z + 17, Blocks.log2, 1, 3);
		world.setBlock(x + 14, y + 22, z + 17, Blocks.log2, 1, 3);
		world.setBlock(x + 15, y + 22, z + 17, Blocks.log2, 1, 3);
		world.setBlock(x + 16, y + 22, z + 17, Blocks.log2, 1, 3);
		world.setBlock(x + 17, y + 22, z + 17, Blocks.log2, 1, 3);
		world.setBlock(x + 8, y + 22, z + 18, Blocks.leaves2, 5, 3);
		world.setBlock(x + 13, y + 22, z + 18, Blocks.log2, 1, 3);
		world.setBlock(x + 14, y + 22, z + 18, Blocks.log2, 1, 3);
		world.setBlock(x + 15, y + 22, z + 18, Blocks.log2, 1, 3);
		world.setBlock(x + 16, y + 22, z + 18, Blocks.log2, 1, 3);
		world.setBlock(x + 17, y + 22, z + 18, Blocks.leaves2, 5, 3);
		world.setBlock(x + 24, y + 22, z + 18, Blocks.leaves2, 5, 3);
		world.setBlock(x + 13, y + 22, z + 19, Blocks.leaves2, 13, 3);
		world.setBlock(x + 14, y + 22, z + 19, Blocks.log2, 1, 3);
		world.setBlock(x + 15, y + 22, z + 19, Blocks.log2, 1, 3);
		world.setBlock(x + 16, y + 22, z + 19, Blocks.log2, 1, 3);
		world.setBlock(x + 15, y + 22, z + 20, Blocks.log2, 1, 3);
		world.setBlock(x + 3, y + 22, z + 21, Blocks.leaves2, 5, 3);
		world.setBlock(x + 16, y + 22, z + 22, Blocks.leaves2, 5, 3);
		world.setBlock(x + 17, y + 22, z + 22, Blocks.leaves2, 13, 3);
		world.setBlock(x + 18, y + 22, z + 22, Blocks.leaves2, 13, 3);
		world.setBlock(x + 21, y + 22, z + 22, Blocks.leaves2, 13, 3);
		world.setBlock(x + 22, y + 22, z + 22, Blocks.leaves2, 5, 3);
		world.setBlock(x + 13, y + 22, z + 23, Blocks.leaves2, 5, 3);
		world.setBlock(x + 17, y + 22, z + 23, Blocks.leaves2, 13, 3);
		world.setBlock(x + 20, y + 22, z + 23, Blocks.leaves2, 5, 3);
		world.setBlock(x + 21, y + 22, z + 23, Blocks.leaves2, 13, 3);
		world.setBlock(x + 22, y + 22, z + 23, Blocks.leaves2, 13, 3);
		world.setBlock(x + 23, y + 22, z + 23, Blocks.leaves2, 5, 3);
		world.setBlock(x + 5, y + 22, z + 24, Blocks.leaves2, 5, 3);
		world.setBlock(x + 21, y + 22, z + 24, Blocks.leaves2, 5, 3);
		world.setBlock(x + 22, y + 22, z + 24, Blocks.leaves2, 5, 3);
		world.setBlock(x + 8, y + 22, z + 29, Blocks.leaves2, 13, 3);
		world.setBlock(x + 7, y + 22, z + 30, Blocks.leaves2, 13, 3);
		world.setBlock(x + 15, y + 22, z + 30, Blocks.leaves2, 5, 3);
		world.setBlock(x + 15, y + 22, z + 31, Blocks.leaves2, 5, 3);
		world.setBlock(x + 18, y + 23, z + 4, Blocks.leaves2, 5, 3);
		world.setBlock(x + 12, y + 23, z + 5, Blocks.leaves2, 5, 3);
		world.setBlock(x + 15, y + 23, z + 5, Blocks.leaves2, 13, 3);
		world.setBlock(x + 16, y + 23, z + 5, Blocks.leaves2, 5, 3);
		world.setBlock(x + 14, y + 23, z + 6, Blocks.leaves2, 13, 3);
		world.setBlock(x + 15, y + 23, z + 6, Blocks.leaves2, 13, 3);
		world.setBlock(x + 16, y + 23, z + 6, Blocks.leaves2, 5, 3);
		world.setBlock(x + 17, y + 23, z + 6, Blocks.leaves2, 5, 3);
		world.setBlock(x + 8, y + 23, z + 7, Blocks.leaves2, 5, 3);
		world.setBlock(x + 12, y + 23, z + 7, Blocks.leaves2, 5, 3);
		world.setBlock(x + 14, y + 23, z + 7, Blocks.leaves2, 13, 3);
		world.setBlock(x + 15, y + 23, z + 7, Blocks.leaves2, 5, 3);
		world.setBlock(x + 12, y + 23, z + 8, Blocks.leaves2, 13, 3);
		world.setBlock(x + 18, y + 23, z + 8, Blocks.leaves2, 5, 3);
		world.setBlock(x + 6, y + 23, z + 9, Blocks.leaves2, 5, 3);
		world.setBlock(x + 9, y + 23, z + 9, Blocks.leaves2, 5, 3);
		world.setBlock(x + 10, y + 23, z + 9, Blocks.leaves2, 5, 3);
		world.setBlock(x + 11, y + 23, z + 9, Blocks.leaves2, 5, 3);
		world.setBlock(x + 12, y + 23, z + 9, Blocks.leaves2, 13, 3);
		world.setBlock(x + 13, y + 23, z + 9, Blocks.leaves2, 13, 3);
		world.setBlock(x + 18, y + 23, z + 9, Blocks.leaves2, 5, 3);
		world.setBlock(x + 19, y + 23, z + 9, Blocks.leaves2, 5, 3);
		world.setBlock(x + 5, y + 23, z + 10, Blocks.leaves2, 5, 3);
		world.setBlock(x + 6, y + 23, z + 10, Blocks.leaves2, 5, 3);
		world.setBlock(x + 7, y + 23, z + 10, Blocks.leaves2, 5, 3);
		world.setBlock(x + 9, y + 23, z + 10, Blocks.leaves2, 5, 3);
		world.setBlock(x + 10, y + 23, z + 10, Blocks.leaves2, 5, 3);
		world.setBlock(x + 11, y + 23, z + 10, Blocks.leaves2, 5, 3);
		world.setBlock(x + 16, y + 23, z + 10, Blocks.leaves2, 5, 3);
		world.setBlock(x + 18, y + 23, z + 10, Blocks.leaves2, 5, 3);
		world.setBlock(x + 19, y + 23, z + 10, Blocks.leaves2, 5, 3);
		world.setBlock(x + 21, y + 23, z + 10, Blocks.leaves2, 13, 3);
		world.setBlock(x + 6, y + 23, z + 11, Blocks.leaves2, 5, 3);
		world.setBlock(x + 9, y + 23, z + 11, Blocks.leaves2, 5, 3);
		world.setBlock(x + 10, y + 23, z + 11, Blocks.leaves2, 5, 3);
		world.setBlock(x + 20, y + 23, z + 11, Blocks.leaves2, 5, 3);
		world.setBlock(x + 21, y + 23, z + 11, Blocks.leaves2, 13, 3);
		world.setBlock(x + 22, y + 23, z + 11, Blocks.leaves2, 13, 3);
		world.setBlock(x + 15, y + 23, z + 12, Blocks.leaves2, 5, 3);
		world.setBlock(x + 21, y + 23, z + 12, Blocks.leaves2, 13, 3);
		world.setBlock(x + 22, y + 23, z + 12, Blocks.leaves2, 13, 3);
		world.setBlock(x + 8, y + 23, z + 13, Blocks.leaves2, 5, 3);
		world.setBlock(x + 9, y + 23, z + 13, Blocks.leaves2, 5, 3);
		world.setBlock(x + 18, y + 23, z + 13, Blocks.leaves2, 13, 3);
		world.setBlock(x + 19, y + 23, z + 13, Blocks.leaves2, 13, 3);
		world.setBlock(x + 5, y + 23, z + 14, Blocks.leaves2, 5, 3);
		world.setBlock(x + 11, y + 23, z + 14, Blocks.leaves2, 5, 3);
		world.setBlock(x + 17, y + 23, z + 14, Blocks.leaves2, 5, 3);
		world.setBlock(x + 18, y + 23, z + 14, Blocks.leaves2, 13, 3);
		world.setBlock(x + 19, y + 23, z + 14, Blocks.leaves2, 5, 3);
		world.setBlock(x + 4, y + 23, z + 15, Blocks.leaves2, 5, 3);
		world.setBlock(x + 5, y + 23, z + 15, Blocks.leaves2, 5, 3);
		world.setBlock(x + 6, y + 23, z + 15, Blocks.leaves2, 5, 3);
		world.setBlock(x + 14, y + 23, z + 15, Blocks.log2, 1, 3);
		world.setBlock(x + 15, y + 23, z + 15, Blocks.log2, 1, 3);
		world.setBlock(x + 16, y + 23, z + 15, Blocks.leaves2, 5, 3);
		world.setBlock(x + 18, y + 23, z + 15, Blocks.leaves2, 5, 3);
		world.setBlock(x + 4, y + 23, z + 16, Blocks.leaves2, 13, 3);
		world.setBlock(x + 5, y + 23, z + 16, Blocks.leaves2, 13, 3);
		world.setBlock(x + 6, y + 23, z + 16, Blocks.leaves2, 5, 3);
		world.setBlock(x + 7, y + 23, z + 16, Blocks.leaves2, 5, 3);
		world.setBlock(x + 13, y + 23, z + 16, Blocks.log2, 1, 3);
		world.setBlock(x + 14, y + 23, z + 16, Blocks.log2, 1, 3);
		world.setBlock(x + 15, y + 23, z + 16, Blocks.log2, 1, 3);
		world.setBlock(x + 16, y + 23, z + 16, Blocks.log2, 1, 3);
		world.setBlock(x + 17, y + 23, z + 16, Blocks.leaves2, 5, 3);
		world.setBlock(x + 5, y + 23, z + 17, Blocks.leaves2, 5, 3);
		world.setBlock(x + 12, y + 23, z + 17, Blocks.log2, 1, 3);
		world.setBlock(x + 13, y + 23, z + 17, Blocks.log2, 1, 3);
		world.setBlock(x + 14, y + 23, z + 17, Blocks.leaves2, 13, 3);
		world.setBlock(x + 15, y + 23, z + 17, Blocks.leaves2, 13, 3);
		world.setBlock(x + 16, y + 23, z + 17, Blocks.log2, 1, 3);
		world.setBlock(x + 17, y + 23, z + 17, Blocks.log2, 1, 3);
		world.setBlock(x + 18, y + 23, z + 17, Blocks.leaves2, 5, 3);
		world.setBlock(x + 24, y + 23, z + 17, Blocks.leaves2, 5, 3);
		world.setBlock(x + 2, y + 23, z + 18, Blocks.leaves2, 5, 3);
		world.setBlock(x + 7, y + 23, z + 18, Blocks.leaves2, 5, 3);
		world.setBlock(x + 8, y + 23, z + 18, Blocks.leaves2, 5, 3);
		world.setBlock(x + 10, y + 23, z + 18, Blocks.leaves2, 5, 3);
		world.setBlock(x + 12, y + 23, z + 18, Blocks.leaves2, 5, 3);
		world.setBlock(x + 13, y + 23, z + 18, Blocks.log2, 1, 3);
		world.setBlock(x + 14, y + 23, z + 18, Blocks.leaves2, 13, 3);
		world.setBlock(x + 15, y + 23, z + 18, Blocks.leaves2, 13, 3);
		world.setBlock(x + 16, y + 23, z + 18, Blocks.log2, 1, 3);
		world.setBlock(x + 17, y + 23, z + 18, Blocks.log2, 1, 3);
		world.setBlock(x + 23, y + 23, z + 18, Blocks.leaves2, 13, 3);
		world.setBlock(x + 24, y + 23, z + 18, Blocks.leaves2, 13, 3);
		world.setBlock(x + 25, y + 23, z + 18, Blocks.leaves2, 13, 3);
		world.setBlock(x + 2, y + 23, z + 19, Blocks.leaves2, 5, 3);
		world.setBlock(x + 8, y + 23, z + 19, Blocks.leaves2, 5, 3);
		world.setBlock(x + 13, y + 23, z + 19, Blocks.log2, 1, 3);
		world.setBlock(x + 14, y + 23, z + 19, Blocks.log2, 1, 3);
		world.setBlock(x + 15, y + 23, z + 19, Blocks.log2, 1, 3);
		world.setBlock(x + 16, y + 23, z + 19, Blocks.log2, 1, 3);
		world.setBlock(x + 22, y + 23, z + 19, Blocks.leaves2, 5, 3);
		world.setBlock(x + 24, y + 23, z + 19, Blocks.leaves2, 5, 3);
		world.setBlock(x + 14, y + 23, z + 20, Blocks.leaves2, 13, 3);
		world.setBlock(x + 15, y + 23, z + 20, Blocks.log2, 1, 3);
		world.setBlock(x + 21, y + 23, z + 20, Blocks.leaves2, 5, 3);
		world.setBlock(x + 2, y + 23, z + 21, Blocks.leaves2, 5, 3);
		world.setBlock(x + 3, y + 23, z + 21, Blocks.leaves2, 5, 3);
		world.setBlock(x + 4, y + 23, z + 21, Blocks.leaves2, 5, 3);
		world.setBlock(x + 15, y + 23, z + 21, Blocks.leaves2, 5, 3);
		world.setBlock(x + 20, y + 23, z + 21, Blocks.leaves2, 5, 3);
		world.setBlock(x + 21, y + 23, z + 21, Blocks.leaves2, 5, 3);
		world.setBlock(x + 22, y + 23, z + 21, Blocks.leaves2, 5, 3);
		world.setBlock(x + 3, y + 23, z + 22, Blocks.leaves2, 5, 3);
		world.setBlock(x + 16, y + 23, z + 22, Blocks.leaves2, 13, 3);
		world.setBlock(x + 17, y + 23, z + 22, Blocks.leaves2, 13, 3);
		world.setBlock(x + 18, y + 23, z + 22, Blocks.leaves2, 5, 3);
		world.setBlock(x + 20, y + 23, z + 22, Blocks.leaves2, 5, 3);
		world.setBlock(x + 21, y + 23, z + 22, Blocks.leaves2, 5, 3);
		world.setBlock(x + 22, y + 23, z + 22, Blocks.leaves2, 5, 3);
		world.setBlock(x + 5, y + 23, z + 23, Blocks.leaves2, 5, 3);
		world.setBlock(x + 12, y + 23, z + 23, Blocks.leaves2, 5, 3);
		world.setBlock(x + 13, y + 23, z + 23, Blocks.leaves2, 5, 3);
		world.setBlock(x + 16, y + 23, z + 23, Blocks.leaves2, 13, 3);
		world.setBlock(x + 17, y + 23, z + 23, Blocks.leaves2, 13, 3);
		world.setBlock(x + 18, y + 23, z + 23, Blocks.leaves2, 5, 3);
		world.setBlock(x + 20, y + 23, z + 23, Blocks.leaves2, 5, 3);
		world.setBlock(x + 21, y + 23, z + 23, Blocks.leaves2, 5, 3);
		world.setBlock(x + 22, y + 23, z + 23, Blocks.leaves2, 5, 3);
		world.setBlock(x + 23, y + 23, z + 23, Blocks.leaves2, 5, 3);
		world.setBlock(x + 4, y + 23, z + 24, Blocks.leaves2, 5, 3);
		world.setBlock(x + 5, y + 23, z + 24, Blocks.leaves2, 5, 3);
		world.setBlock(x + 6, y + 23, z + 24, Blocks.leaves2, 5, 3);
		world.setBlock(x + 13, y + 23, z + 24, Blocks.leaves2, 5, 3);
		world.setBlock(x + 17, y + 23, z + 24, Blocks.leaves2, 5, 3);
		world.setBlock(x + 19, y + 23, z + 24, Blocks.leaves2, 5, 3);
		world.setBlock(x + 21, y + 23, z + 24, Blocks.leaves2, 5, 3);
		world.setBlock(x + 22, y + 23, z + 24, Blocks.leaves2, 5, 3);
		world.setBlock(x + 5, y + 23, z + 25, Blocks.leaves2, 5, 3);
		world.setBlock(x + 10, y + 23, z + 25, Blocks.leaves2, 5, 3);
		world.setBlock(x + 20, y + 23, z + 25, Blocks.leaves2, 5, 3);
		world.setBlock(x + 21, y + 23, z + 25, Blocks.leaves2, 5, 3);
		world.setBlock(x + 18, y + 23, z + 26, Blocks.leaves2, 5, 3);
		world.setBlock(x + 11, y + 23, z + 27, Blocks.leaves2, 5, 3);
		world.setBlock(x + 19, y + 23, z + 27, Blocks.leaves2, 5, 3);
		world.setBlock(x + 21, y + 23, z + 27, Blocks.leaves2, 5, 3);
		world.setBlock(x + 8, y + 23, z + 28, Blocks.leaves2, 13, 3);
		world.setBlock(x + 7, y + 23, z + 29, Blocks.leaves2, 13, 3);
		world.setBlock(x + 8, y + 23, z + 29, Blocks.leaves2, 13, 3);
		world.setBlock(x + 12, y + 23, z + 29, Blocks.leaves2, 5, 3);
		world.setBlock(x + 6, y + 23, z + 30, Blocks.leaves2, 13, 3);
		world.setBlock(x + 7, y + 23, z + 30, Blocks.leaves2, 13, 3);
		world.setBlock(x + 8, y + 23, z + 30, Blocks.leaves2, 13, 3);
		world.setBlock(x + 15, y + 23, z + 30, Blocks.leaves2, 5, 3);
		world.setBlock(x + 7, y + 23, z + 31, Blocks.leaves2, 5, 3);
		world.setBlock(x + 14, y + 23, z + 31, Blocks.leaves2, 5, 3);
		world.setBlock(x + 15, y + 23, z + 31, Blocks.leaves2, 5, 3);
		world.setBlock(x + 16, y + 23, z + 31, Blocks.leaves2, 5, 3);
		world.setBlock(x + 15, y + 23, z + 32, Blocks.leaves2, 5, 3);
		world.setBlock(x + 18, y + 24, z + 3, Blocks.leaves2, 13, 3);
		world.setBlock(x + 12, y + 24, z + 4, Blocks.leaves2, 5, 3);
		world.setBlock(x + 15, y + 24, z + 4, Blocks.leaves2, 13, 3);
		world.setBlock(x + 16, y + 24, z + 4, Blocks.leaves2, 13, 3);
		world.setBlock(x + 17, y + 24, z + 4, Blocks.leaves2, 13, 3);
		world.setBlock(x + 18, y + 24, z + 4, Blocks.leaves2, 5, 3);
		world.setBlock(x + 19, y + 24, z + 4, Blocks.leaves2, 5, 3);
		world.setBlock(x + 12, y + 24, z + 5, Blocks.leaves2, 5, 3);
		world.setBlock(x + 13, y + 24, z + 5, Blocks.leaves2, 5, 3);
		world.setBlock(x + 14, y + 24, z + 5, Blocks.leaves2, 13, 3);
		world.setBlock(x + 15, y + 24, z + 5, Blocks.leaves2, 13, 3);
		world.setBlock(x + 16, y + 24, z + 5, Blocks.leaves2, 5, 3);
		world.setBlock(x + 17, y + 24, z + 5, Blocks.leaves2, 5, 3);
		world.setBlock(x + 18, y + 24, z + 5, Blocks.leaves2, 13, 3);
		world.setBlock(x + 19, y + 24, z + 5, Blocks.leaves2, 5, 3);
		world.setBlock(x + 8, y + 24, z + 6, Blocks.leaves2, 13, 3);
		world.setBlock(x + 14, y + 24, z + 6, Blocks.leaves2, 13, 3);
		world.setBlock(x + 15, y + 24, z + 6, Blocks.leaves2, 13, 3);
		world.setBlock(x + 16, y + 24, z + 6, Blocks.leaves2, 5, 3);
		world.setBlock(x + 17, y + 24, z + 6, Blocks.leaves2, 5, 3);
		world.setBlock(x + 7, y + 24, z + 7, Blocks.leaves2, 13, 3);
		world.setBlock(x + 8, y + 24, z + 7, Blocks.leaves2, 13, 3);
		world.setBlock(x + 12, y + 24, z + 7, Blocks.leaves2, 5, 3);
		world.setBlock(x + 13, y + 24, z + 7, Blocks.leaves2, 13, 3);
		world.setBlock(x + 14, y + 24, z + 7, Blocks.leaves2, 13, 3);
		world.setBlock(x + 15, y + 24, z + 7, Blocks.leaves2, 5, 3);
		world.setBlock(x + 16, y + 24, z + 7, Blocks.leaves2, 5, 3);
		world.setBlock(x + 18, y + 24, z + 7, Blocks.leaves2, 13, 3);
		world.setBlock(x + 8, y + 24, z + 8, Blocks.leaves2, 5, 3);
		world.setBlock(x + 10, y + 24, z + 8, Blocks.leaves2, 5, 3);
		world.setBlock(x + 11, y + 24, z + 8, Blocks.leaves2, 5, 3);
		world.setBlock(x + 12, y + 24, z + 8, Blocks.leaves2, 13, 3);
		world.setBlock(x + 13, y + 24, z + 8, Blocks.leaves2, 13, 3);
		world.setBlock(x + 14, y + 24, z + 8, Blocks.leaves2, 13, 3);
		world.setBlock(x + 15, y + 24, z + 8, Blocks.leaves2, 5, 3);
		world.setBlock(x + 16, y + 24, z + 8, Blocks.leaves2, 5, 3);
		world.setBlock(x + 17, y + 24, z + 8, Blocks.leaves2, 5, 3);
		world.setBlock(x + 18, y + 24, z + 8, Blocks.leaves2, 5, 3);
		world.setBlock(x + 19, y + 24, z + 8, Blocks.leaves2, 5, 3);
		world.setBlock(x + 10, y + 24, z + 9, Blocks.leaves2, 5, 3);
		world.setBlock(x + 11, y + 24, z + 9, Blocks.leaves2, 5, 3);
		world.setBlock(x + 12, y + 24, z + 9, Blocks.leaves2, 13, 3);
		world.setBlock(x + 13, y + 24, z + 9, Blocks.leaves2, 13, 3);
		world.setBlock(x + 14, y + 24, z + 9, Blocks.leaves2, 13, 3);
		world.setBlock(x + 17, y + 24, z + 9, Blocks.leaves2, 5, 3);
		world.setBlock(x + 18, y + 24, z + 9, Blocks.leaves2, 5, 3);
		world.setBlock(x + 19, y + 24, z + 9, Blocks.leaves2, 5, 3);
		world.setBlock(x + 21, y + 24, z + 9, Blocks.leaves2, 5, 3);
		world.setBlock(x + 6, y + 24, z + 10, Blocks.leaves2, 5, 3);
		world.setBlock(x + 7, y + 24, z + 10, Blocks.leaves2, 5, 3);
		world.setBlock(x + 9, y + 24, z + 10, Blocks.leaves2, 5, 3);
		world.setBlock(x + 10, y + 24, z + 10, Blocks.leaves2, 5, 3);
		world.setBlock(x + 11, y + 24, z + 10, Blocks.leaves2, 5, 3);
		world.setBlock(x + 12, y + 24, z + 10, Blocks.leaves2, 5, 3);
		world.setBlock(x + 15, y + 24, z + 10, Blocks.leaves2, 5, 3);
		world.setBlock(x + 16, y + 24, z + 10, Blocks.leaves2, 5, 3);
		world.setBlock(x + 17, y + 24, z + 10, Blocks.leaves2, 5, 3);
		world.setBlock(x + 18, y + 24, z + 10, Blocks.leaves2, 5, 3);
		world.setBlock(x + 19, y + 24, z + 10, Blocks.leaves2, 5, 3);
		world.setBlock(x + 20, y + 24, z + 10, Blocks.leaves2, 5, 3);
		world.setBlock(x + 21, y + 24, z + 10, Blocks.leaves2, 5, 3);
		world.setBlock(x + 22, y + 24, z + 10, Blocks.leaves2, 5, 3);
		world.setBlock(x + 6, y + 24, z + 11, Blocks.leaves2, 5, 3);
		world.setBlock(x + 7, y + 24, z + 11, Blocks.leaves2, 5, 3);
		world.setBlock(x + 8, y + 24, z + 11, Blocks.leaves2, 5, 3);
		world.setBlock(x + 9, y + 24, z + 11, Blocks.leaves2, 5, 3);
		world.setBlock(x + 10, y + 24, z + 11, Blocks.leaves2, 5, 3);
		world.setBlock(x + 11, y + 24, z + 11, Blocks.leaves2, 5, 3);
		world.setBlock(x + 15, y + 24, z + 11, Blocks.leaves2, 5, 3);
		world.setBlock(x + 17, y + 24, z + 11, Blocks.leaves2, 13, 3);
		world.setBlock(x + 18, y + 24, z + 11, Blocks.leaves2, 13, 3);
		world.setBlock(x + 19, y + 24, z + 11, Blocks.leaves2, 13, 3);
		world.setBlock(x + 20, y + 24, z + 11, Blocks.leaves2, 5, 3);
		world.setBlock(x + 21, y + 24, z + 11, Blocks.leaves2, 5, 3);
		world.setBlock(x + 22, y + 24, z + 11, Blocks.leaves2, 5, 3);
		world.setBlock(x + 23, y + 24, z + 11, Blocks.leaves2, 13, 3);
		world.setBlock(x + 8, y + 24, z + 12, Blocks.leaves2, 13, 3);
		world.setBlock(x + 9, y + 24, z + 12, Blocks.leaves2, 5, 3);
		world.setBlock(x + 10, y + 24, z + 12, Blocks.leaves2, 5, 3);
		world.setBlock(x + 11, y + 24, z + 12, Blocks.leaves2, 5, 3);
		world.setBlock(x + 13, y + 24, z + 12, Blocks.leaves2, 5, 3);
		world.setBlock(x + 15, y + 24, z + 12, Blocks.leaves2, 5, 3);
		world.setBlock(x + 16, y + 24, z + 12, Blocks.leaves2, 5, 3);
		world.setBlock(x + 18, y + 24, z + 12, Blocks.leaves2, 5, 3);
		world.setBlock(x + 20, y + 24, z + 12, Blocks.leaves2, 5, 3);
		world.setBlock(x + 21, y + 24, z + 12, Blocks.leaves2, 5, 3);
		world.setBlock(x + 22, y + 24, z + 12, Blocks.leaves2, 5, 3);
		world.setBlock(x + 23, y + 24, z + 12, Blocks.leaves2, 13, 3);
		world.setBlock(x + 7, y + 24, z + 13, Blocks.leaves2, 5, 3);
		world.setBlock(x + 8, y + 24, z + 13, Blocks.leaves2, 13, 3);
		world.setBlock(x + 9, y + 24, z + 13, Blocks.leaves2, 5, 3);
		world.setBlock(x + 10, y + 24, z + 13, Blocks.leaves2, 5, 3);
		world.setBlock(x + 17, y + 24, z + 13, Blocks.leaves2, 13, 3);
		world.setBlock(x + 18, y + 24, z + 13, Blocks.leaves2, 13, 3);
		world.setBlock(x + 19, y + 24, z + 13, Blocks.leaves2, 13, 3);
		world.setBlock(x + 21, y + 24, z + 13, Blocks.leaves2, 5, 3);
		world.setBlock(x + 22, y + 24, z + 13, Blocks.leaves2, 5, 3);
		world.setBlock(x + 5, y + 24, z + 14, Blocks.leaves2, 5, 3);
		world.setBlock(x + 6, y + 24, z + 14, Blocks.leaves2, 5, 3);
		world.setBlock(x + 9, y + 24, z + 14, Blocks.leaves2, 5, 3);
		world.setBlock(x + 10, y + 24, z + 14, Blocks.leaves2, 5, 3);
		world.setBlock(x + 11, y + 24, z + 14, Blocks.leaves2, 5, 3);
		world.setBlock(x + 14, y + 24, z + 14, Blocks.log2, 1, 3);
		world.setBlock(x + 15, y + 24, z + 14, Blocks.leaves2, 5, 3);
		world.setBlock(x + 17, y + 24, z + 14, Blocks.leaves2, 5, 3);
		world.setBlock(x + 18, y + 24, z + 14, Blocks.leaves2, 5, 3);
		world.setBlock(x + 19, y + 24, z + 14, Blocks.leaves2, 5, 3);
		world.setBlock(x + 20, y + 24, z + 14, Blocks.leaves2, 5, 3);
		world.setBlock(x + 4, y + 24, z + 15, Blocks.leaves2, 5, 3);
		world.setBlock(x + 5, y + 24, z + 15, Blocks.leaves2, 5, 3);
		world.setBlock(x + 6, y + 24, z + 15, Blocks.leaves2, 5, 3);
		world.setBlock(x + 7, y + 24, z + 15, Blocks.leaves2, 5, 3);
		world.setBlock(x + 13, y + 24, z + 15, Blocks.leaves2, 5, 3);
		world.setBlock(x + 14, y + 24, z + 15, Blocks.log2, 1, 3);
		world.setBlock(x + 15, y + 24, z + 15, Blocks.log2, 1, 3);
		world.setBlock(x + 16, y + 24, z + 15, Blocks.leaves2, 5, 3);
		world.setBlock(x + 18, y + 24, z + 15, Blocks.leaves2, 5, 3);
		world.setBlock(x + 19, y + 24, z + 15, Blocks.leaves2, 5, 3);
		world.setBlock(x + 3, y + 24, z + 16, Blocks.leaves2, 5, 3);
		world.setBlock(x + 4, y + 24, z + 16, Blocks.leaves2, 5, 3);
		world.setBlock(x + 5, y + 24, z + 16, Blocks.leaves2, 5, 3);
		world.setBlock(x + 6, y + 24, z + 16, Blocks.leaves2, 5, 3);
		world.setBlock(x + 7, y + 24, z + 16, Blocks.leaves2, 5, 3);
		world.setBlock(x + 8, y + 24, z + 16, Blocks.leaves2, 5, 3);
		world.setBlock(x + 12, y + 24, z + 16, Blocks.leaves2, 5, 3);
		world.setBlock(x + 13, y + 24, z + 16, Blocks.log2, 1, 3);
		world.setBlock(x + 14, y + 24, z + 16, Blocks.leaves2, 13, 3);
		world.setBlock(x + 15, y + 24, z + 16, Blocks.leaves2, 13, 3);
		world.setBlock(x + 16, y + 24, z + 16, Blocks.log2, 1, 3);
		world.setBlock(x + 17, y + 24, z + 16, Blocks.leaves2, 5, 3);
		world.setBlock(x + 24, y + 24, z + 16, Blocks.leaves2, 5, 3);
		world.setBlock(x + 4, y + 24, z + 17, Blocks.leaves2, 5, 3);
		world.setBlock(x + 5, y + 24, z + 17, Blocks.leaves2, 5, 3);
		world.setBlock(x + 6, y + 24, z + 17, Blocks.leaves2, 5, 3);
		world.setBlock(x + 7, y + 24, z + 17, Blocks.leaves2, 5, 3);
		world.setBlock(x + 8, y + 24, z + 17, Blocks.leaves2, 5, 3);
		world.setBlock(x + 10, y + 24, z + 17, Blocks.leaves2, 5, 3);
		world.setBlock(x + 12, y + 24, z + 17, Blocks.log2, 1, 3);
		world.setBlock(x + 13, y + 24, z + 17, Blocks.leaves2, 13, 3);
		world.setBlock(x + 14, y + 24, z + 17, Blocks.leaves2, 13, 3);
		world.setBlock(x + 15, y + 24, z + 17, Blocks.leaves2, 13, 3);
		world.setBlock(x + 16, y + 24, z + 17, Blocks.leaves2, 13, 3);
		world.setBlock(x + 17, y + 24, z + 17, Blocks.log2, 1, 3);
		world.setBlock(x + 18, y + 24, z + 17, Blocks.leaves2, 5, 3);
		world.setBlock(x + 23, y + 24, z + 17, Blocks.leaves2, 5, 3);
		world.setBlock(x + 24, y + 24, z + 17, Blocks.leaves2, 5, 3);
		world.setBlock(x + 25, y + 24, z + 17, Blocks.leaves2, 5, 3);
		world.setBlock(x + 2, y + 24, z + 18, Blocks.leaves2, 5, 3);
		world.setBlock(x + 5, y + 24, z + 18, Blocks.leaves2, 5, 3);
		world.setBlock(x + 6, y + 24, z + 18, Blocks.leaves2, 5, 3);
		world.setBlock(x + 7, y + 24, z + 18, Blocks.leaves2, 5, 3);
		world.setBlock(x + 8, y + 24, z + 18, Blocks.leaves2, 5, 3);
		world.setBlock(x + 9, y + 24, z + 18, Blocks.leaves2, 5, 3);
		world.setBlock(x + 10, y + 24, z + 18, Blocks.leaves2, 5, 3);
		world.setBlock(x + 11, y + 24, z + 18, Blocks.leaves2, 5, 3);
		world.setBlock(x + 12, y + 24, z + 18, Blocks.log2, 1, 3);
		world.setBlock(x + 13, y + 24, z + 18, Blocks.leaves2, 13, 3);
		world.setBlock(x + 14, y + 24, z + 18, Blocks.leaves2, 13, 3);
		world.setBlock(x + 15, y + 24, z + 18, Blocks.leaves2, 13, 3);
		world.setBlock(x + 16, y + 24, z + 18, Blocks.leaves2, 13, 3);
		world.setBlock(x + 17, y + 24, z + 18, Blocks.log2, 1, 3);
		world.setBlock(x + 18, y + 24, z + 18, Blocks.leaves2, 5, 3);
		world.setBlock(x + 22, y + 24, z + 18, Blocks.leaves2, 13, 3);
		world.setBlock(x + 23, y + 24, z + 18, Blocks.leaves2, 13, 3);
		world.setBlock(x + 24, y + 24, z + 18, Blocks.leaves2, 5, 3);
		world.setBlock(x + 25, y + 24, z + 18, Blocks.leaves2, 13, 3);
		world.setBlock(x + 26, y + 24, z + 18, Blocks.leaves2, 5, 3);
		world.setBlock(x + 2, y + 24, z + 19, Blocks.leaves2, 5, 3);
		world.setBlock(x + 4, y + 24, z + 19, Blocks.leaves2, 5, 3);
		world.setBlock(x + 7, y + 24, z + 19, Blocks.leaves2, 5, 3);
		world.setBlock(x + 8, y + 24, z + 19, Blocks.leaves2, 5, 3);
		world.setBlock(x + 10, y + 24, z + 19, Blocks.leaves2, 5, 3);
		world.setBlock(x + 12, y + 24, z + 19, Blocks.leaves2, 5, 3);
		world.setBlock(x + 13, y + 24, z + 19, Blocks.log2, 1, 3);
		world.setBlock(x + 14, y + 24, z + 19, Blocks.leaves2, 13, 3);
		world.setBlock(x + 15, y + 24, z + 19, Blocks.leaves2, 13, 3);
		world.setBlock(x + 16, y + 24, z + 19, Blocks.log2, 1, 3);
		world.setBlock(x + 17, y + 24, z + 19, Blocks.leaves2, 5, 3);
		world.setBlock(x + 21, y + 24, z + 19, Blocks.leaves2, 5, 3);
		world.setBlock(x + 22, y + 24, z + 19, Blocks.leaves2, 5, 3);
		world.setBlock(x + 23, y + 24, z + 19, Blocks.leaves2, 5, 3);
		world.setBlock(x + 24, y + 24, z + 19, Blocks.leaves2, 5, 3);
		world.setBlock(x + 25, y + 24, z + 19, Blocks.leaves2, 5, 3);
		world.setBlock(x + 6, y + 24, z + 20, Blocks.leaves2, 5, 3);
		world.setBlock(x + 8, y + 24, z + 20, Blocks.leaves2, 5, 3);
		world.setBlock(x + 13, y + 24, z + 20, Blocks.leaves2, 5, 3);
		world.setBlock(x + 14, y + 24, z + 20, Blocks.log2, 1, 3);
		world.setBlock(x + 15, y + 24, z + 20, Blocks.log2, 1, 3);
		world.setBlock(x + 17, y + 24, z + 20, Blocks.leaves2, 5, 3);
		world.setBlock(x + 20, y + 24, z + 20, Blocks.leaves2, 5, 3);
		world.setBlock(x + 21, y + 24, z + 20, Blocks.leaves2, 5, 3);
		world.setBlock(x + 22, y + 24, z + 20, Blocks.leaves2, 5, 3);
		world.setBlock(x + 24, y + 24, z + 20, Blocks.leaves2, 5, 3);
		world.setBlock(x + 2, y + 24, z + 21, Blocks.leaves2, 5, 3);
		world.setBlock(x + 3, y + 24, z + 21, Blocks.leaves2, 5, 3);
		world.setBlock(x + 4, y + 24, z + 21, Blocks.leaves2, 5, 3);
		world.setBlock(x + 15, y + 24, z + 21, Blocks.leaves2, 13, 3);
		world.setBlock(x + 16, y + 24, z + 21, Blocks.leaves2, 13, 3);
		world.setBlock(x + 18, y + 24, z + 21, Blocks.leaves2, 13, 3);
		world.setBlock(x + 19, y + 24, z + 21, Blocks.leaves2, 13, 3);
		world.setBlock(x + 20, y + 24, z + 21, Blocks.leaves2, 5, 3);
		world.setBlock(x + 21, y + 24, z + 21, Blocks.leaves2, 5, 3);
		world.setBlock(x + 22, y + 24, z + 21, Blocks.leaves2, 5, 3);
		world.setBlock(x + 2, y + 24, z + 22, Blocks.leaves2, 5, 3);
		world.setBlock(x + 3, y + 24, z + 22, Blocks.leaves2, 5, 3);
		world.setBlock(x + 4, y + 24, z + 22, Blocks.leaves2, 5, 3);
		world.setBlock(x + 5, y + 24, z + 22, Blocks.leaves2, 5, 3);
		world.setBlock(x + 9, y + 24, z + 22, Blocks.leaves2, 5, 3);
		world.setBlock(x + 12, y + 24, z + 22, Blocks.leaves2, 5, 3);
		world.setBlock(x + 15, y + 24, z + 22, Blocks.leaves2, 5, 3);
		world.setBlock(x + 16, y + 24, z + 22, Blocks.leaves2, 5, 3);
		world.setBlock(x + 17, y + 24, z + 22, Blocks.leaves2, 13, 3);
		world.setBlock(x + 18, y + 24, z + 22, Blocks.leaves2, 5, 3);
		world.setBlock(x + 19, y + 24, z + 22, Blocks.leaves2, 13, 3);
		world.setBlock(x + 20, y + 24, z + 22, Blocks.leaves2, 5, 3);
		world.setBlock(x + 21, y + 24, z + 22, Blocks.leaves2, 5, 3);
		world.setBlock(x + 22, y + 24, z + 22, Blocks.leaves2, 5, 3);
		world.setBlock(x + 23, y + 24, z + 22, Blocks.leaves2, 5, 3);
		world.setBlock(x + 3, y + 24, z + 23, Blocks.leaves2, 5, 3);
		world.setBlock(x + 4, y + 24, z + 23, Blocks.leaves2, 5, 3);
		world.setBlock(x + 5, y + 24, z + 23, Blocks.leaves2, 5, 3);
		world.setBlock(x + 11, y + 24, z + 23, Blocks.leaves2, 5, 3);
		world.setBlock(x + 12, y + 24, z + 23, Blocks.leaves2, 5, 3);
		world.setBlock(x + 13, y + 24, z + 23, Blocks.leaves2, 5, 3);
		world.setBlock(x + 15, y + 24, z + 23, Blocks.leaves2, 5, 3);
		world.setBlock(x + 16, y + 24, z + 23, Blocks.leaves2, 5, 3);
		world.setBlock(x + 17, y + 24, z + 23, Blocks.leaves2, 13, 3);
		world.setBlock(x + 18, y + 24, z + 23, Blocks.leaves2, 13, 3);
		world.setBlock(x + 19, y + 24, z + 23, Blocks.leaves2, 13, 3);
		world.setBlock(x + 20, y + 24, z + 23, Blocks.leaves2, 5, 3);
		world.setBlock(x + 21, y + 24, z + 23, Blocks.leaves2, 5, 3);
		world.setBlock(x + 22, y + 24, z + 23, Blocks.leaves2, 5, 3);
		world.setBlock(x + 4, y + 24, z + 24, Blocks.leaves2, 5, 3);
		world.setBlock(x + 5, y + 24, z + 24, Blocks.leaves2, 5, 3);
		world.setBlock(x + 6, y + 24, z + 24, Blocks.leaves2, 5, 3);
		world.setBlock(x + 7, y + 24, z + 24, Blocks.leaves2, 5, 3);
		world.setBlock(x + 10, y + 24, z + 24, Blocks.leaves2, 5, 3);
		world.setBlock(x + 12, y + 24, z + 24, Blocks.leaves2, 5, 3);
		world.setBlock(x + 13, y + 24, z + 24, Blocks.leaves2, 5, 3);
		world.setBlock(x + 16, y + 24, z + 24, Blocks.leaves2, 5, 3);
		world.setBlock(x + 17, y + 24, z + 24, Blocks.leaves2, 5, 3);
		world.setBlock(x + 18, y + 24, z + 24, Blocks.leaves2, 5, 3);
		world.setBlock(x + 19, y + 24, z + 24, Blocks.leaves2, 5, 3);
		world.setBlock(x + 20, y + 24, z + 24, Blocks.leaves2, 5, 3);
		world.setBlock(x + 21, y + 24, z + 24, Blocks.leaves2, 5, 3);
		world.setBlock(x + 5, y + 24, z + 25, Blocks.leaves2, 5, 3);
		world.setBlock(x + 6, y + 24, z + 25, Blocks.leaves2, 5, 3);
		world.setBlock(x + 9, y + 24, z + 25, Blocks.leaves2, 5, 3);
		world.setBlock(x + 10, y + 24, z + 25, Blocks.leaves2, 5, 3);
		world.setBlock(x + 17, y + 24, z + 25, Blocks.leaves2, 5, 3);
		world.setBlock(x + 19, y + 24, z + 25, Blocks.leaves2, 5, 3);
		world.setBlock(x + 20, y + 24, z + 25, Blocks.leaves2, 5, 3);
		world.setBlock(x + 21, y + 24, z + 25, Blocks.leaves2, 5, 3);
		world.setBlock(x + 7, y + 24, z + 26, Blocks.leaves2, 5, 3);
		world.setBlock(x + 12, y + 24, z + 26, Blocks.leaves2, 5, 3);
		world.setBlock(x + 18, y + 24, z + 26, Blocks.leaves2, 5, 3);
		world.setBlock(x + 19, y + 24, z + 26, Blocks.leaves2, 5, 3);
		world.setBlock(x + 20, y + 24, z + 26, Blocks.leaves2, 5, 3);
		world.setBlock(x + 11, y + 24, z + 27, Blocks.leaves2, 5, 3);
		world.setBlock(x + 12, y + 24, z + 27, Blocks.leaves2, 5, 3);
		world.setBlock(x + 19, y + 24, z + 27, Blocks.leaves2, 5, 3);
		world.setBlock(x + 20, y + 24, z + 27, Blocks.leaves2, 5, 3);
		world.setBlock(x + 21, y + 24, z + 27, Blocks.leaves2, 5, 3);
		world.setBlock(x + 8, y + 24, z + 28, Blocks.leaves2, 5, 3);
		world.setBlock(x + 10, y + 24, z + 28, Blocks.leaves2, 13, 3);
		world.setBlock(x + 11, y + 24, z + 28, Blocks.leaves2, 5, 3);
		world.setBlock(x + 20, y + 24, z + 28, Blocks.leaves2, 5, 3);
		world.setBlock(x + 6, y + 24, z + 29, Blocks.leaves2, 5, 3);
		world.setBlock(x + 7, y + 24, z + 29, Blocks.leaves2, 5, 3);
		world.setBlock(x + 8, y + 24, z + 29, Blocks.leaves2, 5, 3);
		world.setBlock(x + 9, y + 24, z + 29, Blocks.leaves2, 13, 3);
		world.setBlock(x + 10, y + 24, z + 29, Blocks.leaves2, 13, 3);
		world.setBlock(x + 11, y + 24, z + 29, Blocks.leaves2, 13, 3);
		world.setBlock(x + 12, y + 24, z + 29, Blocks.leaves2, 13, 3);
		world.setBlock(x + 15, y + 24, z + 29, Blocks.leaves2, 5, 3);
		world.setBlock(x + 5, y + 24, z + 30, Blocks.leaves2, 5, 3);
		world.setBlock(x + 6, y + 24, z + 30, Blocks.leaves2, 5, 3);
		world.setBlock(x + 7, y + 24, z + 30, Blocks.leaves2, 5, 3);
		world.setBlock(x + 8, y + 24, z + 30, Blocks.leaves2, 5, 3);
		world.setBlock(x + 9, y + 24, z + 30, Blocks.leaves2, 13, 3);
		world.setBlock(x + 12, y + 24, z + 30, Blocks.leaves2, 13, 3);
		world.setBlock(x + 14, y + 24, z + 30, Blocks.leaves2, 13, 3);
		world.setBlock(x + 15, y + 24, z + 30, Blocks.leaves2, 5, 3);
		world.setBlock(x + 16, y + 24, z + 30, Blocks.leaves2, 5, 3);
		world.setBlock(x + 6, y + 24, z + 31, Blocks.leaves2, 5, 3);
		world.setBlock(x + 7, y + 24, z + 31, Blocks.leaves2, 5, 3);
		world.setBlock(x + 8, y + 24, z + 31, Blocks.leaves2, 5, 3);
		world.setBlock(x + 13, y + 24, z + 31, Blocks.leaves2, 13, 3);
		world.setBlock(x + 14, y + 24, z + 31, Blocks.leaves2, 13, 3);
		world.setBlock(x + 15, y + 24, z + 31, Blocks.leaves2, 5, 3);
		world.setBlock(x + 16, y + 24, z + 31, Blocks.leaves2, 5, 3);
		world.setBlock(x + 7, y + 24, z + 32, Blocks.leaves2, 5, 3);
		world.setBlock(x + 14, y + 24, z + 32, Blocks.leaves2, 5, 3);
		world.setBlock(x + 15, y + 24, z + 32, Blocks.leaves2, 5, 3);
		world.setBlock(x + 16, y + 24, z + 32, Blocks.leaves2, 5, 3);
		world.setBlock(x + 15, y + 24, z + 33, Blocks.leaves2, 5, 3);
		world.setBlock(x + 14, y + 25, z + 1, Blocks.leaves2, 5, 3);
		world.setBlock(x + 15, y + 25, z + 1, Blocks.leaves2, 5, 3);
		world.setBlock(x + 13, y + 25, z + 3, Blocks.leaves2, 5, 3);
		world.setBlock(x + 14, y + 25, z + 3, Blocks.leaves2, 5, 3);
		world.setBlock(x + 15, y + 25, z + 3, Blocks.leaves2, 5, 3);
		world.setBlock(x + 16, y + 25, z + 3, Blocks.leaves2, 13, 3);
		world.setBlock(x + 17, y + 25, z + 3, Blocks.leaves2, 13, 3);
		world.setBlock(x + 12, y + 25, z + 4, Blocks.leaves2, 5, 3);
		world.setBlock(x + 13, y + 25, z + 4, Blocks.leaves2, 5, 3);
		world.setBlock(x + 14, y + 25, z + 4, Blocks.leaves2, 5, 3);
		world.setBlock(x + 15, y + 25, z + 4, Blocks.leaves2, 13, 3);
		world.setBlock(x + 16, y + 25, z + 4, Blocks.leaves2, 13, 3);
		world.setBlock(x + 17, y + 25, z + 4, Blocks.leaves2, 13, 3);
		world.setBlock(x + 18, y + 25, z + 4, Blocks.leaves2, 5, 3);
		world.setBlock(x + 12, y + 25, z + 5, Blocks.leaves2, 5, 3);
		world.setBlock(x + 13, y + 25, z + 5, Blocks.leaves2, 5, 3);
		world.setBlock(x + 14, y + 25, z + 5, Blocks.leaves2, 5, 3);
		world.setBlock(x + 15, y + 25, z + 5, Blocks.leaves2, 5, 3);
		world.setBlock(x + 16, y + 25, z + 5, Blocks.leaves2, 5, 3);
		world.setBlock(x + 17, y + 25, z + 5, Blocks.leaves2, 5, 3);
		world.setBlock(x + 18, y + 25, z + 5, Blocks.leaves2, 13, 3);
		world.setBlock(x + 19, y + 25, z + 5, Blocks.leaves2, 13, 3);
		world.setBlock(x + 8, y + 25, z + 6, Blocks.leaves2, 5, 3);
		world.setBlock(x + 13, y + 25, z + 6, Blocks.leaves2, 5, 3);
		world.setBlock(x + 14, y + 25, z + 6, Blocks.leaves2, 5, 3);
		world.setBlock(x + 15, y + 25, z + 6, Blocks.leaves2, 5, 3);
		world.setBlock(x + 16, y + 25, z + 6, Blocks.leaves2, 5, 3);
		world.setBlock(x + 17, y + 25, z + 6, Blocks.leaves2, 13, 3);
		world.setBlock(x + 18, y + 25, z + 6, Blocks.leaves2, 13, 3);
		world.setBlock(x + 19, y + 25, z + 6, Blocks.leaves2, 13, 3);
		world.setBlock(x + 6, y + 25, z + 7, Blocks.leaves2, 13, 3);
		world.setBlock(x + 7, y + 25, z + 7, Blocks.leaves2, 13, 3);
		world.setBlock(x + 8, y + 25, z + 7, Blocks.leaves2, 5, 3);
		world.setBlock(x + 10, y + 25, z + 7, Blocks.leaves2, 5, 3);
		world.setBlock(x + 11, y + 25, z + 7, Blocks.leaves2, 5, 3);
		world.setBlock(x + 12, y + 25, z + 7, Blocks.leaves2, 5, 3);
		world.setBlock(x + 13, y + 25, z + 7, Blocks.leaves2, 5, 3);
		world.setBlock(x + 14, y + 25, z + 7, Blocks.leaves2, 5, 3);
		world.setBlock(x + 15, y + 25, z + 7, Blocks.leaves2, 5, 3);
		world.setBlock(x + 16, y + 25, z + 7, Blocks.leaves2, 5, 3);
		world.setBlock(x + 17, y + 25, z + 7, Blocks.leaves2, 13, 3);
		world.setBlock(x + 18, y + 25, z + 7, Blocks.leaves2, 13, 3);
		world.setBlock(x + 19, y + 25, z + 7, Blocks.leaves2, 13, 3);
		world.setBlock(x + 7, y + 25, z + 8, Blocks.leaves2, 13, 3);
		world.setBlock(x + 8, y + 25, z + 8, Blocks.leaves2, 5, 3);
		world.setBlock(x + 9, y + 25, z + 8, Blocks.leaves2, 5, 3);
		world.setBlock(x + 10, y + 25, z + 8, Blocks.leaves2, 5, 3);
		world.setBlock(x + 11, y + 25, z + 8, Blocks.leaves2, 5, 3);
		world.setBlock(x + 12, y + 25, z + 8, Blocks.leaves2, 5, 3);
		world.setBlock(x + 13, y + 25, z + 8, Blocks.leaves2, 5, 3);
		world.setBlock(x + 14, y + 25, z + 8, Blocks.leaves2, 5, 3);
		world.setBlock(x + 15, y + 25, z + 8, Blocks.leaves2, 5, 3);
		world.setBlock(x + 16, y + 25, z + 8, Blocks.leaves2, 5, 3);
		world.setBlock(x + 17, y + 25, z + 8, Blocks.leaves2, 5, 3);
		world.setBlock(x + 18, y + 25, z + 8, Blocks.leaves2, 5, 3);
		world.setBlock(x + 19, y + 25, z + 8, Blocks.leaves2, 5, 3);
		world.setBlock(x + 7, y + 25, z + 9, Blocks.leaves2, 13, 3);
		world.setBlock(x + 8, y + 25, z + 9, Blocks.leaves2, 5, 3);
		world.setBlock(x + 9, y + 25, z + 9, Blocks.leaves2, 5, 3);
		world.setBlock(x + 10, y + 25, z + 9, Blocks.leaves2, 5, 3);
		world.setBlock(x + 11, y + 25, z + 9, Blocks.leaves2, 5, 3);
		world.setBlock(x + 12, y + 25, z + 9, Blocks.leaves2, 5, 3);
		world.setBlock(x + 13, y + 25, z + 9, Blocks.leaves2, 5, 3);
		world.setBlock(x + 14, y + 25, z + 9, Blocks.leaves2, 5, 3);
		world.setBlock(x + 15, y + 25, z + 9, Blocks.leaves2, 5, 3);
		world.setBlock(x + 16, y + 25, z + 9, Blocks.leaves2, 5, 3);
		world.setBlock(x + 17, y + 25, z + 9, Blocks.leaves2, 5, 3);
		world.setBlock(x + 18, y + 25, z + 9, Blocks.leaves2, 5, 3);
		world.setBlock(x + 19, y + 25, z + 9, Blocks.leaves2, 5, 3);
		world.setBlock(x + 20, y + 25, z + 9, Blocks.leaves2, 5, 3);
		world.setBlock(x + 21, y + 25, z + 9, Blocks.leaves2, 5, 3);
		world.setBlock(x + 7, y + 25, z + 10, Blocks.leaves2, 5, 3);
		world.setBlock(x + 8, y + 25, z + 10, Blocks.leaves2, 5, 3);
		world.setBlock(x + 9, y + 25, z + 10, Blocks.leaves2, 5, 3);
		world.setBlock(x + 10, y + 25, z + 10, Blocks.leaves2, 5, 3);
		world.setBlock(x + 11, y + 25, z + 10, Blocks.leaves2, 5, 3);
		world.setBlock(x + 12, y + 25, z + 10, Blocks.leaves2, 5, 3);
		world.setBlock(x + 13, y + 25, z + 10, Blocks.leaves2, 5, 3);
		world.setBlock(x + 14, y + 25, z + 10, Blocks.leaves2, 5, 3);
		world.setBlock(x + 15, y + 25, z + 10, Blocks.leaves2, 5, 3);
		world.setBlock(x + 16, y + 25, z + 10, Blocks.leaves2, 5, 3);
		world.setBlock(x + 17, y + 25, z + 10, Blocks.leaves2, 5, 3);
		world.setBlock(x + 18, y + 25, z + 10, Blocks.leaves2, 5, 3);
		world.setBlock(x + 19, y + 25, z + 10, Blocks.leaves2, 5, 3);
		world.setBlock(x + 20, y + 25, z + 10, Blocks.leaves2, 5, 3);
		world.setBlock(x + 21, y + 25, z + 10, Blocks.leaves2, 5, 3);
		world.setBlock(x + 22, y + 25, z + 10, Blocks.leaves2, 5, 3);
		world.setBlock(x + 7, y + 25, z + 11, Blocks.leaves2, 5, 3);
		world.setBlock(x + 8, y + 25, z + 11, Blocks.leaves2, 5, 3);
		world.setBlock(x + 9, y + 25, z + 11, Blocks.leaves2, 5, 3);
		world.setBlock(x + 10, y + 25, z + 11, Blocks.leaves2, 5, 3);
		world.setBlock(x + 11, y + 25, z + 11, Blocks.leaves2, 5, 3);
		world.setBlock(x + 12, y + 25, z + 11, Blocks.leaves2, 5, 3);
		world.setBlock(x + 14, y + 25, z + 11, Blocks.leaves2, 5, 3);
		world.setBlock(x + 15, y + 25, z + 11, Blocks.leaves2, 5, 3);
		world.setBlock(x + 17, y + 25, z + 11, Blocks.leaves2, 5, 3);
		world.setBlock(x + 18, y + 25, z + 11, Blocks.leaves2, 5, 3);
		world.setBlock(x + 19, y + 25, z + 11, Blocks.leaves2, 5, 3);
		world.setBlock(x + 20, y + 25, z + 11, Blocks.leaves2, 5, 3);
		world.setBlock(x + 21, y + 25, z + 11, Blocks.leaves2, 5, 3);
		world.setBlock(x + 22, y + 25, z + 11, Blocks.leaves2, 5, 3);
		world.setBlock(x + 23, y + 25, z + 11, Blocks.leaves2, 13, 3);
		world.setBlock(x + 7, y + 25, z + 12, Blocks.leaves2, 5, 3);
		world.setBlock(x + 8, y + 25, z + 12, Blocks.leaves2, 13, 3);
		world.setBlock(x + 9, y + 25, z + 12, Blocks.leaves2, 5, 3);
		world.setBlock(x + 10, y + 25, z + 12, Blocks.leaves2, 5, 3);
		world.setBlock(x + 11, y + 25, z + 12, Blocks.leaves2, 5, 3);
		world.setBlock(x + 13, y + 25, z + 12, Blocks.leaves2, 5, 3);
		world.setBlock(x + 15, y + 25, z + 12, Blocks.leaves2, 5, 3);
		world.setBlock(x + 16, y + 25, z + 12, Blocks.leaves2, 5, 3);
		world.setBlock(x + 17, y + 25, z + 12, Blocks.leaves2, 5, 3);
		world.setBlock(x + 18, y + 25, z + 12, Blocks.leaves2, 5, 3);
		world.setBlock(x + 19, y + 25, z + 12, Blocks.leaves2, 5, 3);
		world.setBlock(x + 20, y + 25, z + 12, Blocks.leaves2, 5, 3);
		world.setBlock(x + 21, y + 25, z + 12, Blocks.leaves2, 5, 3);
		world.setBlock(x + 22, y + 25, z + 12, Blocks.leaves2, 5, 3);
		world.setBlock(x + 23, y + 25, z + 12, Blocks.leaves2, 13, 3);
		world.setBlock(x + 24, y + 25, z + 12, Blocks.leaves2, 13, 3);
		world.setBlock(x + 5, y + 25, z + 13, Blocks.leaves2, 5, 3);
		world.setBlock(x + 6, y + 25, z + 13, Blocks.leaves2, 5, 3);
		world.setBlock(x + 7, y + 25, z + 13, Blocks.leaves2, 5, 3);
		world.setBlock(x + 8, y + 25, z + 13, Blocks.leaves2, 13, 3);
		world.setBlock(x + 9, y + 25, z + 13, Blocks.leaves2, 5, 3);
		world.setBlock(x + 10, y + 25, z + 13, Blocks.leaves2, 5, 3);
		world.setBlock(x + 11, y + 25, z + 13, Blocks.leaves2, 5, 3);
		world.setBlock(x + 14, y + 25, z + 13, Blocks.leaves2, 5, 3);
		world.setBlock(x + 15, y + 25, z + 13, Blocks.leaves2, 5, 3);
		world.setBlock(x + 20, y + 25, z + 13, Blocks.leaves2, 5, 3);
		world.setBlock(x + 21, y + 25, z + 13, Blocks.leaves2, 5, 3);
		world.setBlock(x + 22, y + 25, z + 13, Blocks.leaves2, 5, 3);
		world.setBlock(x + 23, y + 25, z + 13, Blocks.leaves2, 5, 3);
		world.setBlock(x + 4, y + 25, z + 14, Blocks.leaves2, 5, 3);
		world.setBlock(x + 5, y + 25, z + 14, Blocks.leaves2, 13, 3);
		world.setBlock(x + 6, y + 25, z + 14, Blocks.leaves2, 5, 3);
		world.setBlock(x + 7, y + 25, z + 14, Blocks.leaves2, 5, 3);
		world.setBlock(x + 8, y + 25, z + 14, Blocks.leaves2, 5, 3);
		world.setBlock(x + 9, y + 25, z + 14, Blocks.leaves2, 5, 3);
		world.setBlock(x + 10, y + 25, z + 14, Blocks.leaves2, 5, 3);
		world.setBlock(x + 11, y + 25, z + 14, Blocks.leaves2, 5, 3);
		world.setBlock(x + 12, y + 25, z + 14, Blocks.leaves2, 5, 3);
		world.setBlock(x + 13, y + 25, z + 14, Blocks.log2, 1, 3);
		world.setBlock(x + 14, y + 25, z + 14, Blocks.leaves2, 5, 3);
		world.setBlock(x + 15, y + 25, z + 14, Blocks.log2, 1, 3);
		world.setBlock(x + 16, y + 25, z + 14, Blocks.leaves2, 5, 3);
		world.setBlock(x + 17, y + 25, z + 14, Blocks.leaves2, 5, 3);
		world.setBlock(x + 18, y + 25, z + 14, Blocks.leaves2, 5, 3);
		world.setBlock(x + 19, y + 25, z + 14, Blocks.leaves2, 5, 3);
		world.setBlock(x + 20, y + 25, z + 14, Blocks.leaves2, 5, 3);
		world.setBlock(x + 21, y + 25, z + 14, Blocks.leaves2, 5, 3);
		world.setBlock(x + 22, y + 25, z + 14, Blocks.leaves2, 5, 3);
		world.setBlock(x + 4, y + 25, z + 15, Blocks.leaves2, 13, 3);
		world.setBlock(x + 5, y + 25, z + 15, Blocks.leaves2, 13, 3);
		world.setBlock(x + 6, y + 25, z + 15, Blocks.leaves2, 5, 3);
		world.setBlock(x + 7, y + 25, z + 15, Blocks.leaves2, 5, 3);
		world.setBlock(x + 8, y + 25, z + 15, Blocks.leaves2, 5, 3);
		world.setBlock(x + 9, y + 25, z + 15, Blocks.leaves2, 5, 3);
		world.setBlock(x + 10, y + 25, z + 15, Blocks.leaves2, 5, 3);
		world.setBlock(x + 11, y + 25, z + 15, Blocks.leaves2, 5, 3);
		world.setBlock(x + 12, y + 25, z + 15, Blocks.leaves2, 5, 3);
		world.setBlock(x + 13, y + 25, z + 15, Blocks.leaves2, 5, 3);
		world.setBlock(x + 14, y + 25, z + 15, Blocks.leaves2, 5, 3);
		world.setBlock(x + 15, y + 25, z + 15, Blocks.leaves2, 5, 3);
		world.setBlock(x + 16, y + 25, z + 15, Blocks.leaves2, 5, 3);
		world.setBlock(x + 17, y + 25, z + 15, Blocks.leaves2, 5, 3);
		world.setBlock(x + 18, y + 25, z + 15, Blocks.leaves2, 5, 3);
		world.setBlock(x + 19, y + 25, z + 15, Blocks.leaves2, 5, 3);
		world.setBlock(x + 3, y + 25, z + 16, Blocks.leaves2, 5, 3);
		world.setBlock(x + 4, y + 25, z + 16, Blocks.leaves2, 5, 3);
		world.setBlock(x + 5, y + 25, z + 16, Blocks.leaves2, 13, 3);
		world.setBlock(x + 6, y + 25, z + 16, Blocks.leaves2, 5, 3);
		world.setBlock(x + 7, y + 25, z + 16, Blocks.leaves2, 5, 3);
		world.setBlock(x + 8, y + 25, z + 16, Blocks.leaves2, 5, 3);
		world.setBlock(x + 9, y + 25, z + 16, Blocks.leaves2, 5, 3);
		world.setBlock(x + 12, y + 25, z + 16, Blocks.log2, 1, 3);
		world.setBlock(x + 13, y + 25, z + 16, Blocks.leaves2, 5, 3);
		world.setBlock(x + 14, y + 25, z + 16, Blocks.log2, 1, 3);
		world.setBlock(x + 15, y + 25, z + 16, Blocks.leaves2, 5, 3);
		world.setBlock(x + 16, y + 25, z + 16, Blocks.leaves2, 5, 3);
		world.setBlock(x + 17, y + 25, z + 16, Blocks.log2, 1, 3);
		world.setBlock(x + 18, y + 25, z + 16, Blocks.leaves2, 5, 3);
		world.setBlock(x + 23, y + 25, z + 16, Blocks.leaves2, 5, 3);
		world.setBlock(x + 2, y + 25, z + 17, Blocks.leaves2, 5, 3);
		world.setBlock(x + 3, y + 25, z + 17, Blocks.leaves2, 5, 3);
		world.setBlock(x + 4, y + 25, z + 17, Blocks.leaves2, 5, 3);
		world.setBlock(x + 5, y + 25, z + 17, Blocks.leaves2, 5, 3);
		world.setBlock(x + 6, y + 25, z + 17, Blocks.leaves2, 5, 3);
		world.setBlock(x + 7, y + 25, z + 17, Blocks.leaves2, 5, 3);
		world.setBlock(x + 8, y + 25, z + 17, Blocks.leaves2, 5, 3);
		world.setBlock(x + 9, y + 25, z + 17, Blocks.leaves2, 5, 3);
		world.setBlock(x + 11, y + 25, z + 17, Blocks.leaves2, 5, 3);
		world.setBlock(x + 12, y + 25, z + 17, Blocks.leaves2, 5, 3);
		world.setBlock(x + 13, y + 25, z + 17, Blocks.log2, 1, 3);
		world.setBlock(x + 14, y + 25, z + 17, Blocks.leaves2, 5, 3);
		world.setBlock(x + 15, y + 25, z + 17, Blocks.log2, 1, 3);
		world.setBlock(x + 16, y + 25, z + 17, Blocks.leaves2, 5, 3);
		world.setBlock(x + 17, y + 25, z + 17, Blocks.leaves2, 5, 3);
		world.setBlock(x + 18, y + 25, z + 17, Blocks.leaves2, 5, 3);
		world.setBlock(x + 19, y + 25, z + 17, Blocks.leaves2, 5, 3);
		world.setBlock(x + 22, y + 25, z + 17, Blocks.leaves2, 5, 3);
		world.setBlock(x + 23, y + 25, z + 17, Blocks.leaves2, 5, 3);
		world.setBlock(x + 24, y + 25, z + 17, Blocks.leaves2, 5, 3);
		world.setBlock(x + 1, y + 25, z + 18, Blocks.leaves2, 5, 3);
		world.setBlock(x + 2, y + 25, z + 18, Blocks.leaves2, 5, 3);
		world.setBlock(x + 3, y + 25, z + 18, Blocks.leaves2, 5, 3);
		world.setBlock(x + 4, y + 25, z + 18, Blocks.leaves2, 5, 3);
		world.setBlock(x + 5, y + 25, z + 18, Blocks.leaves2, 5, 3);
		world.setBlock(x + 6, y + 25, z + 18, Blocks.leaves2, 5, 3);
		world.setBlock(x + 7, y + 25, z + 18, Blocks.leaves2, 5, 3);
		world.setBlock(x + 8, y + 25, z + 18, Blocks.leaves2, 5, 3);
		world.setBlock(x + 9, y + 25, z + 18, Blocks.leaves2, 5, 3);
		world.setBlock(x + 10, y + 25, z + 18, Blocks.leaves2, 5, 3);
		world.setBlock(x + 11, y + 25, z + 18, Blocks.log2, 1, 3);
		world.setBlock(x + 12, y + 25, z + 18, Blocks.leaves2, 5, 3);
		world.setBlock(x + 13, y + 25, z + 18, Blocks.leaves2, 5, 3);
		world.setBlock(x + 14, y + 25, z + 18, Blocks.leaves2, 5, 3);
		world.setBlock(x + 15, y + 25, z + 18, Blocks.leaves2, 5, 3);
		world.setBlock(x + 16, y + 25, z + 18, Blocks.leaves2, 5, 3);
		world.setBlock(x + 17, y + 25, z + 18, Blocks.leaves2, 5, 3);
		world.setBlock(x + 18, y + 25, z + 18, Blocks.log2, 1, 3);
		world.setBlock(x + 21, y + 25, z + 18, Blocks.leaves2, 13, 3);
		world.setBlock(x + 22, y + 25, z + 18, Blocks.leaves2, 5, 3);
		world.setBlock(x + 23, y + 25, z + 18, Blocks.leaves2, 13, 3);
		world.setBlock(x + 24, y + 25, z + 18, Blocks.leaves2, 5, 3);
		world.setBlock(x + 25, y + 25, z + 18, Blocks.leaves2, 13, 3);
		world.setBlock(x + 1, y + 25, z + 19, Blocks.leaves2, 5, 3);
		world.setBlock(x + 2, y + 25, z + 19, Blocks.leaves2, 5, 3);
		world.setBlock(x + 3, y + 25, z + 19, Blocks.leaves2, 5, 3);
		world.setBlock(x + 4, y + 25, z + 19, Blocks.leaves2, 5, 3);
		world.setBlock(x + 6, y + 25, z + 19, Blocks.leaves2, 5, 3);
		world.setBlock(x + 7, y + 25, z + 19, Blocks.leaves2, 5, 3);
		world.setBlock(x + 8, y + 25, z + 19, Blocks.leaves2, 5, 3);
		world.setBlock(x + 9, y + 25, z + 19, Blocks.leaves2, 5, 3);
		world.setBlock(x + 10, y + 25, z + 19, Blocks.leaves2, 5, 3);
		world.setBlock(x + 11, y + 25, z + 19, Blocks.leaves2, 5, 3);
		world.setBlock(x + 12, y + 25, z + 19, Blocks.leaves2, 5, 3);
		world.setBlock(x + 13, y + 25, z + 19, Blocks.leaves2, 5, 3);
		world.setBlock(x + 14, y + 25, z + 19, Blocks.leaves2, 5, 3);
		world.setBlock(x + 15, y + 25, z + 19, Blocks.leaves2, 5, 3);
		world.setBlock(x + 16, y + 25, z + 19, Blocks.leaves2, 5, 3);
		world.setBlock(x + 17, y + 25, z + 19, Blocks.log2, 1, 3);
		world.setBlock(x + 18, y + 25, z + 19, Blocks.leaves2, 5, 3);
		world.setBlock(x + 21, y + 25, z + 19, Blocks.leaves2, 5, 3);
		world.setBlock(x + 22, y + 25, z + 19, Blocks.leaves2, 5, 3);
		world.setBlock(x + 23, y + 25, z + 19, Blocks.leaves2, 5, 3);
		world.setBlock(x + 24, y + 25, z + 19, Blocks.leaves2, 5, 3);
		world.setBlock(x + 2, y + 25, z + 20, Blocks.leaves2, 5, 3);
		world.setBlock(x + 3, y + 25, z + 20, Blocks.leaves2, 5, 3);
		world.setBlock(x + 4, y + 25, z + 20, Blocks.leaves2, 5, 3);
		world.setBlock(x + 6, y + 25, z + 20, Blocks.leaves2, 5, 3);
		world.setBlock(x + 7, y + 25, z + 20, Blocks.leaves2, 5, 3);
		world.setBlock(x + 8, y + 25, z + 20, Blocks.leaves2, 5, 3);
		world.setBlock(x + 10, y + 25, z + 20, Blocks.leaves2, 5, 3);
		world.setBlock(x + 13, y + 25, z + 20, Blocks.log2, 1, 3);
		world.setBlock(x + 14, y + 25, z + 20, Blocks.leaves2, 5, 3);
		world.setBlock(x + 15, y + 25, z + 20, Blocks.leaves2, 5, 3);
		world.setBlock(x + 16, y + 25, z + 20, Blocks.leaves2, 5, 3);
		world.setBlock(x + 17, y + 25, z + 20, Blocks.leaves2, 5, 3);
		world.setBlock(x + 19, y + 25, z + 20, Blocks.leaves2, 5, 3);
		world.setBlock(x + 20, y + 25, z + 20, Blocks.leaves2, 5, 3);
		world.setBlock(x + 21, y + 25, z + 20, Blocks.leaves2, 5, 3);
		world.setBlock(x + 22, y + 25, z + 20, Blocks.leaves2, 5, 3);
		world.setBlock(x + 23, y + 25, z + 20, Blocks.leaves2, 5, 3);
		world.setBlock(x + 3, y + 25, z + 21, Blocks.leaves2, 5, 3);
		world.setBlock(x + 4, y + 25, z + 21, Blocks.leaves2, 5, 3);
		world.setBlock(x + 6, y + 25, z + 21, Blocks.leaves2, 5, 3);
		world.setBlock(x + 8, y + 25, z + 21, Blocks.leaves2, 5, 3);
		world.setBlock(x + 9, y + 25, z + 21, Blocks.leaves2, 5, 3);
		world.setBlock(x + 13, y + 25, z + 21, Blocks.leaves2, 5, 3);
		world.setBlock(x + 15, y + 25, z + 21, Blocks.log2, 1, 3);
		world.setBlock(x + 16, y + 25, z + 21, Blocks.leaves2, 13, 3);
		world.setBlock(x + 18, y + 25, z + 21, Blocks.leaves2, 5, 3);
		world.setBlock(x + 19, y + 25, z + 21, Blocks.leaves2, 5, 3);
		world.setBlock(x + 20, y + 25, z + 21, Blocks.leaves2, 5, 3);
		world.setBlock(x + 21, y + 25, z + 21, Blocks.leaves2, 5, 3);
		world.setBlock(x + 22, y + 25, z + 21, Blocks.leaves2, 5, 3);
		world.setBlock(x + 23, y + 25, z + 21, Blocks.leaves2, 5, 3);
		world.setBlock(x + 2, y + 25, z + 22, Blocks.leaves2, 5, 3);
		world.setBlock(x + 3, y + 25, z + 22, Blocks.leaves2, 5, 3);
		world.setBlock(x + 4, y + 25, z + 22, Blocks.leaves2, 5, 3);
		world.setBlock(x + 5, y + 25, z + 22, Blocks.leaves2, 5, 3);
		world.setBlock(x + 8, y + 25, z + 22, Blocks.leaves2, 5, 3);
		world.setBlock(x + 9, y + 25, z + 22, Blocks.leaves2, 5, 3);
		world.setBlock(x + 10, y + 25, z + 22, Blocks.leaves2, 5, 3);
		world.setBlock(x + 12, y + 25, z + 22, Blocks.leaves2, 5, 3);
		world.setBlock(x + 14, y + 25, z + 22, Blocks.leaves2, 5, 3);
		world.setBlock(x + 15, y + 25, z + 22, Blocks.leaves2, 13, 3);
		world.setBlock(x + 16, y + 25, z + 22, Blocks.leaves2, 5, 3);
		world.setBlock(x + 17, y + 25, z + 22, Blocks.leaves2, 13, 3);
		world.setBlock(x + 18, y + 25, z + 22, Blocks.leaves2, 5, 3);
		world.setBlock(x + 19, y + 25, z + 22, Blocks.leaves2, 5, 3);
		world.setBlock(x + 20, y + 25, z + 22, Blocks.leaves2, 5, 3);
		world.setBlock(x + 21, y + 25, z + 22, Blocks.leaves2, 5, 3);
		world.setBlock(x + 25, y + 25, z + 22, Blocks.leaves2, 5, 3);
		world.setBlock(x + 3, y + 25, z + 23, Blocks.leaves2, 5, 3);
		world.setBlock(x + 4, y + 25, z + 23, Blocks.leaves2, 5, 3);
		world.setBlock(x + 5, y + 25, z + 23, Blocks.leaves2, 5, 3);
		world.setBlock(x + 10, y + 25, z + 23, Blocks.leaves2, 5, 3);
		world.setBlock(x + 11, y + 25, z + 23, Blocks.leaves2, 5, 3);
		world.setBlock(x + 12, y + 25, z + 23, Blocks.leaves2, 5, 3);
		world.setBlock(x + 13, y + 25, z + 23, Blocks.leaves2, 5, 3);
		world.setBlock(x + 15, y + 25, z + 23, Blocks.leaves2, 5, 3);
		world.setBlock(x + 16, y + 25, z + 23, Blocks.leaves2, 13, 3);
		world.setBlock(x + 17, y + 25, z + 23, Blocks.leaves2, 5, 3);
		world.setBlock(x + 18, y + 25, z + 23, Blocks.leaves2, 5, 3);
		world.setBlock(x + 19, y + 25, z + 23, Blocks.leaves2, 5, 3);
		world.setBlock(x + 20, y + 25, z + 23, Blocks.leaves2, 5, 3);
		world.setBlock(x + 21, y + 25, z + 23, Blocks.leaves2, 5, 3);
		world.setBlock(x + 26, y + 25, z + 23, Blocks.leaves2, 5, 3);
		world.setBlock(x + 3, y + 25, z + 24, Blocks.leaves2, 5, 3);
		world.setBlock(x + 4, y + 25, z + 24, Blocks.leaves2, 5, 3);
		world.setBlock(x + 5, y + 25, z + 24, Blocks.leaves2, 5, 3);
		world.setBlock(x + 6, y + 25, z + 24, Blocks.leaves2, 5, 3);
		world.setBlock(x + 7, y + 25, z + 24, Blocks.leaves2, 5, 3);
		world.setBlock(x + 8, y + 25, z + 24, Blocks.leaves2, 5, 3);
		world.setBlock(x + 9, y + 25, z + 24, Blocks.leaves2, 5, 3);
		world.setBlock(x + 10, y + 25, z + 24, Blocks.leaves2, 5, 3);
		world.setBlock(x + 11, y + 25, z + 24, Blocks.leaves2, 5, 3);
		world.setBlock(x + 12, y + 25, z + 24, Blocks.leaves2, 5, 3);
		world.setBlock(x + 13, y + 25, z + 24, Blocks.leaves2, 5, 3);
		world.setBlock(x + 16, y + 25, z + 24, Blocks.leaves2, 5, 3);
		world.setBlock(x + 17, y + 25, z + 24, Blocks.leaves2, 5, 3);
		world.setBlock(x + 18, y + 25, z + 24, Blocks.leaves2, 5, 3);
		world.setBlock(x + 19, y + 25, z + 24, Blocks.leaves2, 5, 3);
		world.setBlock(x + 20, y + 25, z + 24, Blocks.leaves2, 5, 3);
		world.setBlock(x + 21, y + 25, z + 24, Blocks.leaves2, 5, 3);
		world.setBlock(x + 22, y + 25, z + 24, Blocks.leaves2, 5, 3);
		world.setBlock(x + 4, y + 25, z + 25, Blocks.leaves2, 5, 3);
		world.setBlock(x + 5, y + 25, z + 25, Blocks.leaves2, 5, 3);
		world.setBlock(x + 6, y + 25, z + 25, Blocks.leaves2, 5, 3);
		world.setBlock(x + 7, y + 25, z + 25, Blocks.leaves2, 5, 3);
		world.setBlock(x + 9, y + 25, z + 25, Blocks.leaves2, 5, 3);
		world.setBlock(x + 10, y + 25, z + 25, Blocks.leaves2, 5, 3);
		world.setBlock(x + 12, y + 25, z + 25, Blocks.leaves2, 5, 3);

		generate_r02(world,  x, y, z);
		return true;

	}
	public boolean generate_r02(World world,  int x, int y, int z)
	{

		world.setBlock(x + 16, y + 25, z + 25, Blocks.leaves2, 5, 3);
		world.setBlock(x + 17, y + 25, z + 25, Blocks.leaves2, 5, 3);
		world.setBlock(x + 18, y + 25, z + 25, Blocks.leaves2, 5, 3);
		world.setBlock(x + 19, y + 25, z + 25, Blocks.leaves2, 5, 3);
		world.setBlock(x + 20, y + 25, z + 25, Blocks.leaves2, 5, 3);
		world.setBlock(x + 21, y + 25, z + 25, Blocks.leaves2, 5, 3);
		world.setBlock(x + 22, y + 25, z + 25, Blocks.leaves2, 5, 3);
		world.setBlock(x + 5, y + 25, z + 26, Blocks.leaves2, 13, 3);
		world.setBlock(x + 6, y + 25, z + 26, Blocks.leaves2, 13, 3);
		world.setBlock(x + 7, y + 25, z + 26, Blocks.leaves2, 5, 3);
		world.setBlock(x + 11, y + 25, z + 26, Blocks.leaves2, 5, 3);
		world.setBlock(x + 12, y + 25, z + 26, Blocks.leaves2, 5, 3);
		world.setBlock(x + 13, y + 25, z + 26, Blocks.leaves2, 5, 3);
		world.setBlock(x + 14, y + 25, z + 26, Blocks.leaves2, 5, 3);
		world.setBlock(x + 17, y + 25, z + 26, Blocks.leaves2, 5, 3);
		world.setBlock(x + 18, y + 25, z + 26, Blocks.leaves2, 5, 3);
		world.setBlock(x + 19, y + 25, z + 26, Blocks.leaves2, 5, 3);
		world.setBlock(x + 20, y + 25, z + 26, Blocks.leaves2, 5, 3);
		world.setBlock(x + 21, y + 25, z + 26, Blocks.leaves2, 5, 3);
		world.setBlock(x + 10, y + 25, z + 27, Blocks.leaves2, 13, 3);
		world.setBlock(x + 11, y + 25, z + 27, Blocks.leaves2, 5, 3);
		world.setBlock(x + 12, y + 25, z + 27, Blocks.leaves2, 5, 3);
		world.setBlock(x + 13, y + 25, z + 27, Blocks.leaves2, 5, 3);
		world.setBlock(x + 18, y + 25, z + 27, Blocks.leaves2, 5, 3);
		world.setBlock(x + 19, y + 25, z + 27, Blocks.leaves2, 5, 3);
		world.setBlock(x + 20, y + 25, z + 27, Blocks.leaves2, 5, 3);
		world.setBlock(x + 21, y + 25, z + 27, Blocks.leaves2, 5, 3);
		world.setBlock(x + 22, y + 25, z + 27, Blocks.leaves2, 5, 3);
		world.setBlock(x + 9, y + 25, z + 28, Blocks.leaves2, 13, 3);
		world.setBlock(x + 10, y + 25, z + 28, Blocks.leaves2, 13, 3);
		world.setBlock(x + 11, y + 25, z + 28, Blocks.leaves2, 5, 3);
		world.setBlock(x + 12, y + 25, z + 28, Blocks.leaves2, 5, 3);
		world.setBlock(x + 14, y + 25, z + 28, Blocks.leaves2, 5, 3);
		world.setBlock(x + 19, y + 25, z + 28, Blocks.leaves2, 5, 3);
		world.setBlock(x + 20, y + 25, z + 28, Blocks.leaves2, 5, 3);
		world.setBlock(x + 21, y + 25, z + 28, Blocks.leaves2, 5, 3);
		world.setBlock(x + 8, y + 25, z + 29, Blocks.leaves2, 5, 3);
		world.setBlock(x + 9, y + 25, z + 29, Blocks.leaves2, 13, 3);
		world.setBlock(x + 10, y + 25, z + 29, Blocks.leaves2, 13, 3);
		world.setBlock(x + 11, y + 25, z + 29, Blocks.leaves2, 13, 3);
		world.setBlock(x + 12, y + 25, z + 29, Blocks.leaves2, 13, 3);
		world.setBlock(x + 13, y + 25, z + 29, Blocks.leaves2, 5, 3);
		world.setBlock(x + 15, y + 25, z + 29, Blocks.leaves2, 5, 3);
		world.setBlock(x + 20, y + 25, z + 29, Blocks.leaves2, 5, 3);
		world.setBlock(x + 6, y + 25, z + 30, Blocks.leaves2, 5, 3);
		world.setBlock(x + 7, y + 25, z + 30, Blocks.leaves2, 5, 3);
		world.setBlock(x + 8, y + 25, z + 30, Blocks.leaves2, 5, 3);
		world.setBlock(x + 9, y + 25, z + 30, Blocks.leaves2, 13, 3);
		world.setBlock(x + 11, y + 25, z + 30, Blocks.leaves2, 13, 3);
		world.setBlock(x + 14, y + 25, z + 30, Blocks.leaves2, 13, 3);
		world.setBlock(x + 15, y + 25, z + 30, Blocks.leaves2, 5, 3);
		world.setBlock(x + 16, y + 25, z + 30, Blocks.leaves2, 5, 3);
		world.setBlock(x + 6, y + 25, z + 31, Blocks.leaves2, 13, 3);
		world.setBlock(x + 7, y + 25, z + 31, Blocks.leaves2, 13, 3);
		world.setBlock(x + 8, y + 25, z + 31, Blocks.leaves2, 5, 3);
		world.setBlock(x + 13, y + 25, z + 31, Blocks.leaves2, 13, 3);
		world.setBlock(x + 14, y + 25, z + 31, Blocks.leaves2, 13, 3);
		world.setBlock(x + 15, y + 25, z + 31, Blocks.leaves2, 5, 3);
		world.setBlock(x + 16, y + 25, z + 31, Blocks.leaves2, 13, 3);
		world.setBlock(x + 17, y + 25, z + 31, Blocks.leaves2, 13, 3);
		world.setBlock(x + 18, y + 25, z + 31, Blocks.leaves2, 5, 3);
		world.setBlock(x + 6, y + 25, z + 32, Blocks.leaves2, 13, 3);
		world.setBlock(x + 7, y + 25, z + 32, Blocks.leaves2, 13, 3);
		world.setBlock(x + 11, y + 25, z + 32, Blocks.leaves2, 13, 3);
		world.setBlock(x + 13, y + 25, z + 32, Blocks.leaves2, 5, 3);
		world.setBlock(x + 14, y + 25, z + 32, Blocks.leaves2, 5, 3);
		world.setBlock(x + 15, y + 25, z + 32, Blocks.leaves2, 5, 3);
		world.setBlock(x + 16, y + 25, z + 32, Blocks.leaves2, 13, 3);
		world.setBlock(x + 17, y + 25, z + 32, Blocks.leaves2, 13, 3);
		world.setBlock(x + 14, y + 25, z + 33, Blocks.leaves2, 5, 3);
		world.setBlock(x + 15, y + 25, z + 33, Blocks.leaves2, 5, 3);
		world.setBlock(x + 16, y + 25, z + 33, Blocks.leaves2, 13, 3);
		world.setBlock(x + 15, y + 25, z + 34, Blocks.leaves2, 5, 3);
		world.setBlock(x + 14, y + 26, z + 0, Blocks.leaves2, 5, 3);
		world.setBlock(x + 15, y + 26, z + 0, Blocks.leaves2, 5, 3);
		world.setBlock(x + 14, y + 26, z + 1, Blocks.leaves2, 5, 3);
		world.setBlock(x + 15, y + 26, z + 1, Blocks.leaves2, 5, 3);
		world.setBlock(x + 13, y + 26, z + 2, Blocks.leaves2, 5, 3);
		world.setBlock(x + 14, y + 26, z + 2, Blocks.leaves2, 5, 3);
		world.setBlock(x + 15, y + 26, z + 2, Blocks.leaves2, 13, 3);
		world.setBlock(x + 16, y + 26, z + 2, Blocks.leaves2, 13, 3);
		world.setBlock(x + 17, y + 26, z + 2, Blocks.leaves2, 13, 3);
		world.setBlock(x + 12, y + 26, z + 3, Blocks.leaves2, 5, 3);
		world.setBlock(x + 13, y + 26, z + 3, Blocks.leaves2, 5, 3);
		world.setBlock(x + 14, y + 26, z + 3, Blocks.leaves2, 5, 3);
		world.setBlock(x + 15, y + 26, z + 3, Blocks.leaves2, 13, 3);
		world.setBlock(x + 16, y + 26, z + 3, Blocks.leaves2, 13, 3);
		world.setBlock(x + 17, y + 26, z + 3, Blocks.leaves2, 13, 3);
		world.setBlock(x + 18, y + 26, z + 3, Blocks.leaves2, 13, 3);
		world.setBlock(x + 12, y + 26, z + 4, Blocks.leaves2, 5, 3);
		world.setBlock(x + 13, y + 26, z + 4, Blocks.leaves2, 5, 3);
		world.setBlock(x + 14, y + 26, z + 4, Blocks.leaves2, 5, 3);
		world.setBlock(x + 15, y + 26, z + 4, Blocks.leaves2, 5, 3);
		world.setBlock(x + 16, y + 26, z + 4, Blocks.leaves2, 5, 3);
		world.setBlock(x + 17, y + 26, z + 4, Blocks.leaves2, 5, 3);
		world.setBlock(x + 18, y + 26, z + 4, Blocks.leaves2, 5, 3);
		world.setBlock(x + 8, y + 26, z + 5, Blocks.leaves2, 5, 3);
		world.setBlock(x + 11, y + 26, z + 5, Blocks.leaves2, 5, 3);
		world.setBlock(x + 12, y + 26, z + 5, Blocks.leaves2, 5, 3);
		world.setBlock(x + 13, y + 26, z + 5, Blocks.leaves2, 5, 3);
		world.setBlock(x + 14, y + 26, z + 5, Blocks.leaves2, 5, 3);
		world.setBlock(x + 15, y + 26, z + 5, Blocks.leaves2, 5, 3);
		world.setBlock(x + 16, y + 26, z + 5, Blocks.leaves2, 5, 3);
		world.setBlock(x + 17, y + 26, z + 5, Blocks.leaves2, 5, 3);
		world.setBlock(x + 18, y + 26, z + 5, Blocks.leaves2, 5, 3);
		world.setBlock(x + 6, y + 26, z + 6, Blocks.leaves2, 5, 3);
		world.setBlock(x + 7, y + 26, z + 6, Blocks.leaves2, 5, 3);
		world.setBlock(x + 8, y + 26, z + 6, Blocks.leaves2, 5, 3);
		world.setBlock(x + 9, y + 26, z + 6, Blocks.leaves2, 5, 3);
		world.setBlock(x + 11, y + 26, z + 6, Blocks.leaves2, 5, 3);
		world.setBlock(x + 12, y + 26, z + 6, Blocks.leaves2, 5, 3);
		world.setBlock(x + 13, y + 26, z + 6, Blocks.leaves2, 5, 3);
		world.setBlock(x + 14, y + 26, z + 6, Blocks.leaves2, 5, 3);
		world.setBlock(x + 15, y + 26, z + 6, Blocks.leaves2, 5, 3);
		world.setBlock(x + 16, y + 26, z + 6, Blocks.leaves2, 5, 3);
		world.setBlock(x + 17, y + 26, z + 6, Blocks.leaves2, 5, 3);
		world.setBlock(x + 18, y + 26, z + 6, Blocks.leaves2, 5, 3);
		world.setBlock(x + 5, y + 26, z + 7, Blocks.leaves2, 13, 3);
		world.setBlock(x + 6, y + 26, z + 7, Blocks.leaves2, 13, 3);
		world.setBlock(x + 7, y + 26, z + 7, Blocks.leaves2, 13, 3);
		world.setBlock(x + 8, y + 26, z + 7, Blocks.leaves2, 5, 3);
		world.setBlock(x + 9, y + 26, z + 7, Blocks.leaves2, 5, 3);
		world.setBlock(x + 10, y + 26, z + 7, Blocks.leaves2, 5, 3);
		world.setBlock(x + 11, y + 26, z + 7, Blocks.leaves2, 5, 3);
		world.setBlock(x + 12, y + 26, z + 7, Blocks.leaves2, 5, 3);
		world.setBlock(x + 13, y + 26, z + 7, Blocks.leaves2, 5, 3);
		world.setBlock(x + 14, y + 26, z + 7, Blocks.leaves2, 5, 3);
		world.setBlock(x + 15, y + 26, z + 7, Blocks.leaves2, 5, 3);
		world.setBlock(x + 16, y + 26, z + 7, Blocks.leaves2, 5, 3);
		world.setBlock(x + 17, y + 26, z + 7, Blocks.leaves2, 5, 3);
		world.setBlock(x + 18, y + 26, z + 7, Blocks.leaves2, 5, 3);
		world.setBlock(x + 19, y + 26, z + 7, Blocks.leaves2, 5, 3);
		world.setBlock(x + 20, y + 26, z + 7, Blocks.leaves2, 5, 3);
		world.setBlock(x + 6, y + 26, z + 8, Blocks.leaves2, 13, 3);
		world.setBlock(x + 7, y + 26, z + 8, Blocks.leaves2, 13, 3);
		world.setBlock(x + 8, y + 26, z + 8, Blocks.leaves2, 5, 3);
		world.setBlock(x + 9, y + 26, z + 8, Blocks.leaves2, 5, 3);
		world.setBlock(x + 10, y + 26, z + 8, Blocks.leaves2, 5, 3);
		world.setBlock(x + 11, y + 26, z + 8, Blocks.leaves2, 5, 3);
		world.setBlock(x + 12, y + 26, z + 8, Blocks.leaves2, 5, 3);
		world.setBlock(x + 13, y + 26, z + 8, Blocks.leaves2, 5, 3);
		world.setBlock(x + 14, y + 26, z + 8, Blocks.leaves2, 5, 3);
		world.setBlock(x + 15, y + 26, z + 8, Blocks.leaves2, 5, 3);
		world.setBlock(x + 16, y + 26, z + 8, Blocks.leaves2, 5, 3);
		world.setBlock(x + 17, y + 26, z + 8, Blocks.leaves2, 5, 3);
		world.setBlock(x + 18, y + 26, z + 8, Blocks.leaves2, 5, 3);
		world.setBlock(x + 19, y + 26, z + 8, Blocks.leaves2, 5, 3);
		world.setBlock(x + 20, y + 26, z + 8, Blocks.leaves2, 5, 3);
		world.setBlock(x + 21, y + 26, z + 8, Blocks.leaves2, 5, 3);
		world.setBlock(x + 7, y + 26, z + 9, Blocks.leaves2, 13, 3);
		world.setBlock(x + 8, y + 26, z + 9, Blocks.leaves2, 5, 3);
		world.setBlock(x + 9, y + 26, z + 9, Blocks.leaves2, 5, 3);
		world.setBlock(x + 10, y + 26, z + 9, Blocks.leaves2, 5, 3);
		world.setBlock(x + 11, y + 26, z + 9, Blocks.leaves2, 5, 3);
		world.setBlock(x + 12, y + 26, z + 9, Blocks.leaves2, 5, 3);
		world.setBlock(x + 13, y + 26, z + 9, Blocks.leaves2, 5, 3);
		world.setBlock(x + 14, y + 26, z + 9, Blocks.leaves2, 5, 3);
		world.setBlock(x + 15, y + 26, z + 9, Blocks.leaves2, 5, 3);
		world.setBlock(x + 16, y + 26, z + 9, Blocks.leaves2, 5, 3);
		world.setBlock(x + 17, y + 26, z + 9, Blocks.leaves2, 5, 3);
		world.setBlock(x + 18, y + 26, z + 9, Blocks.leaves2, 5, 3);
		world.setBlock(x + 19, y + 26, z + 9, Blocks.leaves2, 5, 3);
		world.setBlock(x + 20, y + 26, z + 9, Blocks.leaves2, 5, 3);
		world.setBlock(x + 21, y + 26, z + 9, Blocks.leaves2, 5, 3);
		world.setBlock(x + 7, y + 26, z + 10, Blocks.leaves2, 5, 3);
		world.setBlock(x + 8, y + 26, z + 10, Blocks.leaves2, 5, 3);
		world.setBlock(x + 9, y + 26, z + 10, Blocks.leaves2, 5, 3);
		world.setBlock(x + 10, y + 26, z + 10, Blocks.leaves2, 5, 3);
		world.setBlock(x + 11, y + 26, z + 10, Blocks.leaves2, 5, 3);
		world.setBlock(x + 12, y + 26, z + 10, Blocks.leaves2, 5, 3);
		world.setBlock(x + 13, y + 26, z + 10, Blocks.leaves2, 5, 3);
		world.setBlock(x + 14, y + 26, z + 10, Blocks.leaves2, 5, 3);
		world.setBlock(x + 15, y + 26, z + 10, Blocks.leaves2, 5, 3);
		world.setBlock(x + 16, y + 26, z + 10, Blocks.leaves2, 5, 3);
		world.setBlock(x + 17, y + 26, z + 10, Blocks.leaves2, 5, 3);
		world.setBlock(x + 18, y + 26, z + 10, Blocks.leaves2, 5, 3);
		world.setBlock(x + 19, y + 26, z + 10, Blocks.leaves2, 5, 3);
		world.setBlock(x + 20, y + 26, z + 10, Blocks.leaves2, 5, 3);
		world.setBlock(x + 21, y + 26, z + 10, Blocks.leaves2, 13, 3);
		world.setBlock(x + 22, y + 26, z + 10, Blocks.leaves2, 13, 3);
		world.setBlock(x + 23, y + 26, z + 10, Blocks.leaves2, 5, 3);
		world.setBlock(x + 8, y + 26, z + 11, Blocks.leaves2, 5, 3);
		world.setBlock(x + 9, y + 26, z + 11, Blocks.leaves2, 5, 3);
		world.setBlock(x + 10, y + 26, z + 11, Blocks.leaves2, 5, 3);
		world.setBlock(x + 11, y + 26, z + 11, Blocks.leaves2, 5, 3);
		world.setBlock(x + 12, y + 26, z + 11, Blocks.leaves2, 5, 3);
		world.setBlock(x + 14, y + 26, z + 11, Blocks.leaves2, 5, 3);
		world.setBlock(x + 15, y + 26, z + 11, Blocks.leaves2, 5, 3);
		world.setBlock(x + 16, y + 26, z + 11, Blocks.leaves2, 5, 3);
		world.setBlock(x + 17, y + 26, z + 11, Blocks.leaves2, 13, 3);
		world.setBlock(x + 18, y + 26, z + 11, Blocks.leaves2, 13, 3);
		world.setBlock(x + 19, y + 26, z + 11, Blocks.leaves2, 13, 3);
		world.setBlock(x + 20, y + 26, z + 11, Blocks.leaves2, 5, 3);
		world.setBlock(x + 21, y + 26, z + 11, Blocks.leaves2, 5, 3);
		world.setBlock(x + 22, y + 26, z + 11, Blocks.leaves2, 5, 3);
		world.setBlock(x + 23, y + 26, z + 11, Blocks.leaves2, 13, 3);
		world.setBlock(x + 24, y + 26, z + 11, Blocks.leaves2, 13, 3);
		world.setBlock(x + 6, y + 26, z + 12, Blocks.leaves2, 5, 3);
		world.setBlock(x + 7, y + 26, z + 12, Blocks.leaves2, 5, 3);
		world.setBlock(x + 8, y + 26, z + 12, Blocks.leaves2, 5, 3);
